Workbook

Sheet Resumen
A1: Base de prospectos B2B – Valparaíso / San Antonio / Casablanca / Curacaví
A2: Fuente: 22 exportaciones de Google Maps (mapsscraper.ai, plan gratuito) del 05-10-2026. Totales calculados con fórmulas sobre la hoja Base_limpia.
A4: Indicador | B4: Valor
A5: Filas brutas (sin pies de página) | B5: 296 | C5: Dato fijo: 344 filas leídas − 48 filas de pie de página del scraper
A6: Empresas únicas | B6: =COUNTA(Base_limpia!$A$2:$A$196) -> 195
A7: Con teléfono | B7: =COUNTIF(Base_limpia!$J$2:$J$196,"+*") -> 144
A8: Con web propia | B8: =COUNTIF(Base_limpia!$N$2:$N$196,"Sí") -> 109
A9: Score de completitud promedio | B9: =ROUND(AVERAGE(Base_limpia!$I$2:$I$196),1) -> 66.7
A11: Relevancia | B11: Empresas | C11: % del total
A12: Alta | B12: =COUNTIF(Base_limpia!$G$2:$G$196,A12) -> 126 | C12: =B12/$B$6 -> 0.64615385
A13: Media | B13: =COUNTIF(Base_limpia!$G$2:$G$196,A13) -> 44 | C13: =B13/$B$6 -> 0.22564103
A14: Baja | B14: =COUNTIF(Base_limpia!$G$2:$G$196,A14) -> 19 | C14: =B14/$B$6 -> 0.097435897
A15: Descartar | B15: =COUNTIF(Base_limpia!$G$2:$G$196,A15) -> 6 | C15: =B15/$B$6 -> 0.030769231
A17: Segmento | B17: Total | C17: Alta | D17: Media | E17: Score promedio
A18: Transporte de carga | B18: =COUNTIF(Base_limpia!$F$2:$F$196,A18) -> 57 | C18: =COUNTIFS(Base_limpia!$F$2:$F$196,A18,Base_limpia!$G$2:$G$196,"Alta") -> 39 | D18: =COUNTIFS(Base_limpia!$F$2:$F$196,A18,Base_limpia!$G$2:$G$196,"Media") -> 16 | E18: =IFERROR(ROUND(AVERAGEIF(Base_limpia!$F$2:$F$196,A18,Base_limpia!$I$2:$I$196),1),0) -> 57.5
A19: Maquinaria / Industrial | B19: =COUNTIF(Base_limpia!$F$2:$F$196,A19) -> 34 | C19: =COUNTIFS(Base_limpia!$F$2:$F$196,A19,Base_limpia!$G$2:$G$196,"Alta") -> 26 | D19: =COUNTIFS(Base_limpia!$F$2:$F$196,A19,Base_limpia!$G$2:$G$196,"Media") -> 5 | E19: =IFERROR(ROUND(AVERAGEIF(Base_limpia!$F$2:$F$196,A19,Base_limpia!$I$2:$I$196),1),0) -> 78.2
A20: Logística / Almacenaje | B20: =COUNTIF(Base_limpia!$F$2:$F$196,A20) -> 30 | C20: =COUNTIFS(Base_limpia!$F$2:$F$196,A20,Base_limpia!$G$2:$G$196,"Alta") -> 17 | D20: =COUNTIFS(Base_limpia!$F$2:$F$196,A20,Base_limpia!$G$2:$G$196,"Media") -> 8 | E20: =IFERROR(ROUND(AVERAGEIF(Base_limpia!$F$2:$F$196,A20,Base_limpia!$I$2:$I$196),1),0) -> 54.2
A21: Frío / Alimentos | B21: =COUNTIF(Base_limpia!$F$2:$F$196,A21) -> 22 | C21: =COUNTIFS(Base_limpia!$F$2:$F$196,A21,Base_limpia!$G$2:$G$196,"Alta") -> 7 | D21: =COUNTIFS(Base_limpia!$F$2:$F$196,A21,Base_limpia!$G$2:$G$196,"Media") -> 8 | E21: =IFERROR(ROUND(AVERAGEIF(Base_limpia!$F$2:$F$196,A21,Base_limpia!$I$2:$I$196),1),0) -> 83.9
A22: Otros / Servicios empresariales | B22: =COUNTIF(Base_limpia!$F$2:$F$196,A22) -> 20 | C22: =COUNTIFS(Base_limpia!$F$2:$F$196,A22,Base_limpia!$G$2:$G$196,"Alta") -> 14 | D22: =COUNTIFS(Base_limpia!$F$2:$F$196,A22,Base_limpia!$G$2:$G$196,"Media") -> 3 | E22: =IFERROR(ROUND(AVERAGEIF(Base_limpia!$F$2:$F$196,A22,Base_limpia!$I$2:$I$196),1),0) -> 67.5
A23: Vitivinícola / Agrícola | B23: =COUNTIF(Base_limpia!$F$2:$F$196,A23) -> 15 | C23: =COUNTIFS(Base_limpia!$F$2:$F$196,A23,Base_limpia!$G$2:$G$196,"Alta") -> 8 | D23: =COUNTIFS(Base_limpia!$F$2:$F$196,A23,Base_limpia!$G$2:$G$196,"Media") -> 4 | E23: =IFERROR(ROUND(AVERAGEIF(Base_limpia!$F$2:$F$196,A23,Base_limpia!$I$2:$I$196),1),0) -> 69.7
A24: Portuario / Contenedores | B24: =COUNTIF(Base_limpia!$F$2:$F$196,A24) -> 12 | C24: =COUNTIFS(Base_limpia!$F$2:$F$196,A24,Base_limpia!$G$2:$G$196,"Alta") -> 11 | D24: =COUNTIFS(Base_limpia!$F$2:$F$196,A24,Base_limpia!$G$2:$G$196,"Media") -> 0 | E24: =IFERROR(ROUND(AVERAGEIF(Base_limpia!$F$2:$F$196,A24,Base_limpia!$I$2:$I$196),1),0) -> 75
A25: Química / Energía | B25: =COUNTIF(Base_limpia!$F$2:$F$196,A25) -> 5 | C25: =COUNTIFS(Base_limpia!$F$2:$F$196,A25,Base_limpia!$G$2:$G$196,"Alta") -> 4 | D25: =COUNTIFS(Base_limpia!$F$2:$F$196,A25,Base_limpia!$G$2:$G$196,"Media") -> 0 | E25: =IFERROR(ROUND(AVERAGEIF(Base_limpia!$F$2:$F$196,A25,Base_limpia!$I$2:$I$196),1),0) -> 59
A27: Comuna | B27: Total | C27: Alta
A28: San Antonio | B28: =COUNTIF(Base_limpia!$O$2:$O$196,A28) -> 63 | C28: =COUNTIFS(Base_limpia!$O$2:$O$196,A28,Base_limpia!$G$2:$G$196,"Alta") -> 43
A29: Viña del Mar | B29: =COUNTIF(Base_limpia!$O$2:$O$196,A29) -> 40 | C29: =COUNTIFS(Base_limpia!$O$2:$O$196,A29,Base_limpia!$G$2:$G$196,"Alta") -> 34
A30: Valparaíso | B30: =COUNTIF(Base_limpia!$O$2:$O$196,A30) -> 38 | C30: =COUNTIFS(Base_limpia!$O$2:$O$196,A30,Base_limpia!$G$2:$G$196,"Alta") -> 27
A31: Casablanca | B31: =COUNTIF(Base_limpia!$O$2:$O$196,A31) -> 12 | C31: =COUNTIFS(Base_limpia!$O$2:$O$196,A31,Base_limpia!$G$2:$G$196,"Alta") -> 7
A32: Curacaví | B32: =COUNTIF(Base_limpia!$O$2:$O$196,A32) -> 11 | C32: =COUNTIFS(Base_limpia!$O$2:$O$196,A32,Base_limpia!$G$2:$G$196,"Alta") -> 5
A33: Concón | B33: =COUNTIF(Base_limpia!$O$2:$O$196,A33) -> 4 | C33: =COUNTIFS(Base_limpia!$O$2:$O$196,A33,Base_limpia!$G$2:$G$196,"Alta") -> 3
A34: Cartagena | B34: =COUNTIF(Base_limpia!$O$2:$O$196,A34) -> 3 | C34: =COUNTIFS(Base_limpia!$O$2:$O$196,A34,Base_limpia!$G$2:$G$196,"Alta") -> 3
A35: Pudahuel | B35: =COUNTIF(Base_limpia!$O$2:$O$196,A35) -> 3 | C35: =COUNTIFS(Base_limpia!$O$2:$O$196,A35,Base_limpia!$G$2:$G$196,"Alta") -> 0
A36: Quilpué | B36: =COUNTIF(Base_limpia!$O$2:$O$196,A36) -> 2 | C36: =COUNTIFS(Base_limpia!$O$2:$O$196,A36,Base_limpia!$G$2:$G$196,"Alta") -> 1
A37: Quillota | B37: =COUNTIF(Base_limpia!$O$2:$O$196,A37) -> 2 | C37: =COUNTIFS(Base_limpia!$O$2:$O$196,A37,Base_limpia!$G$2:$G$196,"Alta") -> 2
A38: Santiago | B38: =COUNTIF(Base_limpia!$O$2:$O$196,A38) -> 2 | C38: =COUNTIFS(Base_limpia!$O$2:$O$196,A38,Base_limpia!$G$2:$G$196,"Alta") -> 0
A39: San Bernardo | B39: =COUNTIF(Base_limpia!$O$2:$O$196,A39) -> 2 | C39: =COUNTIFS(Base_limpia!$O$2:$O$196,A39,Base_limpia!$G$2:$G$196,"Alta") -> 0
... A47: Algarrobo | B47: =COUNTIF(Base_limpia!$O$2:$O$196,A47) -> 1 | C47: =COUNTIFS(Base_limpia!$O$2:$O$196,A47,Base_limpia!$G$2:$G$196,"Alta") -> 0

Sheet Base_limpia
A1: Place_Id | B1: Empresa | C1: Nombre_original | D1: Grupo_empresa | E1: N_sedes_grupo | F1: Segmento | G1: Relevancia | H1: Motivo_relevancia | I1: Score_completitud | J1: Telefono | K1: Tipo_telefono | L1: Sitio_web | M1: Dominio | N1: Web_propia | O1: Comuna | P1: Region | Q1: Codigo_postal | R1: Direccion | S1: Precision_direccion | T1: Latitud | U1: Longitud | V1: Categoria_principal | W1: Categorias | X1: N_resenas | Y1: Rating | Z1: Horario | AA1: Google_Maps_URL | AB1: Busquedas_origen | AC1: N_apariciones | AD1: Flags_calidad
A2: ChIJZ4iHJyfPYpYR_t_bNE6g844 | B2: Viña Casas del Bosque | C2: Viña Casas del Bosque | E2: 1 | F2: Vitivinícola / Agrícola | G2: Alta | H2: Viña de gran escala (enoturismo + producción) | I2: 100 | J2: +56 2 2480 6941 | K2: Fijo | L2: http://casasdelbosque.cl/ | M2: casasdelbosque.cl | N2: Sí | O2: Casablanca | P2: Valparaíso | R2: Ex Fundo Santa Rosa - Hijuela Nº 2, Casablanca, Valparaíso | S2: Con número | T2: -33.318621 | U2: -71.43545 | V2: Bodega | W2: Bodega, Recinto para eventos, Restaurante, Atracción turística, Tienda de vinos | X2: 1688 | Y2: 4.6 | Z2: lunes:10 am–5:30 pm | martes:10 am–5:30 pm | miércoles:10 am–5:30 pm | jueves:10 am–5:30 pm | viernes:10 am–5:30 pm | sábado:10 am–6 pm | domingo:10 am–6 pm | AA2: https://www.google.com/maps?cid=10300753030481174526 | AB2: Bodegas, Valparaíso - Chile; Viña*, Casablanca, Chile | AC2: 3
A3: ChIJU5_yCuBuYpYRLQPLGWUBG6s | B3: Casa Viñamar | C3: Casa Viñamar | E3: 1 | F3: Vitivinícola / Agrícola | G3: Alta | H3: Empresa industrial/logística en zona objetivo con canal de contacto | I3: 100 | J3: +56 9 8242 3349 | K3: Móvil | L3: https://vsptwinegroup.com/tours-and-events/es/holidays/vinamar/ | M3: vsptwinegroup.com | N3: Sí | O3: Casablanca | P3: Valparaíso | R3: Ruta 68, km 72, Casablanca, Valparaíso | S3: Con número | T3: -33.358489 | U3: -71.353124 | V3: Viñedo | W3: Viñedo, Restaurante, Atracción turística, Tienda de vinos | X3: 1636 | Y3: 4.7 | Z3: lunes:10 am–5:30 pm | martes:10 am–5:30 pm | miércoles:10 am–5:30 pm | jueves:10 am–5:30 pm | viernes:10 am–5:30 pm | sábado:10 am–5:30 pm | domingo:10 am–5:30 pm | AA3: https://www.google.com/maps?cid=12329449938592924461 | AB3: Viña*, Casablanca, Chile | AC3: 1
A4: ChIJU-puoGdmYpYRlseXs0fRl0E | B4: Viña Indómita | C4: Viña Indómita | E4: 1 | F4: Vitivinícola / Agrícola | G4: Alta | H4: Empresa industrial/logística en zona objetivo con canal de contacto | I4: 100 | J4: +56 32 215 3902 | K4: Fijo | L4: http://www.indomita.cl/ | M4: indomita.cl | N4: Sí | O4: Casablanca | P4: Valparaíso | R4: Ruta 68, Casablanca, Valparaíso | S4: Con número | T4: -33.359765 | U4: -71.343837 | V4: Viñedo | W4: Viñedo, Tienda de vinos | X4: 1294 | Y4: 4.5 | Z4: lunes:10 am–4:30 pm | martes:10 am–5:30 pm | miércoles:10 am–5:30 pm | jueves:10 am–5:30 pm | viernes:10 am–5:30 pm | sábado:Cerrado | domingo:Cerrado | AA4: https://www.google.com/maps?cid=4726476439834576790 | AB4: Viña*, Casablanca, Chile | AC4: 1
A5: ChIJTwDjYuQ4YpYRQ807Bo5Ehvg | B5: STI – San Antonio Terminal Internacional | C5: . | E5: 1 | F5: Portuario / Contenedores | G5: Alta | H5: Empresa industrial/logística en zona objetivo con canal de contacto | I5: 100 | J5: +56 35 220 1600 | K5: Fijo | L5: http://www.stiport.com/ | M5: stiport.com | N5: Sí | O5: San Antonio | P5: Valparaíso | R5: Bernardo O'Higgins Riquelme 2263, San Antonio, Valparaíso | S5: Con número | T5: -33.588561 | U5: -71.614453 | V5: Empresa portuaria | W5: Empresa portuaria, Proveedor de contenedores | X5: 928 | Y5: 4 | Z5: lunes:8:30 am–6 pm | martes:8:30 am–6 pm | miércoles:8:30 am–6 pm | jueves:8:30 am–6 pm | viernes:8:30 am–6 pm | sábado:8:30 am–6 pm | domingo:8:30 am–6 pm | AA5: https://www.google.com/maps?cid=17908076345065983299 | AB5: Empresa, San Antonio, Chile | AC5: 1 | AD5: nombre_corregido
A6: ChIJNwHdaVlHYpYR6J0IpChNBgo | B6: Seaport | C6: Seaport | E6: 1 | F6: Portuario / Contenedores | G6: Alta | H6: Empresa industrial/logística en zona objetivo con canal de contacto | I6: 100 | J6: +56 35 220 1500 | K6: Fijo | L6: http://www.seaport.cl/ | M6: seaport.cl | N6: Sí | O6: San Antonio | P6: Valparaíso | Q6: 2660000 | R6: Ruta G86, Aguas Buenas N° 6729, Cruce a Cartagena, 2660000 San Antonio, Valparaíso | S6: Con número | T6: -33.563936 | U6: -71.57017 | V6: Terminal de contenedores | W6: Terminal de contenedores | X6: 775 | Y6: 4 | Z6: lunes:9 am–5 pm | martes:9 am–5 pm | miércoles:9 am–5 pm | jueves:9 am–5 pm | viernes:9 am–5 pm | sábado:9:30–11:30 am | domingo:Cerrado | AA6: https://www.google.com/maps?cid=722349627185602024 | AB6: Empresa, San Antonio, Chile | AC6: 1
A7: ChIJCTijh51vYpYRgdNHBt8McYg | B7: Bodegas RE | C7: Bodegas RE | E7: 1 | F7: Vitivinícola / Agrícola | G7: Alta | H7: Empresa industrial/logística en zona objetivo con canal de contacto | I7: 100 | J7: +56 9 9345 9114 | K7: Móvil | L7: http://www.bodegasre.cl/ | M7: bodegasre.cl | N7: Sí | O7: Casablanca | P7: Valparaíso | R7: F-850 1380, Casablanca, Valparaíso | S7: Con número | T7: -33.304382 | U7: -71.397881 | V7: Bodega | W7: Bodega, Atracción turística | X7: 378 | Y7: 4.8 | Z7: lunes:10 am–6 pm | martes:10 am–6 pm | miércoles:10 am–6 pm | jueves:10 am–6 pm | viernes:10 am–6 pm | sábado:10 am–6 pm | domingo:11 am–5 pm | AA7: https://www.google.com/maps?cid=9831653613549114241 | AB7: Bodegas, Valparaíso - Chile | AC7: 3
A8: ChIJwfWdZmE4YpYRWcnQ83BNQSg | B8: Puerto Columbo San Antonio | C8: Puerto Columbo San Antonio | E8: 1 | F8: Otros / Servicios empresariales | G8: Alta | H8: Empresa industrial/logística en zona objetivo con canal de contacto | I8: 100 | J8: +56 35 220 3701 | K8: Fijo | L8: http://www.puertocolumbo.com/ | M8: puertocolumbo.com | N8: Sí | O8: San Antonio | P8: Valparaíso | R8: Ruta Nacional 78, Barrio Industrial # 2375, San Antonio, Valparaíso | S8: Con número | T8: -33.596729 | U8: -71.590718 | V8: Oficinas de empresa | W8: Oficinas de empresa | X8: 260 | Y8: 4.1 | Z8: lunes:8:30 am–6 pm | martes:8:30 am–6 pm | miércoles:8:30 am–6 pm | jueves:8:30 am–6 pm | viernes:8:30 am–6 pm | sábado:8:30 am–12:45 pm | domingo:Cerrado | AA8: https://www.google.com/maps?cid=2900684782525532505 | AB8: Empresa, San Antonio, Chile | AC8: 1
A9: ChIJqf97jz91YpYR3MnNt5Ur0aQ | B9: Terminal y Servicios Logísticos Las Cadenas Ltda. | C9: Terminal y Servicios Logísticos Las Cadenas Ltda. | E9: 1 | F9: Logística / Almacenaje | G9: Alta | H9: Empresa industrial/logística en zona objetivo con canal de contacto | I9: 100 | J9: +56 9 6122 2911 | K9: Móvil | L9: http://www.tlogisticolascadenas.cl/ | M9: tlogisticolascadenas.cl | N9: Sí | O9: Valparaíso | P9: Valparaíso | R9: 2821, Placilla, Cerro El Altar, Valparaíso | S9: Con número | T9: -33.134111 | U9: -71.548821 | V9: Gran superficie | W9: Gran superficie | X9: 174 | Y9: 4.3 | Z9: lunes:8 am–11 pm | martes:8 am–11 pm | miércoles:8 am–11 pm | jueves:8 am–11 pm | viernes:8 am–11 pm | sábado:8 am–5 pm | domingo:Cerrado | AA9: https://www.google.com/maps?cid=11876321614386547164 | AB9: Servicios logísticos, Valparaiso - Chile; Servicios logísticos, Valparaiso, Chile | AC9: 2
A10: ChIJaQpqAFI4YpYRZfGI7BTASjw | B10: Ferretería Industrial METALMAR | C10: Ferretería Industrial METALMAR | E10: 1 | F10: Maquinaria / Industrial | G10: Alta | H10: Empresa industrial/logística en zona objetivo con canal de contacto | I10: 100 | J10: +56 35 237 5110 | K10: Fijo | L10: http://www.metalmarchile.cl/ | M10: metalmarchile.cl | N10: Sí | O10: San Antonio | P10: Valparaíso | Q10: 2663592 | R10: Barros Luco 3058, 2663592 San Antonio, Valparaíso | S10: Con número | T10: -33.608233 | U10: -71.613862 | V10: Ferretería | W10: Ferretería, Centro comercial | X10: 147 | Y10: 4.6 | Z10: lunes:9 am–5 pm | martes:9 am–5 pm | miércoles:9 am–5 pm | jueves:9 am–5 pm | viernes:9 am–5 pm | sábado:9:30 am–1:30 pm | domingo:Cerrado | AA10: https://www.google.com/maps?cid=4344495986652541285 | AB10: Maquinaria industrial, San Antonio -Chile; Maquinaria industrial, San Antonio, Chile | AC10: 2
A11: ChIJDVf_dxPciZYRdQiz4oh22k4 | B11: Tranvial | C11: Tranvial | E11: 1 | F11: Transporte de carga | G11: Alta | H11: Empresa industrial/logística en zona objetivo con canal de contacto | I11: 100 | J11: +56 600 006 0060 | K11: 600 (call center) | L11: https://www.tranvial.com/ | M11: tranvial.com | N11: Sí | O11: Viña del Mar | P11: Valparaíso | R11: Edificio Reitz III - C. Limache 3437, Viña del Mar, Valparaíso | S11: Con número | T11: -33.04325 | U11: -71.517542 | V11: Servicio de transporte | W11: Servicio de transporte, Servicio de lanzadera, Servicio de logística, Servicio de transporte refrigerado, Empresa de transporte por camión | X11: 112 | Y11: 4.3 | Z11: lunes:Abierto las 24 horas | martes:Abierto las 24 horas | miércoles:Abierto las 24 horas | jueves:Abierto las 24 horas | viernes:Abierto las 24 horas | sábado:Abierto las 24 horas | domingo:Abierto las 24 horas | AA11: https://www.google.com/maps?cid=5681984210172315765 | AB11: Empresa, Viña del Mar, Chile; Transporte de carga, Viña del Mar, Chile | AC11: 3
A12: ChIJWdtkvBNvYpYRnhth1EiS96g | B12: Calca | C12: Calca | D12: Calca | E12: 2 | F12: Otros / Servicios empresariales | G12: Alta | H12: Empresa industrial/logística en zona objetivo con canal de contacto | I12: 100 | J12: +56 32 274 1652 | K12: Fijo | L12: http://www.calca.cl/ | M12: calca.cl | N12: Sí | O12: Casablanca | P12: Valparaíso | Q12: 2480505 | R12: Av. Portales 90, 2480505 Casablanca, Valparaíso | S12: Con número | T12: -33.321134 | U12: -71.410031 | V12: Comercio | W12: Comercio | X12: 56 | Y12: 4.6 | Z12: lunes:9 am–2 pm | martes:9 am–2 pm | miércoles:9 am–2 pm | jueves:9 am–2 pm | viernes:9 am–2 pm | sábado:9 am–12:30 pm | domingo:Cerrado | AA12: https://www.google.com/maps?cid=12175360959117859742 | AB12: Calca | AC12: 1
A13: ChIJIxwuEtNvYpYRa8XHXQiKrXA | B13: Emergent Cold LatAm | C13: Emergent Cold LatAm | E13: 1 | F13: Logística / Almacenaje | G13: Alta | H13: Empresa industrial/logística en zona objetivo con canal de contacto | I13: 100 | J13: +56 600 656 0030 | K13: 600 (call center) | L13: https://emergentcoldlatam.com/ | M13: emergentcoldlatam.com | N13: Sí | O13: Casablanca | P13: Valparaíso | R13: F-852 4621, Lo Vásquez, Casablanca, Valparaíso | S13: Con número | T13: -33.27258 | U13: -71.428276 | V13: Servicio de logística | W13: Servicio de logística | X13: 55 | Y13: 4 | Z13: lunes:Abierto las 24 horas | martes:Abierto las 24 horas | miércoles:Abierto las 24 horas | jueves:Abierto las 24 horas | viernes:Abierto las 24 horas | sábado:Abierto las 24 horas | domingo:Abierto las 24 horas | AA13: https://www.google.com/maps?cid=8119297471756617067 | AB13: Frigoríficos, Casablanca, Chile | AC13: 1
A14: ChIJt8G2SvLeiZYR9dWQP36S5DU | B14: Empresas Demaria S.A. | C14: Empresas Demaria S.A. | D14: Empresas Demaria S.A. | E14: 2 | F14: Otros / Servicios empresariales | G14: Alta | H14: Empresa industrial/logística en zona objetivo con canal de contacto | I14: 100 | J14: +56 32 226 7000 | K14: Fijo | L14: https://demaria.cl/ | M14: demaria.cl | N14: Sí | O14: Viña del Mar | P14: Valparaíso | Q14: 2562126 | R14: C. Limache 3535, 2562126 Viña del Mar, Valparaíso | S14: Con número | T14: -33.044418 | U14: -71.515894 | V14: Oficinas de empresa | W14: Oficinas de empresa | X14: 55 | Y14: 4.4 | Z14: lunes:9 am–6 pm | martes:9 am–6 pm | miércoles:9 am–6 pm | jueves:9 am–6 pm | viernes:9 am–6 pm | sábado:Cerrado | domingo:Cerrado | AA14: https://www.google.com/maps?cid=3883389849630201333 | AB14: Empresa, Viña del Mar, Chile | AC14: 1
A15: ChIJ9ckcCEfhiZYReWhuBcEBD7A | B15: Egido Empresas | C15: Egido Empresas | E15: 1 | F15: Transporte de carga | G15: Alta | H15: Empresa industrial/logística en zona objetivo con canal de contacto | I15: 100 | J15: +56 9 7450 5347 | K15: Móvil | L15: http://www.egido.cl/ | M15: egido.cl | N15: Sí | O15: Valparaíso | P15: Valparaíso | R15: Camino La Pólvora 4, La Polvora, Valparaíso | S15: Con número | T15: -33.094393 | U15: -71.588863 | V15: Empresa de transporte por camión | W15: Empresa de transporte por camión, Servicio de grúa, Tienda general, Almacén | X15: 51 | Y15: 4.3 | Z15: lunes:8 am–10 pm | martes:8 am–10 pm | miércoles:8 am–10 pm | jueves:8 am–10 pm | viernes:8 am–10 pm | sábado:8 am–2 pm | domingo:Cerrado | AA15: https://www.google.com/maps?cid=12686360603857414265 | AB15: Transporte de carga, Valparaiso, Chile | AC15: 1
A16: ChIJJ9ygp2l1YpYRz2k8P5b3_-E | B16: SERVIEX Ltda | C16: SERVIEX Ltda | E16: 1 | F16: Logística / Almacenaje | G16: Alta | H16: Empresa industrial/logística en zona objetivo con canal de contacto | I16: 95 | J16: +56 9 4173 7193 | K16: Móvil | L16: https://serviexltda.cl/ | M16: serviexltda.cl | N16: Sí | O16: Valparaíso | P16: Valparaíso | Q16: 2340000 | R16: Undécima Avenida 1730, Pc 384 Placilla, 2340000 Valparaíso | S16: Con número | T16: -33.124745 | U16: -71.545804 | V16: Servicio de logística | W16: Servicio de logística, Tienda general, Asesor en comercio internacional, Almacén, Bodega | X16: 49 | Y16: 5 | Z16: lunes:9 am–6 pm | martes:9 am–6 pm | miércoles:9 am–6 pm | jueves:9 am–6 pm | viernes:9 am–6 pm | sábado:Cerrado | domingo:Cerrado | AA16: https://www.google.com/maps?cid=16285007002273081807 | AB16: Servicios logísticos, Valparaiso - Chile | AC16: 1
A17: ChIJAXDu37PgiZYRZHTn5UC-ITM | B17: Frigorífico Víctor Mancilla y Cía Ltda. | C17: Frigorífico Víctor Mancilla y Cía Ltda. | E17: 1 | F17: Frío / Alimentos | G17: Alta | H17: Empresa industrial/logística en zona objetivo con canal de contacto | I17: 95 | J17: +56 32 262 7464 | K17: Fijo | L17: http://www.pesqueramancilla.cl/ | M17: pesqueramancilla.cl | N17: Sí | O17: Valparaíso | P17: Valparaíso | Q17: 2391272 | R17: R. Philippi 195, 2391272 Valparaíso | S17: Con número | T17: -33.035152 | U17: -71.588425 | V17: Comercio | W17: Comercio | X17: 42 | Y17: 4.2 | Z17: lunes:9 am–5 pm | martes:9 am–5 pm | miércoles:9 am–5 pm | jueves:9 am–5 pm | viernes:9 am–5 pm | sábado:9:30 am–1 pm | domingo:Cerrado | AA17: https://www.google.com/maps?cid=3684435156110111844 | AB17: Frigoríficos, Casablanca, Chile; Frigoríficos, V Región, Chile | AC17: 2
A18: ChIJ66xAzl9HYpYR7X2_s30nfzo | B18: SL TRANSPORTE LTDA | C18: SL TRANSPORTE LTDA | E18: 1 | F18: Transporte de carga | G18: Alta | H18: Empresa industrial/logística en zona objetivo con canal de contacto | I18: 95 | J18: +56 9 4008 8368 | K18: Móvil | L18: http://www.sltransporte.cl/ | M18: sltransporte.cl | N18: Sí | O18: San Antonio | P18: Valparaíso | Q18: 2660000 | R18: Los Eucaliptus, Av. Aguas Buenas 597, 2660000 San Antonio, Valparaíso | S18: Con número | T18: -33.569049 | U18: -71.570103 | V18: Empresa de transporte por camión | W18: Empresa de transporte por camión, Servicio de logística | X18: 41 | Y18: 4 | Z18: lunes:8:30 am–8 pm | martes:8:30 am–8 pm | miércoles:8:30 am–8 pm | jueves:8:30 am–8 pm | viernes:8:30 am–8 pm | sábado:8:30 am–3 pm | domingo:Cerrado | AA18: https://www.google.com/maps?cid=4215131197082140141 | AB18: Logística en San Antonio, Chile; Servicios logísticos, San Antonio, Chile; Transporte de carga, San Antonio, Chile | AC18: 3
A19: ChIJ9bP4ZR9HYpYRf9Ne0tjkdas | B19: FRIGORIFICO FRIOMOR S.A | C19: FRIGORIFICO FRIOMOR S.A | E19: 1 | F19: Frío / Alimentos | G19: Alta | H19: Empresa industrial/logística en zona objetivo con canal de contacto | I19: 95 | J19: +56 9 9619 6628 | K19: Móvil | L19: http://www.friomor.cl/ | M19: friomor.cl | N19: Sí | O19: Cartagena | P19: Valparaíso | R19: Las Majadas Lote 2 y 3 s/n, Cartagena, San Antonio, Cartagena, Valparaíso | S19: Con número | T19: -33.563029 | U19: -71.528961 | V19: Almacén | W19: Almacén, Instalación de almacenamiento en frío | X19: 26 | Y19: 4.5 | Z19: lunes:8 am–6 pm | martes:8 am–6 pm | miércoles:8 am–6 pm | jueves:8 am–6 pm | viernes:8 am–6 pm | sábado:9 am–12 pm | domingo:Cerrado | AA19: https://www.google.com/maps?cid=12355032772654322559 | AB19: Frigoríficos, Casablanca, Chile; Frigoríficos, V Región, Chile | AC19: 2
A20: ChIJOdzSlWTciZYRIK3x7MPWBs8 | B20: OSKUPACK | C20: OSKUPACK | E20: 1 | F20: Maquinaria / Industrial | G20: Alta | H20: Empresa industrial/logística en zona objetivo con canal de contacto | I20: 95 | J20: +56 9 9822 4595 | K20: Móvil | L20: https://oskupack.cl/ | M20: oskupack.cl | N20: Sí | O20: Viña del Mar | P20: Valparaíso | Q20: 2520000 | R20: Camino Lajarilla 744, 2520000 Viña del Mar, Valparaíso | S20: Con número | T20: -32.97771 | U20: -71.489106 | V20: Empresa de embalaje | W20: Empresa de embalaje, Empresa de fabricación de plástico | X20: 25 | Y20: 4.4 | Z20: lunes:9 am–5:30 pm | martes:9 am–5:30 pm | miércoles:9 am–5:30 pm | jueves:9 am–5:30 pm | viernes:9 am–5:30 pm | sábado:Cerrado | domingo:Cerrado | AA20: https://www.google.com/maps?cid=14917846952693574944 | AB20: Empresa, Viña del Mar, Chile | AC20: 1
A21: ChIJDZauyu_ciZYRzf5sek8mtt8 | B21: INDUSTRIAL COSTA SPA | C21: INDUSTRIAL COSTA SPA | E21: 1 | F21: Maquinaria / Industrial | G21: Alta | H21: Empresa industrial/logística en zona objetivo con canal de contacto | I21: 95 | J21: +56 9 8888 4772 | K21: Móvil | L21: http://industrialcostaspa.com/ | M21: industrialcostaspa.com | N21: Sí | O21: Viña del Mar | P21: Valparaíso | R21: Camino internacional 5465 Galpón F3, 1, Viña del Mar, Valparaíso | S21: Con número | T21: -32.962128 | U21: -71.510179 | V21: Taller de maquinaria | W21: Taller de maquinaria, Ingeniero mecánico, Empresa de construcciones metálicas, Servicio de reparación | X21: 23 | Y21: 4.1 | Z21: lunes:8 am–5:30 pm | martes:8 am–5:30 pm | miércoles:8 am–5:30 pm | jueves:8 am–5:30 pm | viernes:8 am–4:30 pm | sábado:Cerrado | domingo:Cerrado | AA21: https://www.google.com/maps?cid=16120114039017504461 | AB21: Empresa, Viña del Mar, Chile; Maquinaria industrial, Viña del Mar-Chile | AC21: 2
A22: ChIJh8dGG8PgiZYR9GB0wf0-N5s | B22: ROLIMAQ - VENTUS | C22: ROLIMAQ - VENTUS | E22: 1 | F22: Maquinaria / Industrial | G22: Alta | H22: Empresa industrial/logística en zona objetivo con canal de contacto | I22: 95 | J22: +56 9 5908 1452 | K22: Móvil | L22: http://www.rolimaq.cl/ | M22: rolimaq.cl | N22: Sí | O22: Viña del Mar | P22: Valparaíso | R22: 5 ORIENTE 608 VIÑA DEL MAR, Av. Colón 2877, Valparaíso, Viña del Mar, Valparaíso | S22: Con número | T22: -33.017182 | U22: -71.543249 | V22: Empresa de suministros industriales | W22: Empresa de suministros industriales | X22: 20 | Y22: 4.6 | Z22: lunes:9 am–6 pm | martes:9 am–6 pm | miércoles:9 am–6 pm | jueves:9 am–6 pm | viernes:9 am–6 pm | sábado:Cerrado | domingo:Cerrado | AA22: https://www.google.com/maps?cid=11184477459191193844 | AB22: Maquinaria industrial, Viña del Mar-Chile | AC22: 1
A23: ChIJe4q_Blp1YpYRjtN4sW_ahZs | B23: Delfrio Frigorífico de Valparaiso S.A. | C23: Delfrio Frigorífico de Valparaiso S.A. | D23: Delfrio Frigorífico de Valparaiso S.A. | E23: 2 | F23: Frío / Alimentos | G23: Alta | H23: Empresa industrial/logística en zona objetivo con canal de contacto | I23: 95 | J23: +56 32 229 1166 | K23: Fijo | L23: http://www.delfrio.cl/ | M23: delfrio.cl | N23: Sí | O23: Valparaíso | P23: Valparaíso | R23: Ruta 68 1240, Placilla, Valparaíso | S23: Con número | T23: -33.117636 | U23: -71.559892 | V23: Servicios de empresa a empresa | W23: Servicios de empresa a empresa | X23: 19 | Y23: 4.3 | Z23: lunes:8:30 am–5:30 pm | martes:8:30 am–5:30 pm | miércoles:8:30 am–5:30 pm | jueves:8:30 am–5:30 pm | viernes:8:30 am–5:30 pm | sábado:Cerrado | domingo:Cerrado | AA23: https://www.google.com/maps?cid=11206603421035058062 | AB23: Frigoríficos, Casablanca, Chile; Frigoríficos, V Región, Chile | AC23: 2
A24: ChIJ2UzWJj45YpYRxzMGbrKQI58 | B24: Distribuidor Autorizado Stihl San Antonio AGROMAR | C24: Distribuidor Autorizado Stihl San Antonio AGROMAR | E24: 1 | F24: Maquinaria / Industrial | G24: Alta | H24: Empresa industrial/logística en zona objetivo con canal de contacto | I24: 95 | J24: +56 9 8814 2767 | K24: Móvil | L24: https://redstihl.cl/productos/aceite-de-mezcla-premium-stihl-1l/ | M24: redstihl.cl | N24: Sí | O24: San Antonio | P24: Valparaíso | Q24: 2660750 | R24: Av. Chile 402, 2660750 San Antonio, Valparaíso | S24: Con número | T24: -33.61324 | U24: -71.60837 | V24: Cuarto de herramientas | W24: Cuarto de herramientas | X24: 15 | Y24: 4.1 | Z24: lunes:9 am–1:30 pm | martes:9 am–1:30 pm | miércoles:9 am–1:30 pm | jueves:9 am–1:30 pm | viernes:9 am–1:30 pm | sábado:Cerrado | domingo:Cerrado | AA24: https://www.google.com/maps?cid=11467168172239893447 | AB24: Maquinaria industrial, San Antonio -Chile; Maquinaria industrial, San Antonio, Chile | AC24: 2
A25: ChIJyU3YuwZHYpYR-gzSQD783YI | B25: Logistica el Cardal LOGEC, Malvilla | C25: Logistica el Cardal LOGEC, Malvilla | E25: 1 | F25: Logística / Almacenaje | G25: Alta | H25: Empresa industrial/logística en zona objetivo con canal de contacto | I25: 95 | J25: +56 9 5534 0864 | K25: Móvil | L25: http://www.logec.cl/ | M25: logec.cl | N25: Sí | O25: San Antonio | P25: Valparaíso | R25: Camino Malvilla 1378, Ruta G974, San Antonio, Valparaíso | S25: Con número | T25: -33.581295 | U25: -71.531363 | V25: Almacén | W25: Almacén, Oficinas de empresa | X25: 15 | Y25: 4.5 | Z25: lunes:8 am–1 pm | martes:8 am–1 pm | miércoles:8 am–1 pm | jueves:8 am–1 pm | viernes:8 am–1 pm | sábado:Cerrado | domingo:Cerrado | AA25: https://www.google.com/maps?cid=9429970539089366266 | AB25: Bodegas y almacenaje, San Antonio; Logística en San Antonio, Chile | AC25: 2
A26: ChIJK-5LjLLZiZYRavnzJYEFO28 | B26: Mibodega | C26: Mibodega | E26: 1 | F26: Logística / Almacenaje | G26: Alta | H26: Empresa industrial/logística en zona objetivo con canal de contacto | I26: 95 | J26: +56 9 3391 9144 | K26: Móvil | L26: https://mibodega.cl/ | M26: mibodega.cl | N26: Sí | O26: Quilpué | P26: Valparaíso | Q26: 2430000 | R26: Baquedano 1475, 2430000 Quilpué, Valparaíso | S26: Con número | T26: -33.042551 | U26: -71.416834 | V26: Bodega | W26: Bodega | X26: 15 | Y26: 4.3 | Z26: lunes:Abierto las 24 horas | martes:Abierto las 24 horas | miércoles:Abierto las 24 horas | jueves:Abierto las 24 horas | viernes:Abierto las 24 horas | sábado:Abierto las 24 horas | domingo:Abierto las 24 horas | AA26: https://www.google.com/maps?cid=8015006014081595754 | AB26: Bodegas, Valparaíso - Chile | AC26: 3
A27: ChIJ1d4Y2OXdiZYRXhgUpPYHODY | B27: Empresas Tuxpan | C27: Empresas Tuxpan | E27: 1 | F27: Otros / Servicios empresariales | G27: Alta | H27: Empresa industrial/logística en zona objetivo con canal de contacto | I27: 95 | J27: +56 32 268 0906 | K27: Fijo | L27: http://www.tuxpan.com/ | M27: tuxpan.com | N27: Sí | O27: Viña del Mar | P27: Valparaíso | Q27: 2520696 | R27: 7 Nte. 360, 2520696 Viña del Mar, Valparaíso | S27: Con número | T27: -33.016011 | U27: -71.554638 | V27: Oficinas de empresa | W27: Oficinas de empresa | X27: 14 | Y27: 5 | Z27: lunes:9 am–1 pm | martes:9 am–1 pm | miércoles:9 am–1 pm | jueves:9 am–1 pm | viernes:9 am–1 pm | sábado:Cerrado | domingo:Cerrado | AA27: https://www.google.com/maps?cid=3906881432640034910 | AB27: Empresa, Viña del Mar, Chile | AC27: 1
A28: ChIJ_VAVpefeiZYR4lFQkH6LgZU | B28: VIRGINIA - Empresas Demaria S.A. | C28: VIRGINIA - Empresas Demaria S.A. | D28: Empresas Demaria S.A. | E28: 2 | F28: Maquinaria / Industrial | G28: Alta | H28: Empresa industrial/logística en zona objetivo con canal de contacto | I28: 95 | J28: +56 32 226 7000 | K28: Fijo | L28: http://www.virginia.cl/ | M28: virginia.cl | N28: Sí | O28: Viña del Mar | P28: Valparaíso | Q28: 2562126 | R28: C. Limache 3535, 2562126 Viña del Mar, Valparaíso | S28: Con número | T28: -33.044718 | U28: -71.515161 | V28: Proveedor de productos de limpieza | W28: Proveedor de productos de limpieza | X28: 12 | Y28: 4.8 | Z28: lunes:8 am–6 pm | martes:8 am–6 pm | miércoles:8 am–6 pm | jueves:8 am–6 pm | viernes:8 am–6 pm | sábado:Cerrado | domingo:Cerrado | AA28: https://www.google.com/maps?cid=10773045159350260194 | AB28: Empresa, Viña del Mar, Chile | AC28: 1
A29: ChIJi5H3-nXbiZYRReEyOV_Qz3Y | B29: Bodegas Mauco | C29: Bodegas Mauco | Arriendo MiniBodegas | Galpones | Concón Viña del Mar Valparaíso Quilpué Quillota | E29: 1 | F29: Logística / Almacenaje | G29: Alta | H29: Empresa industrial/logística en zona objetivo con canal de contacto | I29: 95 | J29: +56 9 9779 1746 | K29: Móvil | L29: http://www.bodegasmauco.cl/ | M29: bodegasmauco.cl | N29: Sí | O29: Quillota | P29: Valparaíso | Q29: 2260000 | R29: RUTA f 360 KM1 Quillota, 2260000 Valparaíso, Quillota, Valparaíso | S29: Con número | T29: -32.917767 | U29: -71.434898 | V29: Bodega | W29: Bodega | X29: 11 | Y29: 4.5 | Z29: lunes:Abierto las 24 horas | martes:Abierto las 24 horas | miércoles:Abierto las 24 horas | jueves:Abierto las 24 horas | viernes:Abierto las 24 horas | sábado:Abierto las 24 horas | domingo:Abierto las 24 horas | AA29: https://www.google.com/maps?cid=8561290524054708549 | AB29: Bodegas, Valparaíso - Chile | AC29: 2 | AD29: nombre_corregido
A30: ChIJzeDAEPY5YpYRU7mFPUjuCbM | B30: Puerto San Antonio | C30: Puerto San Antonio | D30: PUERTO SAN ANTONIO | E30: 2 | F30: Portuario / Contenedores | G30: Alta | H30: Empresa industrial/logística en zona objetivo con canal de contacto | I30: 90 | J30: +56 35 258 6000 | K30: Fijo | L30: https://puertosanantonio.com/ | M30: puertosanantonio.com | N30: Sí | O30: San Antonio | P30: Valparaíso | Q30: 2660000 | R30: Antonio Núñez de Fonseca 1552, 2660000 San Antonio, Valparaíso | S30: Con número | T30: -33.574501 | U30: -71.626755 | V30: Empresa portuaria | W30: Empresa portuaria | X30: 521 | Y30: 4.5 | AA30: https://www.google.com/maps?cid=12901104601616726355 | AB30: Empresa, San Antonio, Chile | AC30: 1 | AD30: sin_horario
A31: ChIJz5AzAYY4YpYReXQuinPOZSI | B31: D&C San Antonio, patio principal | C31: D&C San Antonio, patio principal | E31: 1 | F31: Portuario / Contenedores | G31: Alta | H31: Empresa industrial/logística en zona objetivo con canal de contacto | I31: 90 | J31: +56 32 251 3302 | K31: Fijo | L31: http://www.dycsa.cl/ | M31: dycsa.cl | N31: Sí | O31: San Antonio | P31: Valparaíso | R31: Ruta G 94 F Nuevo Acceso al Puerto 3559 Barrio Industrial San Antonio, San Antonio, Valparaíso | S31: Con número | T31: -33.58876 | U31: -71.584752 | V31: Servicio de contenedores | W31: Servicio de contenedores, Proveedor de contenedores | X31: 464 | Y31: 3.2 | Z31: lunes:8:30 am–9 pm | martes:8:30 am–9 pm | miércoles:8:30 am–9 pm | jueves:8:30 am–9 pm | viernes:8:30 am–9 pm | sábado:8:30 am–3 pm | domingo:Cerrado | AA31: https://www.google.com/maps?cid=2478614165572187257 | AB31: Maquinaria industrial, San Antonio, Chile | AC31: 1
A32: ChIJsyA89Q9HYpYRmf5pd7-I9Lc | B32: Maersk Logistics and Service Chile SpA | C32: Maersk Logistics and Service Chile SpA | D32: Maersk Logistics and Service Chile SpA | E32: 2 | F32: Portuario / Contenedores | G32: Alta | H32: Empresa industrial/logística en zona objetivo con canal de contacto | I32: 90 | J32: +56 35 220 2700 | K32: Fijo | L32: http://www.maersk.com/ | M32: maersk.com | N32: Sí | O32: San Antonio | P32: Valparaíso | R32: Avenida Las Factorías 8150, San Antonio, Valparaíso | S32: Con número | T32: -33.576092 | U32: -71.536746 | V32: Terminal de contenedores | W32: Terminal de contenedores | X32: 292 | Y32: 3.9 | Z32: lunes:8 am–10 pm | martes:8 am–10 pm | miércoles:8 am–10 pm | jueves:8 am–10 pm | viernes:8 am–10 pm | sábado:8 am–6 pm | domingo:Cerrado | AA32: https://www.google.com/maps?cid=13255369959181778585 | AB32: Empresa, San Antonio, Chile; Logística en San Antonio, Chile | AC32: 2
A33: ChIJm3jkdoluYpYRGRGsx282Lfk | B33: Kingston Family Vineyards | C33: Kingston Family Vineyards | E33: 1 | F33: Vitivinícola / Agrícola | G33: Alta | H33: Empresa industrial/logística en zona objetivo con canal de contacto | I33: 90 | J33: +56 32 332 0150 | K33: Fijo | L33: http://www.kingstonvineyards.com/ | M33: kingstonvineyards.com | N33: Sí | O33: Casablanca | P33: Valparaíso | R33: Hijuela El Maitén S/N, Casablanca, Valparaíso | S33: Sin número | T33: -33.317081 | U33: -71.460571 | V33: Bodega | W33: Bodega, Atracción turística, Viñedo | X33: 216 | Y33: 4.8 | Z33: lunes:10 am–6 pm | martes:10 am–6 pm | miércoles:10 am–6 pm | jueves:10 am–6 pm | viernes:10 am–6 pm | sábado:10 am–6 pm | domingo:10 am–6 pm | AA33: https://www.google.com/maps?cid=17955067143115247897 | AB33: Bodegas, Valparaíso - Chile | AC33: 3 | AD33: direccion_imprecisa
A34: ChIJlbjaulVHYpYRQbbSWmVsH2A | B34: TLS Terminal Logistico San Antonio LTDA. | C34: TLS Terminal Logistico San Antonio LTDA. | E34: 1 | F34: Portuario / Contenedores | G34: Alta | H34: Empresa industrial/logística en zona objetivo con canal de contacto | I34: 90 | J34: +56 35 245 0146 | K34: Fijo | L34: http://www.tls.cl/ | M34: tls.cl | N34: Sí | O34: Cartagena | P34: Valparaíso | R34: Camino antiguo a Santiago SN, Cartagena, Valparaíso | S34: Sin número | T34: -33.551105 | U34: -71.569975 | V34: Servicio de contenedores | W34: Servicio de contenedores, Servicios de empresa a empresa | X34: 158 | Y34: 4.1 | Z34: lunes:7 am–11 pm | martes:7 am–11 pm | miércoles:7 am–11 pm | jueves:7 am–11 pm | viernes:7 am–11 pm | sábado:7 am–11 pm | domingo:Cerrado | AA34: https://www.google.com/maps?cid=6926373934490367553 | AB34: Logística en San Antonio, Chile | AC34: 1 | AD34: direccion_imprecisa
A35: ChIJe1d2vUZHYpYR1Qtvf2Vs_o0 | B35: Transportes Olivares | C35: Transportes Olivares | D35: Transportes Olivares | E35: 2 | F35: Transporte de carga | G35: Alta | H35: Empresa industrial/logística en zona objetivo con canal de contacto | I35: 90 | J35: +56 9 9637 6297 | K35: Móvil | L35: http://www.transportesolivares.cl/ | M35: transportesolivares.cl | N35: Sí | O35: San Antonio | P35: Valparaíso | Q35: 2660885 | R35: José Miguel Carrera Verdugo 830, of.6, 2660885 San Antonio, Valparaíso | S35: Con número | T35: -33.609401 | U35: -71.605023 | V35: Empresa de transporte por camión | W35: Empresa de transporte por camión | X35: 9 | Y35: 4 | Z35: lunes:9 am–7 pm | martes:9 am–7 pm | miércoles:9 am–7 pm | jueves:9 am–7 pm | viernes:9 am–6 pm | sábado:Cerrado | domingo:Cerrado | AA35: https://www.google.com/maps?cid=10231734586617826261 | AB35: Transporte de carga, San Antonio, Chile | AC35: 1
A36: ChIJKRr43uLdiZYROrcftBGiDMI | B36: TopMachine | C36: TopMachine | E36: 1 | F36: Maquinaria / Industrial | G36: Alta | H36: Empresa industrial/logística en zona objetivo con canal de contacto | I36: 90 | J36: +56 9 9222 6713 | K36: Móvil | L36: http://www.topmachine.cl/ | M36: topmachine.cl | N36: Sí | O36: Viña del Mar | P36: Valparaíso | R36: 1 - Calle Viana 837 Local 1, Viña del Mar, Valparaíso | S36: Con número | T36: -33.02606 | U36: -71.550078 | V36: Empresa de suministros industriales | W36: Empresa de suministros industriales | X36: 6 | Y36: 5 | Z36: lunes:9 am–2 pm | martes:9 am–2 pm | miércoles:9 am–2 pm | jueves:9 am–2 pm | viernes:9 am–2 pm | sábado:Cerrado | domingo:Cerrado | AA36: https://www.google.com/maps?cid=13982729139998668602 | AB36: Maquinaria industrial, Viña del Mar-Chile | AC36: 1
A37: ChIJyU-2Vd05YpYRTY3Hjq0as3w | B37: Forza Industrial | C37: Forza Industrial I HERRAMIENTAS I GENERADORES I SOLDADORAS I COMPRESORES I HIDROLAVADORAS I MOTOR ESTACIONARIOS | E37: 1 | F37: Maquinaria / Industrial | G37: Alta | H37: Empresa industrial/logística en zona objetivo con canal de contacto | I37: 90 | J37: +56 9 6629 5814 | K37: Móvil | L37: https://www.forzaindustrial.cl/ | M37: forzaindustrial.cl | N37: Sí | O37: San Antonio | P37: Valparaíso | Q37: 2660000 | R37: Av. Chile 55, Loc B, 2660000 Llolleo, San Antonio, Valparaíso | S37: Con número | T37: -33.61014 | U37: -71.608832 | V37: Tienda de herramientas y troqueles | W37: Tienda de herramientas y troqueles, Taller de maquinaria | X37: 5 | Y37: 5 | Z37: lunes:9 am–6 pm | martes:9 am–6 pm | miércoles:9 am–6 pm | jueves:9 am–6 pm | viernes:9 am–6 pm | sábado:Cerrado | domingo:Cerrado | AA37: https://www.google.com/maps?cid=8985555014261378381 | AB37: Maquinaria industrial, San Antonio -Chile; Maquinaria industrial, San Antonio, Chile | AC37: 2 | AD37: nombre_corregido
A38: ChIJCa2d-6vhiZYRdD4ps24G0NE | B38: Comercializadora de Carnes Gutiérrez y Gutiérrez | C38: Comercializadora de Carnes Gutiérrez y Gutiérrez | E38: 1 | F38: Frío / Alimentos | G38: Alta | H38: Empresa industrial/logística en zona objetivo con canal de contacto | I38: 90 | J38: +56 32 221 3124 | K38: Fijo | L38: https://www.carnesag.cl/ | M38: carnesag.cl | N38: Sí | O38: Valparaíso | P38: Valparaíso | Q38: 2340168 | R38: Juana Ross 155, 2340168 Valparaíso | S38: Con número | T38: -33.049856 | U38: -71.605408 | V38: Proveedor mayorista de alimentos | W38: Proveedor mayorista de alimentos | X38: 5 | Y38: 5 | Z38: lunes:8 am–2 pm | martes:8 am–2 pm | miércoles:8 am–2 pm | jueves:8 am–2 pm | viernes:8 am–2 pm | sábado:Cerrado | domingo:Cerrado | AA38: https://www.google.com/maps?cid=15118591021604748916 | AB38: Frigoríficos, V Región, Chile | AC38: 1
A39: ChIJiX4WM4veiZYRsQ5pBIXFnuw | B39: CER Chile | C39: CER Chile | E39: 1 | F39: Otros / Servicios empresariales | G39: Alta | H39: Empresa industrial/logística en zona objetivo con canal de contacto | I39: 90 | J39: +56 9 9745 4023 | K39: Móvil | L39: http://www.cer-chile.cl/ | M39: cer-chile.cl | N39: Sí | O39: Viña del Mar | P39: Valparaíso | R39: C. Limache 3437, Ofi 520, Viña del Mar, Valparaíso | S39: Con número | T39: -33.04325 | U39: -71.517542 | V39: Oficinas de empresa | W39: Oficinas de empresa | X39: 5 | Y39: 5 | Z39: lunes:8:30 am–5:30 pm | martes:8:30 am–5:30 pm | miércoles:8:30 am–5:30 pm | jueves:8:30 am–5:30 pm | viernes:8:30 am–5:30 pm | sábado:Cerrado | domingo:Cerrado | AA39: https://www.google.com/maps?cid=17050282414366592689 | AB39: Empresa, Viña del Mar, Chile | AC39: 1
A40: ChIJf-0CUiw5YpYRlKtqkW09qxo | B40: Transportes Olivares | C40: Transportes Olivares | D40: Transportes Olivares | E40: 2 | F40: Transporte de carga | G40: Alta | H40: Empresa industrial/logística en zona objetivo con canal de contacto | I40: 90 | J40: +56 9 9637 6297 | K40: Móvil | L40: http://www.transportesolivares.cl/ | M40: transportesolivares.cl | N40: Sí | O40: San Antonio | P40: Valparaíso | Q40: 2662776 | R40: Barros Luco 1814, 6, 2662776 Barrancas, San Antonio, Valparaíso | S40: Con número | T40: -33.596141 | U40: -71.613047 | V40: Empresa de transporte por camión | W40: Empresa de transporte por camión | X40: 3 | Y40: 5 | Z40: lunes:9 am–6:30 pm | martes:9 am–6:30 pm | miércoles:9 am–6:30 pm | jueves:9 am–6:30 pm | viernes:9 am–6:30 pm | sábado:Cerrado | domingo:Cerrado | AA40: https://www.google.com/maps?cid=1921697206804065172 | AB40: Transporte de carga, San Antonio, Chile | AC40: 1
...

Sheet Prospectos
A1: Empresa | B1: Grupo_empresa | C1: Segmento | D1: Relevancia | E1: Score_completitud | F1: Telefono | G1: Tipo_telefono | H1: Sitio_web | I1: Comuna | J1: Direccion | K1: Categoria_principal | L1: N_resenas | M1: Rating | N1: Google_Maps_URL | O1: Flags_calidad
A2: Viña Casas del Bosque | C2: Vitivinícola / Agrícola | D2: Alta | E2: 100 | F2: +56 2 2480 6941 | G2: Fijo | H2: http://casasdelbosque.cl/ | I2: Casablanca | J2: Ex Fundo Santa Rosa - Hijuela Nº 2, Casablanca, Valparaíso | K2: Bodega | L2: 1688 | M2: 4.6 | N2: https://www.google.com/maps?cid=10300753030481174526
A3: Casa Viñamar | C3: Vitivinícola / Agrícola | D3: Alta | E3: 100 | F3: +56 9 8242 3349 | G3: Móvil | H3: https://vsptwinegroup.com/tours-and-events/es/holidays/vinamar/ | I3: Casablanca | J3: Ruta 68, km 72, Casablanca, Valparaíso | K3: Viñedo | L3: 1636 | M3: 4.7 | N3: https://www.google.com/maps?cid=12329449938592924461
A4: Viña Indómita | C4: Vitivinícola / Agrícola | D4: Alta | E4: 100 | F4: +56 32 215 3902 | G4: Fijo | H4: http://www.indomita.cl/ | I4: Casablanca | J4: Ruta 68, Casablanca, Valparaíso | K4: Viñedo | L4: 1294 | M4: 4.5 | N4: https://www.google.com/maps?cid=4726476439834576790
A5: STI – San Antonio Terminal Internacional | C5: Portuario / Contenedores | D5: Alta | E5: 100 | F5: +56 35 220 1600 | G5: Fijo | H5: http://www.stiport.com/ | I5: San Antonio | J5: Bernardo O'Higgins Riquelme 2263, San Antonio, Valparaíso | K5: Empresa portuaria | L5: 928 | M5: 4 | N5: https://www.google.com/maps?cid=17908076345065983299 | O5: nombre_corregido
A6: Seaport | C6: Portuario / Contenedores | D6: Alta | E6: 100 | F6: +56 35 220 1500 | G6: Fijo | H6: http://www.seaport.cl/ | I6: San Antonio | J6: Ruta G86, Aguas Buenas N° 6729, Cruce a Cartagena, 2660000 San Antonio, Valparaíso | K6: Terminal de contenedores | L6: 775 | M6: 4 | N6: https://www.google.com/maps?cid=722349627185602024
A7: Bodegas RE | C7: Vitivinícola / Agrícola | D7: Alta | E7: 100 | F7: +56 9 9345 9114 | G7: Móvil | H7: http://www.bodegasre.cl/ | I7: Casablanca | J7: F-850 1380, Casablanca, Valparaíso | K7: Bodega | L7: 378 | M7: 4.8 | N7: https://www.google.com/maps?cid=9831653613549114241
A8: Puerto Columbo San Antonio | C8: Otros / Servicios empresariales | D8: Alta | E8: 100 | F8: +56 35 220 3701 | G8: Fijo | H8: http://www.puertocolumbo.com/ | I8: San Antonio | J8: Ruta Nacional 78, Barrio Industrial # 2375, San Antonio, Valparaíso | K8: Oficinas de empresa | L8: 260 | M8: 4.1 | N8: https://www.google.com/maps?cid=2900684782525532505
A9: Terminal y Servicios Logísticos Las Cadenas Ltda. | C9: Logística / Almacenaje | D9: Alta | E9: 100 | F9: +56 9 6122 2911 | G9: Móvil | H9: http://www.tlogisticolascadenas.cl/ | I9: Valparaíso | J9: 2821, Placilla, Cerro El Altar, Valparaíso | K9: Gran superficie | L9: 174 | M9: 4.3 | N9: https://www.google.com/maps?cid=11876321614386547164
A10: Ferretería Industrial METALMAR | C10: Maquinaria / Industrial | D10: Alta | E10: 100 | F10: +56 35 237 5110 | G10: Fijo | H10: http://www.metalmarchile.cl/ | I10: San Antonio | J10: Barros Luco 3058, 2663592 San Antonio, Valparaíso | K10: Ferretería | L10: 147 | M10: 4.6 | N10: https://www.google.com/maps?cid=4344495986652541285
A11: Tranvial | C11: Transporte de carga | D11: Alta | E11: 100 | F11: +56 600 006 0060 | G11: 600 (call center) | H11: https://www.tranvial.com/ | I11: Viña del Mar | J11: Edificio Reitz III - C. Limache 3437, Viña del Mar, Valparaíso | K11: Servicio de transporte | L11: 112 | M11: 4.3 | N11: https://www.google.com/maps?cid=5681984210172315765
A12: Calca | B12: Calca | C12: Otros / Servicios empresariales | D12: Alta | E12: 100 | F12: +56 32 274 1652 | G12: Fijo | H12: http://www.calca.cl/ | I12: Casablanca | J12: Av. Portales 90, 2480505 Casablanca, Valparaíso | K12: Comercio | L12: 56 | M12: 4.6 | N12: https://www.google.com/maps?cid=12175360959117859742
A13: Emergent Cold LatAm | C13: Logística / Almacenaje | D13: Alta | E13: 100 | F13: +56 600 656 0030 | G13: 600 (call center) | H13: https://emergentcoldlatam.com/ | I13: Casablanca | J13: F-852 4621, Lo Vásquez, Casablanca, Valparaíso | K13: Servicio de logística | L13: 55 | M13: 4 | N13: https://www.google.com/maps?cid=8119297471756617067
A14: Empresas Demaria S.A. | B14: Empresas Demaria S.A. | C14: Otros / Servicios empresariales | D14: Alta | E14: 100 | F14: +56 32 226 7000 | G14: Fijo | H14: https://demaria.cl/ | I14: Viña del Mar | J14: C. Limache 3535, 2562126 Viña del Mar, Valparaíso | K14: Oficinas de empresa | L14: 55 | M14: 4.4 | N14: https://www.google.com/maps?cid=3883389849630201333
A15: Egido Empresas | C15: Transporte de carga | D15: Alta | E15: 100 | F15: +56 9 7450 5347 | G15: Móvil | H15: http://www.egido.cl/ | I15: Valparaíso | J15: Camino La Pólvora 4, La Polvora, Valparaíso | K15: Empresa de transporte por camión | L15: 51 | M15: 4.3 | N15: https://www.google.com/maps?cid=12686360603857414265
A16: SERVIEX Ltda | C16: Logística / Almacenaje | D16: Alta | E16: 95 | F16: +56 9 4173 7193 | G16: Móvil | H16: https://serviexltda.cl/ | I16: Valparaíso | J16: Undécima Avenida 1730, Pc 384 Placilla, 2340000 Valparaíso | K16: Servicio de logística | L16: 49 | M16: 5 | N16: https://www.google.com/maps?cid=16285007002273081807
A17: Frigorífico Víctor Mancilla y Cía Ltda. | C17: Frío / Alimentos | D17: Alta | E17: 95 | F17: +56 32 262 7464 | G17: Fijo | H17: http://www.pesqueramancilla.cl/ | I17: Valparaíso | J17: R. Philippi 195, 2391272 Valparaíso | K17: Comercio | L17: 42 | M17: 4.2 | N17: https://www.google.com/maps?cid=3684435156110111844
A18: SL TRANSPORTE LTDA | C18: Transporte de carga | D18: Alta | E18: 95 | F18: +56 9 4008 8368 | G18: Móvil | H18: http://www.sltransporte.cl/ | I18: San Antonio | J18: Los Eucaliptus, Av. Aguas Buenas 597, 2660000 San Antonio, Valparaíso | K18: Empresa de transporte por camión | L18: 41 | M18: 4 | N18: https://www.google.com/maps?cid=4215131197082140141
A19: FRIGORIFICO FRIOMOR S.A | C19: Frío / Alimentos | D19: Alta | E19: 95 | F19: +56 9 9619 6628 | G19: Móvil | H19: http://www.friomor.cl/ | I19: Cartagena | J19: Las Majadas Lote 2 y 3 s/n, Cartagena, San Antonio, Cartagena, Valparaíso | K19: Almacén | L19: 26 | M19: 4.5 | N19: https://www.google.com/maps?cid=12355032772654322559
A20: OSKUPACK | C20: Maquinaria / Industrial | D20: Alta | E20: 95 | F20: +56 9 9822 4595 | G20: Móvil | H20: https://oskupack.cl/ | I20: Viña del Mar | J20: Camino Lajarilla 744, 2520000 Viña del Mar, Valparaíso | K20: Empresa de embalaje | L20: 25 | M20: 4.4 | N20: https://www.google.com/maps?cid=14917846952693574944
A21: INDUSTRIAL COSTA SPA | C21: Maquinaria / Industrial | D21: Alta | E21: 95 | F21: +56 9 8888 4772 | G21: Móvil | H21: http://industrialcostaspa.com/ | I21: Viña del Mar | J21: Camino internacional 5465 Galpón F3, 1, Viña del Mar, Valparaíso | K21: Taller de maquinaria | L21: 23 | M21: 4.1 | N21: https://www.google.com/maps?cid=16120114039017504461
A22: ROLIMAQ - VENTUS | C22: Maquinaria / Industrial | D22: Alta | E22: 95 | F22: +56 9 5908 1452 | G22: Móvil | H22: http://www.rolimaq.cl/ | I22: Viña del Mar | J22: 5 ORIENTE 608 VIÑA DEL MAR, Av. Colón 2877, Valparaíso, Viña del Mar, Valparaíso | K22: Empresa de suministros industriales | L22: 20 | M22: 4.6 | N22: https://www.google.com/maps?cid=11184477459191193844
A23: Delfrio Frigorífico de Valparaiso S.A. | B23: Delfrio Frigorífico de Valparaiso S.A. | C23: Frío / Alimentos | D23: Alta | E23: 95 | F23: +56 32 229 1166 | G23: Fijo | H23: http://www.delfrio.cl/ | I23: Valparaíso | J23: Ruta 68 1240, Placilla, Valparaíso | K23: Servicios de empresa a empresa | L23: 19 | M23: 4.3 | N23: https://www.google.com/maps?cid=11206603421035058062
A24: Distribuidor Autorizado Stihl San Antonio AGROMAR | C24: Maquinaria / Industrial | D24: Alta | E24: 95 | F24: +56 9 8814 2767 | G24: Móvil | H24: https://redstihl.cl/productos/aceite-de-mezcla-premium-stihl-1l/ | I24: San Antonio | J24: Av. Chile 402, 2660750 San Antonio, Valparaíso | K24: Cuarto de herramientas | L24: 15 | M24: 4.1 | N24: https://www.google.com/maps?cid=11467168172239893447
A25: Logistica el Cardal LOGEC, Malvilla | C25: Logística / Almacenaje | D25: Alta | E25: 95 | F25: +56 9 5534 0864 | G25: Móvil | H25: http://www.logec.cl/ | I25: San Antonio | J25: Camino Malvilla 1378, Ruta G974, San Antonio, Valparaíso | K25: Almacén | L25: 15 | M25: 4.5 | N25: https://www.google.com/maps?cid=9429970539089366266
A26: Mibodega | C26: Logística / Almacenaje | D26: Alta | E26: 95 | F26: +56 9 3391 9144 | G26: Móvil | H26: https://mibodega.cl/ | I26: Quilpué | J26: Baquedano 1475, 2430000 Quilpué, Valparaíso | K26: Bodega | L26: 15 | M26: 4.3 | N26: https://www.google.com/maps?cid=8015006014081595754
A27: Empresas Tuxpan | C27: Otros / Servicios empresariales | D27: Alta | E27: 95 | F27: +56 32 268 0906 | G27: Fijo | H27: http://www.tuxpan.com/ | I27: Viña del Mar | J27: 7 Nte. 360, 2520696 Viña del Mar, Valparaíso | K27: Oficinas de empresa | L27: 14 | M27: 5 | N27: https://www.google.com/maps?cid=3906881432640034910
A28: VIRGINIA - Empresas Demaria S.A. | B28: Empresas Demaria S.A. | C28: Maquinaria / Industrial | D28: Alta | E28: 95 | F28: +56 32 226 7000 | G28: Fijo | H28: http://www.virginia.cl/ | I28: Viña del Mar | J28: C. Limache 3535, 2562126 Viña del Mar, Valparaíso | K28: Proveedor de productos de limpieza | L28: 12 | M28: 4.8 | N28: https://www.google.com/maps?cid=10773045159350260194
A29: Bodegas Mauco | C29: Logística / Almacenaje | D29: Alta | E29: 95 | F29: +56 9 9779 1746 | G29: Móvil | H29: http://www.bodegasmauco.cl/ | I29: Quillota | J29: RUTA f 360 KM1 Quillota, 2260000 Valparaíso, Quillota, Valparaíso | K29: Bodega | L29: 11 | M29: 4.5 | N29: https://www.google.com/maps?cid=8561290524054708549 | O29: nombre_corregido
A30: Puerto San Antonio | B30: PUERTO SAN ANTONIO | C30: Portuario / Contenedores | D30: Alta | E30: 90 | F30: +56 35 258 6000 | G30: Fijo | H30: https://puertosanantonio.com/ | I30: San Antonio | J30: Antonio Núñez de Fonseca 1552, 2660000 San Antonio, Valparaíso | K30: Empresa portuaria | L30: 521 | M30: 4.5 | N30: https://www.google.com/maps?cid=12901104601616726355 | O30: sin_horario
A31: D&C San Antonio, patio principal | C31: Portuario / Contenedores | D31: Alta | E31: 90 | F31: +56 32 251 3302 | G31: Fijo | H31: http://www.dycsa.cl/ | I31: San Antonio | J31: Ruta G 94 F Nuevo Acceso al Puerto 3559 Barrio Industrial San Antonio, San Antonio, Valparaíso | K31: Servicio de contenedores | L31: 464 | M31: 3.2 | N31: https://www.google.com/maps?cid=2478614165572187257
A32: Maersk Logistics and Service Chile SpA | B32: Maersk Logistics and Service Chile SpA | C32: Portuario / Contenedores | D32: Alta | E32: 90 | F32: +56 35 220 2700 | G32: Fijo | H32: http://www.maersk.com/ | I32: San Antonio | J32: Avenida Las Factorías 8150, San Antonio, Valparaíso | K32: Terminal de contenedores | L32: 292 | M32: 3.9 | N32: https://www.google.com/maps?cid=13255369959181778585
A33: Kingston Family Vineyards | C33: Vitivinícola / Agrícola | D33: Alta | E33: 90 | F33: +56 32 332 0150 | G33: Fijo | H33: http://www.kingstonvineyards.com/ | I33: Casablanca | J33: Hijuela El Maitén S/N, Casablanca, Valparaíso | K33: Bodega | L33: 216 | M33: 4.8 | N33: https://www.google.com/maps?cid=17955067143115247897 | O33: direccion_imprecisa
A34: TLS Terminal Logistico San Antonio LTDA. | C34: Portuario / Contenedores | D34: Alta | E34: 90 | F34: +56 35 245 0146 | G34: Fijo | H34: http://www.tls.cl/ | I34: Cartagena | J34: Camino antiguo a Santiago SN, Cartagena, Valparaíso | K34: Servicio de contenedores | L34: 158 | M34: 4.1 | N34: https://www.google.com/maps?cid=6926373934490367553 | O34: direccion_imprecisa
A35: Transportes Olivares | B35: Transportes Olivares | C35: Transporte de carga | D35: Alta | E35: 90 | F35: +56 9 9637 6297 | G35: Móvil | H35: http://www.transportesolivares.cl/ | I35: San Antonio | J35: José Miguel Carrera Verdugo 830, of.6, 2660885 San Antonio, Valparaíso | K35: Empresa de transporte por camión | L35: 9 | M35: 4 | N35: https://www.google.com/maps?cid=10231734586617826261
A36: TopMachine | C36: Maquinaria / Industrial | D36: Alta | E36: 90 | F36: +56 9 9222 6713 | G36: Móvil | H36: http://www.topmachine.cl/ | I36: Viña del Mar | J36: 1 - Calle Viana 837 Local 1, Viña del Mar, Valparaíso | K36: Empresa de suministros industriales | L36: 6 | M36: 5 | N36: https://www.google.com/maps?cid=13982729139998668602
A37: Forza Industrial | C37: Maquinaria / Industrial | D37: Alta | E37: 90 | F37: +56 9 6629 5814 | G37: Móvil | H37: https://www.forzaindustrial.cl/ | I37: San Antonio | J37: Av. Chile 55, Loc B, 2660000 Llolleo, San Antonio, Valparaíso | K37: Tienda de herramientas y troqueles | L37: 5 | M37: 5 | N37: https://www.google.com/maps?cid=8985555014261378381 | O37: nombre_corregido
A38: Comercializadora de Carnes Gutiérrez y Gutiérrez | C38: Frío / Alimentos | D38: Alta | E38: 90 | F38: +56 32 221 3124 | G38: Fijo | H38: https://www.carnesag.cl/ | I38: Valparaíso | J38: Juana Ross 155, 2340168 Valparaíso | K38: Proveedor mayorista de alimentos | L38: 5 | M38: 5 | N38: https://www.google.com/maps?cid=15118591021604748916
A39: CER Chile | C39: Otros / Servicios empresariales | D39: Alta | E39: 90 | F39: +56 9 9745 4023 | G39: Móvil | H39: http://www.cer-chile.cl/ | I39: Viña del Mar | J39: C. Limache 3437, Ofi 520, Viña del Mar, Valparaíso | K39: Oficinas de empresa | L39: 5 | M39: 5 | N39: https://www.google.com/maps?cid=17050282414366592689
A40: Transportes Olivares | B40: Transportes Olivares | C40: Transporte de carga | D40: Alta | E40: 90 | F40: +56 9 9637 6297 | G40: Móvil | H40: http://www.transportesolivares.cl/ | I40: San Antonio | J40: Barros Luco 1814, 6, 2662776 Barrancas, San Antonio, Valparaíso | K40: Empresa de transporte por camión | L40: 3 | M40: 5 | N40: https://www.google.com/maps?cid=1921697206804065172
...

Sheet Revisar_descartados
A1: Empresa | B1: Nombre_original | C1: Relevancia | D1: Motivo_relevancia | E1: Categorias | F1: Direccion | G1: Telefono | H1: Google_Maps_URL
A2: Vivero Las Higueras | B2: Vivero Las Higueras | C2: Baja | D2: Negocio minorista / no industrial (Centro de jardinería) | E2: Centro de jardinería, Jardín, Vivero | F2: Ambrosio O'Higgins 2159, 9630000 Curacavi, Curacaví, Región Metropolitana | G2: +56 9 4592 5759 | H2: https://www.google.com/maps?cid=12293987451101561929
A3: Equipos Gastronomicos Rorland | B3: Equipos Gastronomicos Rorland | C3: Baja | D3: Comercio minorista de equipos gastronómicos | E3: Comercio | F3: Independencia 2377, 2363026 Valparaíso | G3: +56 32 225 3651 | H3: https://www.google.com/maps?cid=1219856587436675942
A4: Corralosorno Quilpué | B4: Corralosorno Quilpué | C4: Baja | D4: Negocio minorista / no industrial (Carnicería) | E4: Carnicería | F4: Av. Industrial 1750, 2420468 Quilpué, Valparaíso | G4: +56 9 3414 8336 | H4: https://www.google.com/maps?cid=17096525727655765651
A5: Escuela Industrial San Antonio | B5: Escuela Industrial San Antonio | C5: Baja | D5: Negocio minorista / no industrial (Escuela secundaria de formación profesional) | E5: Escuela secundaria de formación profesional | F5: Centenario 278, 2661311 San Antonio, Valparaíso | G5: +56 35 229 1641 | H5: https://www.google.com/maps?cid=4177057867605349442
A6: Centro de Negocios Viña | B6: Centro de Negocios Viña | C6: Baja | D6: Negocio minorista / no industrial (Alquiler de oficinas virtuales) | E6: Alquiler de oficinas virtuales | F6: 1 Nte. 461, Ofi N°703, 2520307 Viña del Mar, Valparaíso | G6: +56 32 320 5459 | H6: https://www.google.com/maps?cid=6431957245828810260
A7: Centro de Negocios Sercotec Viña del Mar | B7: Centro de Negocios Sercotec Viña del Mar | C7: Baja | D7: Negocio minorista / no industrial (Consultora de administración empresarial) | E7: Consultora de administración empresarial | F7: 10 Nte 1059, 2531034 Viña del Mar, Valparaíso | G7: +56 9 8536 1466 | H7: https://www.google.com/maps?cid=3631155152832843340
A8: Frigorificio de Osorno .S.A Sala de ventas Quilpué | B8: Frigorificio de Osorno .S.A Sala de ventas Quilpué | C8: Baja | D8: Negocio minorista / no industrial (Carnicería) | E8: Carnicería, Establecimiento de servicios, Supermercado | G8: +56 9 3414 8336 | H8: https://www.google.com/maps?cid=11703444163609919525
A9: Casablanca chile Vinamar | B9: Casablanca chile Vinamar | C9: Baja | D9: Negocio minorista / no industrial (Restaurante) | E9: Restaurante | F9: Santiago - Valparaíso, Casablanca, Valparaíso | G9: +56 32 275 4300 | H9: https://www.google.com/maps?cid=943218181419965127
A10: La Industrial Outlet | B10: La Industrial Outlet | C10: Baja | D10: Ferretería minorista | E10: Ferretería | F10: San Antonio 1280, Loc 18, 2530970 Viña del Mar, Valparaíso | G10: +56 9 8900 4831 | H10: https://www.google.com/maps?cid=1712249352124228757
A11: Bodega El Granero | B11: Bodega El Granero | C11: Baja | D11: Negocio minorista / no industrial (Tienda de alimentos para animales) | E11: Tienda de alimentos para animales | F11: Chacabuco 2726, Chacabuco 2780, 2340000 Valparaíso | G11: +56 32 222 9968 | H11: https://www.google.com/maps?cid=17202916291960963566
A12: BODEGA URRIOLA | B12: BODEGA URRIOLA | C12: Baja | D12: Negocio minorista / no industrial (Tienda de bebidas alcohólicas) | E12: Tienda de bebidas alcohólicas, Delicatessen, Tienda de vinos | F12: Urriola 393, 2370654 Valparaíso | G12: +56 9 3698 0027 | H12: https://www.google.com/maps?cid=900648830059042680
A13: Bodega Chacabuco | B13: Bodega Chacabuco | C13: Baja | D13: Negocio minorista / no industrial (Tienda de alimentación) | E13: Tienda de alimentación | F13: Chacabuco 2748, 2340103 Valparaíso | G13: +56 32 211 6704 | H13: https://www.google.com/maps?cid=7102832595028841173
A14: Carniceria Nacional | B14: Carniceria Nacional | C14: Baja | D14: Negocio minorista / no industrial (Carnicería) | E14: Carnicería | F14: Sta. Luisa 980, Casablanca, Valparaíso | G14: +56 9 4526 4464 | H14: https://www.google.com/maps?cid=14628573641233465999
A15: Agricom | B15: Agricom | C15: Baja | D15: Negocio minorista / no industrial (Frutería) | E15: Frutería | F15: Curacavi, Curacaví, Región Metropolitana | G15: +56 9 9133 3721 | H15: https://www.google.com/maps?cid=13116013631737311498
A16: Carnicería Carnes Casablanca | B16: Carnicería Carnes Casablanca | C16: Baja | D16: Negocio minorista / no industrial (Carnicería) | E16: Carnicería | F16: Av. Portales 771, 2480427 Casablanca, Valparaíso | G16: +56 9 9689 5670 | H16: https://www.google.com/maps?cid=7002970082433172947
A17: Bodega el Campo | B17: Bodega el Campo | C17: Baja | D17: Comercio minorista | E17: Bodega | F17: Chacabuco 2780, 2340103 Valparaíso | G17: +56 32 222 9968 | H17: https://www.google.com/maps?cid=17924098167821079798
A18: Foco Alimentos Spa | B18: Foco Alimentos Spa | C18: Baja | D18: Negocio minorista / no industrial (Carnicería) | E18: Carnicería | F18: El Boldo 366, Loc 2 y 3, 2710000 Algarrobo, Valparaíso | G18: +56 9 9904 0482 | H18: https://www.google.com/maps?cid=9977597838848029023
A19: Terminal de Buses De Viña Del Mar | B19: Terminal de Buses De Viña Del Mar | C19: Baja | D19: Negocio minorista / no industrial (Empresa de autobuses) | E19: Empresa de autobuses | F19: Av. Valparaíso 1055, 2520479 Viña del Mar, Valparaíso | H19: https://www.google.com/maps?cid=6437795891577142128
