Workbook

Sheet Contactos
A1: ID | B1: Nombre | C1: Cargo | D1: Empresa | E1: País | F1: Email | G1: LinkedIn | H1: Origen | I1: Estado | J1: Prioridad | K1: Próxima acción | L1: Notas | M1: Rubro(s) | N1: Segmento SafetyMind | O1: Teléfono(s) | P1: Web | Q1: Dirección | R1: Ciudad/Región | S1: Anunciante
A2: 1 | D2: Administración de Empresas S.A.C. | E2: Perú | F2: dpalacios@aesa.com.pe | H2: Directorio SSO 2026 | I2: Prospecto | J2: Alta | K2: Identificar Gerente SSOMA/HSE en LinkedIn y proponer demo | L2: Directorio SSO 2026, pág. PDF 37. Sin contacto nominal; no inventar decisor. | M2: Empresas contratistas y conexas | N2: Cliente potencial – operación de alto riesgo | O2: 7062230 | P2: www.aesa.com.pe | Q2: Cl. Las Begonias 441 Of. 1401 Urb. Jardín - San Isidro - Lima | R2: Lima | S2: No
A3: 2 | D3: Ahorro de Energía y Mantenimiento Industrial S.A.C. | E3: Perú | F3: ademinsa@ademinsa.com | H3: Directorio SSO 2026 | I3: Prospecto | J3: Alta | K3: Identificar Gerente SSOMA/HSE en LinkedIn y proponer demo | L3: Directorio SSO 2026, pág. PDF 18. Sin contacto nominal; no inventar decisor. Otros emails: atencionalcliente@ademinsa.com. | M3: Mantenimiento industrial | N3: Cliente potencial – operación de alto riesgo | O3: 2750082 | P3: www.ademinsa.com | Q3: Cl. Cerro Azul 479 Of. 101A Urb. San Ignacio de Loyola Santiago de Surco - Lima | R3: Lima | S3: No
A4: 3 | D4: AiD Ingenieros S.A.C. | E4: Perú | F4: aidingenieros@aidingenieros.com.pe | H4: Directorio SSO 2026 | I4: Prospecto | J4: Alta | K4: Identificar Gerente SSOMA/HSE en LinkedIn y proponer demo | L4: Directorio SSO 2026, pág. PDF 18, 37. Sin contacto nominal; no inventar decisor. | M4: Mantenimiento industrial; Empresas contratistas y conexas | N4: Cliente potencial – operación de alto riesgo | O4: (054) 446162 | P4: www.aidingenieros.com.pe | Q4: Mz. C Lt. 5B Urb. Magisterial II Etapa Yanahuara - Arequipa | R4: Arequipa | S4: No
A5: 4 | D5: AK Drilling International S.A. | E5: Perú | F5: global@akdint.com | H5: Directorio SSO 2026 | I5: Prospecto | J5: Alta | K5: Identificar Gerente SSOMA/HSE en LinkedIn y proponer demo | L5: Directorio SSO 2026, pág. PDF 20, 37. Sin contacto nominal; no inventar decisor. | M5: Perforación geológica; Empresas contratistas y conexas | N5: Cliente potencial – operación de alto riesgo | O5: 2513380 | P5: www.akdrillinginternational.com | Q5: Cl. Perseo Mz. J Lt. 12 Urb. La Campiña Chorrillos - Lima | R5: Lima | S5: No
A6: 5 | D6: Alicomser Contratistas S.A.C. | E6: Perú | F6: alicomser@alicomser.com | H6: Directorio SSO 2026 | I6: Prospecto | J6: Alta | K6: Identificar Gerente SSOMA/HSE en LinkedIn y proponer demo | L6: Directorio SSO 2026, pág. PDF 32, 35, 37. Sin contacto nominal; no inventar decisor. | M6: Sostenimiento de rocas y suelos; Ventilación industrial y subterránea; Empresas contratistas y conexas | N6: Cliente potencial – operación de alto riesgo | O6: 5310928 / 914946043 | P6: www.alicomser.com | Q6: Av. Universitaria Mz. H Lt. 7 P. 2 Asoc. Daniel Alcides Carrión II Los Olivos - Lima | R6: Lima | S6: No
A7: 6 | D7: Almacenera Pacífico S.A.C. | E7: Perú | F7: ventas@alpa.com.pe | H7: Directorio SSO 2026 | I7: Prospecto | J7: Alta | K7: Identificar Gerente SSOMA/HSE en LinkedIn y proponer demo | L7: Directorio SSO 2026, pág. PDF 34. Sin contacto nominal; no inventar decisor. | M7: Transporte de combustibles y materiales peligrosos | N7: Cliente potencial – operación de alto riesgo | O7: 6181620 / 983283750 | P7: www.alpa.com.pe | Q7: Carretera Antigua Panamericana Sur km 29.5 - Lurín - Lima | R7: Lima | S7: No
A8: 7 | D8: Almasa S.R.L. | E8: Perú | F8: almasa@almasa.com.pe | H8: Directorio SSO 2026 | I8: Prospecto | J8: Alta | K8: Identificar Gerente SSOMA/HSE en LinkedIn y proponer demo | L8: Directorio SSO 2026, pág. PDF 37. Sin contacto nominal; no inventar decisor. | M8: Empresas contratistas y conexas | N8: Cliente potencial – operación de alto riesgo | O8: 3720204 | P8: www.almasa.com.pe | Q8: Jr. Monterosa 270 Of. 602 Urb. Chacarilla del Estanque Santiago de Surco - Lima | R8: Lima | S8: No
A9: 8 | D9: American Sur Internacional S.A.C. | E9: Perú | F9: info@americasurinternacional.com | H9: Directorio SSO 2026 | I9: Prospecto | J9: Alta | K9: Identificar Gerente SSOMA/HSE en LinkedIn y proponer demo | L9: Directorio SSO 2026, pág. PDF 20. Sin contacto nominal; no inventar decisor. | M9: Perforación geológica | N9: Cliente potencial – operación de alto riesgo | O9: 2190700 | P9: www.americasurinternacional.com | Q9: Av. Alameda Sur 568 Urb. Villa Marina Chorrillos - Lima | R9: Lima | S9: No
A10: 9 | D10: Anddes Asociados S.A.C. | E10: Perú | F10: info@anddes.com | H10: Directorio SSO 2026 | I10: Prospecto | J10: Alta | K10: Identificar Gerente SSOMA/HSE en LinkedIn y proponer demo | L10: Directorio SSO 2026, pág. PDF 20, 37. Sin contacto nominal; no inventar decisor. | M10: Medioambiente: productos y servicios; Empresas contratistas y conexas | N10: Cliente potencial – operación de alto riesgo | O10: 3174900 | P10: www.anddes.com | Q10: Av. Javier Prado Este Cdra.48, Edificio Capital Golf Of. 1301 - Santiago de Surco Lima | R10: Lima | S10: No
A11: 10 | D11: AOM Suministros Industriales S.A.C. | E11: Perú | F11: info@aom.pe | H11: Directorio SSO 2026 | I11: Prospecto | J11: Alta | K11: Identificar Gerente SSOMA/HSE en LinkedIn y proponer demo | L11: Directorio SSO 2026, pág. PDF 7, 14, 19, 20. Sin contacto nominal; no inventar decisor. | M11: Campamentos e instalaciones; Equipos de protección personal; Máquinas, herramientas y repuestos; Perforación geológica | N11: Cliente potencial – operación de alto riesgo | P11: www.aom.pe | Q11: Jr. Cruz del Sur 140 Of.1503, Santiago de Surco - Lima | R11: Lima | S11: No
A12: 11 | D12: APM Terminals Inland Services S.A. | E12: Perú | F12: apmtcservicios@apmterminals.com | H12: Directorio SSO 2026 | I12: Prospecto | J12: Alta | K12: Identificar Gerente SSOMA/HSE en LinkedIn y proponer demo | L12: Directorio SSO 2026, pág. PDF 34. Sin contacto nominal; no inventar decisor. | M12: Transporte de combustibles y materiales peligrosos | N12: Cliente potencial – operación de alto riesgo | O12: 2008800 | P12: www.apmterminals.com | Q12: Av. Néstor Gambetta km 4.5 - Callao | R12: Callao | S12: No
A13: 12 | D13: Arkel Perú S.A.C. | E13: Perú | F13: info@arkel.pe | H13: Directorio SSO 2026 | I13: Prospecto | J13: Alta | K13: Identificar Gerente SSOMA/HSE en LinkedIn y proponer demo | L13: Directorio SSO 2026, pág. PDF 32. Sin contacto nominal; no inventar decisor. | M13: Sostenimiento de rocas y suelos | N13: Cliente potencial – operación de alto riesgo | O13: 901284293 | P13: www.arkel.pe | Q13: Jr. Ricardo Palma 174 Primera Zona Collique - Comas Lima | R13: Lima | S13: No
A14: 13 | D14: Beagle Shipping S.A. | E14: Perú | F14: servicioalcliente@beagle.com.pe | H14: Directorio SSO 2026 | I14: Prospecto | J14: Alta | K14: Identificar Gerente SSOMA/HSE en LinkedIn y proponer demo | L14: Directorio SSO 2026, pág. PDF 34. Sin contacto nominal; no inventar decisor. | M14: Transporte de combustibles y materiales peligrosos | N14: Cliente potencial – operación de alto riesgo | O14: 6168585 | P14: www.beagle.com.pe | Q14: Jr. Comandante Jiménez 120 Of. B Magdalena del Mar - Lima | R14: Lima | S14: No
A15: 14 | D15: Beton Terra Ingenieros S.A.C. | E15: Perú | F15: contacto@betonterra.com | H15: Directorio SSO 2026 | I15: Prospecto | J15: Alta | K15: Identificar Gerente SSOMA/HSE en LinkedIn y proponer demo | L15: Directorio SSO 2026, pág. PDF 20. Sin contacto nominal; no inventar decisor. | M15: Perforación geológica | N15: Cliente potencial – operación de alto riesgo | O15: 991888076 | P15: www.betonterra.pe | Q15: Jr. Pablo Picasso Mz. B1 Lt. 13 Of. 201, Los Álamos de Monterrico Etapa 3 - Santiago de Surco - Lima | R15: Lima | S15: No
A16: 15 | D16: BISA | E16: Perú | F16: comercial@bisa.com.pe | H16: Directorio SSO 2026 | I16: Prospecto | J16: Alta | K16: Identificar Gerente SSOMA/HSE en LinkedIn y proponer demo | L16: Directorio SSO 2026, pág. PDF 37. Sin contacto nominal; no inventar decisor. | M16: Empresas contratistas y conexas | N16: Cliente potencial – operación de alto riesgo | O16: 6266200 | P16: www.bisa.com.pe | Q16: Av. Andrés Reyes 338 Of. Piso 5 - San Isidro - Lima | R16: Lima | S16: No
A17: 16 | D17: Boart Longyear S.A.C. | E17: Perú | F17: info@boartlongyear.com | H17: Directorio SSO 2026 | I17: Prospecto | J17: Alta | K17: Identificar Gerente SSOMA/HSE en LinkedIn y proponer demo | L17: Directorio SSO 2026, pág. PDF 19, 20, 37. Sin contacto nominal; no inventar decisor. | M17: Máquinas, herramientas y repuestos; Perforación geológica; Empresas contratistas y conexas | N17: Cliente potencial – operación de alto riesgo | O17: 2034200 | P17: www.boartlongyear.com | Q17: Av. El Derby 055 Torre 1 Of. 601 Centro de Negocios Cronos - Santiago de Surco Lima | R17: Lima | S17: No
A18: 17 | D18: Bouby S.A.C. | E18: Perú | F18: boubysac@boubysac.com | H18: Directorio SSO 2026 | I18: Prospecto | J18: Alta | K18: Identificar Gerente SSOMA/HSE en LinkedIn y proponer demo | L18: Directorio SSO 2026, pág. PDF 37. Sin contacto nominal; no inventar decisor. | M18: Empresas contratistas y conexas | N18: Cliente potencial – operación de alto riesgo | O18: 3482991 | P18: www.boubysac.com | Q18: Av. La Mar 267, Santa Anita - Lima | R18: Lima | S18: No
A19: 18 | D19: C&V International SRL | E19: Perú | F19: ventas@cvinternational.com.pe | H19: Directorio SSO 2026 | I19: Prospecto | J19: Alta | K19: Identificar Gerente SSOMA/HSE en LinkedIn y proponer demo | L19: Directorio SSO 2026, pág. PDF 37. Sin contacto nominal; no inventar decisor. | M19: Empresas contratistas y conexas | N19: Cliente potencial – operación de alto riesgo | O19: 5156714 | P19: www.cvinternational.com.pe | Q19: Cl. Emiliano Tenorio Gadea 260 Urb. San Amadeo de Garagay San Martin de Porres - Lima | R19: Lima | S19: No
A20: 19 | D20: Canchanya Ingenieros S.R.L. | E20: Perú | F20: hcanchanya@cis.com.pe | H20: Directorio SSO 2026 | I20: Prospecto | J20: Alta | K20: Identificar Gerente SSOMA/HSE en LinkedIn y proponer demo | L20: Directorio SSO 2026, pág. PDF 20, 32, 36, 37. Sin contacto nominal; no inventar decisor. | M20: Perforación geológica; Sostenimiento de rocas y suelos; Voladura, explosivos y polvorines; Empresas contratistas y conexas | N20: Cliente potencial – operación de alto riesgo | O20: 7172709 | P20: www.cis.com.pe | Q20: Av. Separadora Industrial 1910 Urb. Residencial Monterrico - La Molina Lima | R20: Lima | S20: No
A21: 20 | B21: Gisella Ojeda | D21: Castem E.I.R.L. | E21: Perú | F21: gojeda@castem.com.pe | H21: Directorio SSO 2026 | I21: Prospecto | J21: Alta | K21: Identificar Gerente SSOMA/HSE en LinkedIn y proponer demo | L21: Directorio SSO 2026, pág. PDF 32, 37. Anunciante (inversión activa en SST). Contacto publicado; validar vigencia. | M21: Sostenimiento de rocas y suelos; Empresas contratistas y conexas | N21: Cliente potencial – operación de alto riesgo | O21: (01) 5274146 / 946084469 | P21: www.castem.com.pe | Q21: Cl. San Francisco Mz.G Lt. 88 Urb. Leoncio Prado, Puente Piedra - Lima | R21: Lima | S21: Sí
A22: 21 | D22: CEMPROTEC S.A.C. | E22: Perú | F22: comercial@cemprotec.com.pe | H22: Directorio SSO 2026 | I22: Prospecto | J22: Alta | K22: Identificar Gerente SSOMA/HSE en LinkedIn y proponer demo | L22: Directorio SSO 2026, pág. PDF 37. Sin contacto nominal; no inventar decisor. | M22: Empresas contratistas y conexas | N22: Cliente potencial – operación de alto riesgo | O22: 989156472 | P22: www.cemprotec.com.pe | Q22: Av. Las Praderas de Lurín Mz.A Lt.9 Grupo D Panamericana Sur km 37.22 Lurín - Lima | R22: Lima | S22: No
A23: 22 | D23: CERV / Certus S.A.C. | E23: Perú | F23: comercial@cerv.com.pe | H23: Directorio SSO 2026 | I23: Prospecto | J23: Alta | K23: Identificar Gerente SSOMA/HSE en LinkedIn y proponer demo | L23: Directorio SSO 2026, pág. PDF 9, 18. Sin contacto nominal; no inventar decisor. | M23: Capacitación, consultoría y auditoría; Mantenimiento industrial | N23: Cliente potencial – operación de alto riesgo | O23: 980508948 | P23: www.cerv.com.pe | Q23: Cl. Melgar 620 Of. 201 Cerro Colorado - Arequipa | R23: Arequipa | S23: No
A24: 23 | D24: Cesel Ingenieros | E24: Perú | F24: cesel@cesel.com.pe | H24: Directorio SSO 2026 | I24: Prospecto | J24: Alta | K24: Identificar Gerente SSOMA/HSE en LinkedIn y proponer demo | L24: Directorio SSO 2026, pág. PDF 37. Sin contacto nominal; no inventar decisor. | M24: Empresas contratistas y conexas | N24: Cliente potencial – operación de alto riesgo | O24: 7055000 | P24: www.cesel.com.pe | Q24: Av. José Gálvez Barrenechea 646 Urb. Córpac - San Isidro - Lima | R24: Lima | S24: No
A25: 24 | D25: Cime Ingenieros S.R.L. | E25: Perú | F25: info@cimeingenieros.com | H25: Directorio SSO 2026 | I25: Prospecto | J25: Alta | K25: Identificar Gerente SSOMA/HSE en LinkedIn y proponer demo | L25: Directorio SSO 2026, pág. PDF 18, 37. Sin contacto nominal; no inventar decisor. | M25: Mantenimiento industrial; Empresas contratistas y conexas | N25: Cliente potencial – operación de alto riesgo | O25: 5623571 / 4521115 | P25: www.cimeingenieros.com | Q25: Cl. Gamma 180 Urb. Parque Internacional de Industria y Comercio Callao | R25: Callao | S25: No
A26: 25 | D26: Cimec Ingenieros S.A. | E26: Perú | F26: info@cimec.com | H26: Directorio SSO 2026 | I26: Prospecto | J26: Alta | K26: Identificar Gerente SSOMA/HSE en LinkedIn y proponer demo | L26: Directorio SSO 2026, pág. PDF 37. Sin contacto nominal; no inventar decisor. Otros emails: noticimec@cimec.com. | M26: Empresas contratistas y conexas | N26: Cliente potencial – operación de alto riesgo | O26: 7193630 / 995746542 | P26: www.cimec.com | Q26: Cl. Ismael Bielich Flores 753 Urb. Benavides - Santiago de Surco - Lima | R26: Lima | S26: No
A27: 26 | D27: CN Minería y Construcción S.A.C. | E27: Perú | F27: cnsac@cnsac.com.pe | H27: Directorio SSO 2026 | I27: Prospecto | J27: Alta | K27: Identificar Gerente SSOMA/HSE en LinkedIn y proponer demo | L27: Directorio SSO 2026, pág. PDF 37. Sin contacto nominal; no inventar decisor. | M27: Empresas contratistas y conexas | N27: Cliente potencial – operación de alto riesgo | O27: 6128989 | P27: www.cnsac.com.pe | Q27: Av. Mariscal Nieto 119 Urb. El Pino Industrial - San Luis - Lima | R27: Lima | S27: No
A28: 27 | D28: Coansa del Perú Ingenieros S.A.C. | E28: Perú | F28: asistente.gerencia@coansadelperu.com | H28: Directorio SSO 2026 | I28: Prospecto | J28: Alta | K28: Identificar Gerente SSOMA/HSE en LinkedIn y proponer demo | L28: Directorio SSO 2026, pág. PDF 37. Sin contacto nominal; no inventar decisor. | M28: Empresas contratistas y conexas | N28: Cliente potencial – operación de alto riesgo | O28: (076) 348759 | P28: www.coansadelperu.com | Q28: Av. Javier Prado Este 560 Of. 2302 San Isidro - Lima | R28: Lima | S28: No
A29: 28 | D29: Comercial del Acero S.A. | E29: Perú | F29: ventas@comasa.com.pe | H29: Directorio SSO 2026 | I29: Prospecto | J29: Alta | K29: Identificar Gerente SSOMA/HSE en LinkedIn y proponer demo | L29: Directorio SSO 2026, pág. PDF 32. Sin contacto nominal; no inventar decisor. | M29: Sostenimiento de rocas y suelos | N29: Cliente potencial – operación de alto riesgo | O29: 6193000 | P29: www.comasa.com.pe | Q29: Av. Argentina 2051 - Cercado de Lima Lima | R29: Lima | S29: No
A30: 29 | D30: Concremax S.A. | E30: Perú | H30: Directorio SSO 2026 | I30: Prospecto | J30: Alta | K30: Identificar Gerente SSOMA/HSE en LinkedIn y proponer demo | L30: Directorio SSO 2026, pág. PDF 37. Sin contacto nominal; no inventar decisor. | M30: Empresas contratistas y conexas | N30: Cliente potencial – operación de alto riesgo | O30: 2172700 / 905454100 | P30: www.concremax.com.pe | Q30: Cooperativa Las Vertientes Mz. F Lt. 3A Villa El Salvador - Lima | R30: Lima | S30: No
A31: 30 | D31: Confipetrol Andina S.A. | E31: Perú | H31: Directorio SSO 2026 | I31: Prospecto | J31: Alta | K31: Identificar Gerente SSOMA/HSE en LinkedIn y proponer demo | L31: Directorio SSO 2026, pág. PDF 37. Sin contacto nominal; no inventar decisor. | M31: Empresas contratistas y conexas | N31: Cliente potencial – operación de alto riesgo | O31: 7106100 | P31: www.confipetrol.com | Q31: Av. Santo Toribio 173 Edf. Real 8 Of.1002 - San Isidro - Lima | R31: Lima | S31: No
A32: 31 | D32: CONGEMIN JH S.A.C. | E32: Perú | F32: contacto@congemin.com | H32: Directorio SSO 2026 | I32: Prospecto | J32: Alta | K32: Identificar Gerente SSOMA/HSE en LinkedIn y proponer demo | L32: Directorio SSO 2026, pág. PDF 20, 32, 36, 37. Sin contacto nominal; no inventar decisor. | M32: Perforación geológica; Sostenimiento de rocas y suelos; Voladura, explosivos y polvorines; Empresas contratistas y conexas | N32: Cliente potencial – operación de alto riesgo | O32: 3496849 | P32: www.congemin.com | Q32: Cl. Las Acacias Mz.I Lt.5A Urb. La Capitana, Huachipa - Lurigancho Lima | R32: Lima | S32: No
A33: 32 | D33: Consorcio Metalúrgico S.A. | E33: Perú | F33: ventas@comesa.com.pe | H33: Directorio SSO 2026 | I33: Prospecto | J33: Alta | K33: Identificar Gerente SSOMA/HSE en LinkedIn y proponer demo | L33: Directorio SSO 2026, pág. PDF 37. Sin contacto nominal; no inventar decisor. | M33: Empresas contratistas y conexas | N33: Cliente potencial – operación de alto riesgo | O33: 4648000 | P33: www.comesa.com.pe | Q33: Av. Maquinarias 3150 - Cercado de Lima - Lima | R33: Lima | S33: No
A34: 33 | D34: Contrans S.A.C. | E34: Perú | F34: ventas@contrans.com.pe | H34: Directorio SSO 2026 | I34: Prospecto | J34: Alta | K34: Identificar Gerente SSOMA/HSE en LinkedIn y proponer demo | L34: Directorio SSO 2026, pág. PDF 34. Sin contacto nominal; no inventar decisor. | M34: Transporte de combustibles y materiales peligrosos | N34: Cliente potencial – operación de alto riesgo | O34: 6123500 | P34: www.contrans.com.pe | Q34: Av. A Nº204 ex Fundo Oquendo Alt. km 8.5 de Av. Néstor Gambetta Callao | R34: Callao | S34: No
A35: 34 | D35: Contrata Minera Cristóbal S.A.C. | E35: Perú | F35: contacto.cristobal@cmcristobal.com | H35: Directorio SSO 2026 | I35: Prospecto | J35: Alta | K35: Identificar Gerente SSOMA/HSE en LinkedIn y proponer demo | L35: Directorio SSO 2026, pág. PDF 37. Sin contacto nominal; no inventar decisor. Otros emails: info.cristobal@cmcristobal.com. | M35: Empresas contratistas y conexas | N35: Cliente potencial – operación de alto riesgo | O35: 2608282 | P35: www.cmcristobal.com | Q35: Jr. Sevilla 283 - Santiago de Surco Lima | R35: Lima | S35: No
A36: 35 | D36: Contratos Mineros e Inversiones S.A.C. | E36: Perú | F36: info@contmin.pe | H36: Directorio SSO 2026 | I36: Prospecto | J36: Alta | K36: Identificar Gerente SSOMA/HSE en LinkedIn y proponer demo | L36: Directorio SSO 2026, pág. PDF 37. Sin contacto nominal; no inventar decisor. | M36: Empresas contratistas y conexas | N36: Cliente potencial – operación de alto riesgo | O36: 7356273 | P36: www.contmin.pe | Q36: Av. Coronel Andrés Reyes 437 Of. 601 San Isidro - Lima | R36: Lima | S36: No
A37: 36 | D37: Coopsol Minería y Petróleo S.A. | E37: Perú | F37: informes@coopsol.com | H37: Directorio SSO 2026 | I37: Prospecto | J37: Alta | K37: Identificar Gerente SSOMA/HSE en LinkedIn y proponer demo | L37: Directorio SSO 2026, pág. PDF 37. Sin contacto nominal; no inventar decisor. | M37: Empresas contratistas y conexas | N37: Cliente potencial – operación de alto riesgo | O37: 4223344 / 4409882 / 6178800 | P37: www.coopsolmineria.com | Q37: Cl. Federico Villareal 555 Urb. Chacarilla de Santa Cruz - San Isidro - Lima | R37: Lima | S37: No
A38: 37 | D38: Corimayo Servicios Mineros S.A.C. | E38: Perú | H38: Directorio SSO 2026 | I38: Prospecto | J38: Alta | K38: Identificar Gerente SSOMA/HSE en LinkedIn y proponer demo | L38: Directorio SSO 2026, pág. PDF 20, 36. Sin contacto nominal; no inventar decisor. | M38: Perforación geológica; Voladura, explosivos y polvorines | N38: Cliente potencial – operación de alto riesgo | O38: 2717153 | Q38: Cl. Albert Einstein 334 Urb. La Calera de la Merced - Surquillo - Lima | R38: Lima | S38: No
A39: 38 | D39: Corporación Aceros Arequipa S.A. | E39: Perú | H39: Directorio SSO 2026 | I39: Prospecto | J39: Alta | K39: Identificar Gerente SSOMA/HSE en LinkedIn y proponer demo | L39: Directorio SSO 2026, pág. PDF 32. Sin contacto nominal; no inventar decisor. | M39: Sostenimiento de rocas y suelos | N39: Cliente potencial – operación de alto riesgo | O39: 5171800 | P39: www.acerosarequipa.com | Q39: Carretera Panamericana Sur km 229 - Pisco - Ica | R39: Ica | S39: No
A40: 39 | D40: Corporación ADHARA | E40: Perú | F40: ventas@adhara.pe | H40: Directorio SSO 2026 | I40: Prospecto | J40: Alta | K40: Identificar Gerente SSOMA/HSE en LinkedIn y proponer demo | L40: Directorio SSO 2026, pág. PDF 33. Sin contacto nominal; no inventar decisor. | M40: Sostenimiento de rocas y suelos | N40: Cliente potencial – operación de alto riesgo | O40: (+51) 900704108 | P40: www.adhara.pe | Q40: Mza. N Lt. 25 Urb. Santo Domingo II Etapa, Carabayllo - Lima | R40: Lima | S40: No
...

Sheet Oportunidades
A1: ID oportunidad | B1: ID contacto | C1: Empresa | D1: Necesidad | E1: Solución propuesta | F1: Etapa | G1: Valor estimado | H1: Probabilidad | I1: Próxima acción | J1: Fecha

Sheet Resumen
A1: Evento/Fuente | B1: País | C1: Cantidad
A2: Directorio SSO 2026 | B2: Perú | C2: =COUNTIFS(Contactos!$H:$H,$A2,Contactos!$E:$E,$B2) -> 667
A3: Directorio SSO 2026 | B3: Colombia | C3: =COUNTIFS(Contactos!$H:$H,$A3,Contactos!$E:$E,$B3) -> 1
A4: Directorio SSO 2026 | B4: Brasil | C4: =COUNTIFS(Contactos!$H:$H,$A4,Contactos!$E:$E,$B4) -> 1
A5: Directorio SSO 2026 | B5: Argentina | C5: =COUNTIFS(Contactos!$H:$H,$A5,Contactos!$E:$E,$B5) -> 1
A6: Directorio SSO 2026 | B6: Canadá | C6: =COUNTIFS(Contactos!$H:$H,$A6,Contactos!$E:$E,$B6) -> 1
A7: Directorio SSO 2026 | B7: Estados Unidos | C7: =COUNTIFS(Contactos!$H:$H,$A7,Contactos!$E:$E,$B7) -> 1
A8: Directorio SSO 2026 | B8: Australia | C8: =COUNTIFS(Contactos!$H:$H,$A8,Contactos!$E:$E,$B8) -> 1
A9: Directorio SSO 2026 | B9: China | C9: =COUNTIFS(Contactos!$H:$H,$A9,Contactos!$E:$E,$B9) -> 1
A10: Total | C10: =SUM(C2:C9) -> 674
A12: Segmento SafetyMind | B12: Alta | C12: Media | D12: Baja | E12: Total
A13: Cliente potencial – operación de alto riesgo | B13: =COUNTIFS(Contactos!$N:$N,$A13,Contactos!$J:$J,B$12) -> 168 | C13: =COUNTIFS(Contactos!$N:$N,$A13,Contactos!$J:$J,C$12) -> 0 | D13: =COUNTIFS(Contactos!$N:$N,$A13,Contactos!$J:$J,D$12) -> 0 | E13: =SUM(B13:D13) -> 168
A14: Partner tecnológico / competidor | B14: =COUNTIFS(Contactos!$N:$N,$A14,Contactos!$J:$J,B$12) -> 16 | C14: =COUNTIFS(Contactos!$N:$N,$A14,Contactos!$J:$J,C$12) -> 0 | D14: =COUNTIFS(Contactos!$N:$N,$A14,Contactos!$J:$J,D$12) -> 0 | E14: =SUM(B14:D14) -> 16
A15: Canal / aliado – consultoría SST | B15: =COUNTIFS(Contactos!$N:$N,$A15,Contactos!$J:$J,B$12) -> 82 | C15: =COUNTIFS(Contactos!$N:$N,$A15,Contactos!$J:$J,C$12) -> 0 | D15: =COUNTIFS(Contactos!$N:$N,$A15,Contactos!$J:$J,D$12) -> 0 | E15: =SUM(B15:D15) -> 82
A16: Aliado complementario – seguridad | B16: =COUNTIFS(Contactos!$N:$N,$A16,Contactos!$J:$J,B$12) -> 8 | C16: =COUNTIFS(Contactos!$N:$N,$A16,Contactos!$J:$J,C$12) -> 105 | D16: =COUNTIFS(Contactos!$N:$N,$A16,Contactos!$J:$J,D$12) -> 0 | E16: =SUM(B16:D16) -> 113
A17: Canal / distribuidor EPP | B17: =COUNTIFS(Contactos!$N:$N,$A17,Contactos!$J:$J,B$12) -> 6 | C17: =COUNTIFS(Contactos!$N:$N,$A17,Contactos!$J:$J,C$12) -> 78 | D17: =COUNTIFS(Contactos!$N:$N,$A17,Contactos!$J:$J,D$12) -> 0 | E17: =SUM(B17:D17) -> 84
A18: Aliado complementario – salud | B18: =COUNTIFS(Contactos!$N:$N,$A18,Contactos!$J:$J,B$12) -> 1 | C18: =COUNTIFS(Contactos!$N:$N,$A18,Contactos!$J:$J,C$12) -> 47 | D18: =COUNTIFS(Contactos!$N:$N,$A18,Contactos!$J:$J,D$12) -> 0 | E18: =SUM(B18:D18) -> 48
A19: Proveedor industrial (baja afinidad) | B19: =COUNTIFS(Contactos!$N:$N,$A19,Contactos!$J:$J,B$12) -> 0 | C19: =COUNTIFS(Contactos!$N:$N,$A19,Contactos!$J:$J,C$12) -> 0 | D19: =COUNTIFS(Contactos!$N:$N,$A19,Contactos!$J:$J,D$12) -> 163 | E19: =SUM(B19:D19) -> 163
A20: Total | B20: =SUM(B13:B19) -> 281 | C20: =SUM(C13:C19) -> 230 | D20: =SUM(D13:D19) -> 163 | E20: =SUM(E13:E19) -> 674
A22: Estado (pipeline) | B22: Cantidad
A23: Prospecto | B23: =COUNTIF(Contactos!$I:$I,A23) -> 674
A24: Contactado | B24: =COUNTIF(Contactos!$I:$I,A24) -> 0
A25: Reunión | B25: =COUNTIF(Contactos!$I:$I,A25) -> 0
A26: Propuesta | B26: =COUNTIF(Contactos!$I:$I,A26) -> 0
A27: Cliente | B27: =COUNTIF(Contactos!$I:$I,A27) -> 0
A28: No interesado | B28: =COUNTIF(Contactos!$I:$I,A28) -> 0
A30: Indicadores de calidad de datos | B30: Cantidad
A31: Con email | B31: =COUNTIF(Contactos!$F$2:$F$2000,"?*") -> 623
A32: Con teléfono | B32: =COUNTA(Contactos!$O$2:$O$2000) -> 654
A33: Con contacto nominal | B33: =COUNTIF(Contactos!$B$2:$B$2000,"?*") -> 20
A34: Anunciantes del directorio | B34: =COUNTIF(Contactos!$S:$S,"Sí") -> 21
A35: Con LinkedIn validado | B35: =COUNTIF(Contactos!$G$2:$G$2000,"?*") -> 0

Sheet Eventos
A1: Evento | B1: País | C1: Valor para SafetyMind
A2: Directorio SSO 2026 – Cero Accidentes (22.ª ed.) | B2: Perú | C2: Mapa de ~670 proveedores SST en Perú: contratistas mineros (clientes potenciales), consultoras SST (canal), TI/telecom (partners/competencia), distribuidores EPP (canal hacia minería) y 21 anunciantes con inversión activa en SST.
