Workbook

Sheet Contactos
A1: ID | B1: Nombre | C1: Cargo | D1: Empresa | E1: País | F1: Email | G1: LinkedIn | H1: Origen | I1: Estado | J1: Prioridad | K1: Próxima acción | L1: Notas | M1: Segmento SafetyMind | N1: Stand(s) | O1: N° stands | P1: Rubro AquaSur | Q1: Descripción | R1: Teléfono(s) | S1: Cruce otros CRM
A2: 1 | D2: AQUACHILE | E2: Chile | H2: AquaSur 2026 | I2: Prospecto | J2: Alta | K2: Mapear Gerente de Personas/SSOMA y centros de cultivo; proponer piloto (buceo, cosecha, wellboat) | L2: AquaSur 2026. Sin contacto publicado. | M2: Cliente final – productor acuícola | N2: N-32 | O2: 1 | P2: Producción acuícola, pesquera y alimentos › Productores / procesadores acuícolas | Q2: AquaChile empresa nacida en el sur de Chile Líder en la producción de salmón a nivel nacional y mundial. Conformada por un equipo de personas apasionadas y comprometidas, convencidas de que la innovación es parte esencial del ADN. En AquaChile existe un profundo orgullo por su origen, por su gente y por el rol que cumple llevando salmón chileno de alta calidad a los mercados internacionales | S2: No
A3: 2 | D3: BLUMAR | E3: Chile | H3: AquaSur 2026 | I3: Prospecto | J3: Alta | K3: Mapear Gerente de Personas/SSOMA y centros de cultivo; proponer piloto (buceo, cosecha, wellboat) | L3: AquaSur 2026. Sin stand asignado en el listado. Sin contacto publicado. | M3: Cliente final – productor acuícola | N3: Sin stand | O3: 0 | P3: Producción acuícola, pesquera y alimentos › Productores / procesadores acuícolas | Q3: Blumar es una compañía chilena con más de 75 años de trayectoria en pesca y acuicultura. Integra toda su cadena productiva, desde la captura y elaboración de harina y aceite de pescado hasta la salmonicultura en el sur austral. Con presencia en Chile y mercados internacionales, impulsa una operación sostenible, innovadora y comprometida con el cuidado del océano y el trabajo con las comunidades. | S3: No
A4: 3 | D4: ALO RENTAL | E4: Chile | H4: AquaSur 2026 | I4: Prospecto | J4: Alta | K4: Identificar Gerente HSE/Prevención en LinkedIn y proponer demo (faenas marítimas de alto riesgo) | L4: AquaSur 2026. También expone en Exponor 2026 (ID 16). Sin contacto publicado. | M4: Cliente potencial – contratista / operación de alto riesgo | N4: AD-04 | O4: 1 | P4: Equipos e insumos industriales › Ingeniería / mantenimiento | Q4: En ALO Group, hemos liderado el sector de soluciones para trabajos en altura desde 2004, ofreciendo servicios integrales que garantizan seguridad y eficiencia en cada proyecto. Nos dedicamos a elevar personas y proyectos, brindando certeza y confianza a través de soluciones integrales en plataformas para trabajo en altura y manipuladores telescópicos. | S4: Exponor (ID 16)
A5: 4 | D5: ASENAV | E5: Chile | H5: AquaSur 2026 | I5: Prospecto | J5: Alta | K5: Identificar Gerente HSE/Prevención en LinkedIn y proponer demo (faenas marítimas de alto riesgo) | L5: AquaSur 2026. Sin contacto publicado. | M5: Cliente potencial – contratista / operación de alto riesgo | N5: A-36 | O5: 1 | P5: Infraestructura marina y equipamiento acuícola › Servicios / equipos marítimos | Q5: ASENAV es un astillero chileno con más de 50 años de experiencia en el diseño y construcción de embarcaciones especializadas. Destaca por su ingeniería propia, soluciones a medida y altos estándares de calidad, innovación y sostenibilidad, atendiendo clientes de la industria acuícola y marítima a nivel internacional. | S5: No
A6: 5 | D6: ASMAR SHIPYARDS | E6: Chile | H6: AquaSur 2026 | I6: Prospecto | J6: Alta | K6: Identificar Gerente HSE/Prevención en LinkedIn y proponer demo (faenas marítimas de alto riesgo) | L6: AquaSur 2026. Sin contacto publicado. | M6: Cliente potencial – contratista / operación de alto riesgo | N6: J-49 | O6: 1 | P6: Infraestructura marina y equipamiento acuícola › Jaulas / flotación / estructuras | Q6: Astilleros y Maestranzas de la Armada – ASMAR, es un astillero estatal chileno, cuya actividad principal es satisfacer las necesidades de mantenimiento y construcción de buques para la Armada de Chile. Además, ASMAR repara, carena, transforma y moderniza buques pesqueros y mercantes, junto a plataformas de ensilajes, pontones y otros artefactos navales. | S6: No
A7: 6 | D7: BELATOR | E7: Chile | H7: AquaSur 2026 | I7: Prospecto | J7: Alta | K7: Identificar Gerente HSE/Prevención en LinkedIn y proponer demo (faenas marítimas de alto riesgo) | L7: AquaSur 2026. Sin contacto publicado. | M7: Cliente potencial – contratista / operación de alto riesgo | N7: M-36 | O7: 1 | P7: Servicios empresariales y consultoría › Servicios operacionales / abastecimiento | Q7: Aseguramos la continuidad operacional del negocio gracias al alto nivel de nuestros operadores, y a la optimización de los procesos a través de tecnología de vanguardia que permite prevenir posibles riesgos. Siendo lo primordial la seguridad anticipativa de la mano del modelo de seguridad basada en la supervivencia urbana. | S7: No
A8: 7 | D8: COMERCIAL INDUSTRIAL TERRAMAR SPA - WALBUSCH S.A | E8: Chile | H8: AquaSur 2026 | I8: Prospecto | J8: Alta | K8: Identificar Gerente HSE/Prevención en LinkedIn y proponer demo (faenas marítimas de alto riesgo) | L8: AquaSur 2026. Sin contacto publicado. | M8: Cliente potencial – contratista / operación de alto riesgo | N8: B-18 | O8: 1 | P8: Infraestructura marina y equipamiento acuícola › Redes / cabos / fondeo | Q8: Walbusch S.A. Desde 1996, hemos sido pioneros en servicios marítimos para la industria salmonicultura, adaptándonos a las crecientes demandas del sector. Con una amplia experiencia en el montaje de sistemas de fondeo. | S8: No
A9: 8 | D9: DIVING AUSTRAL | E9: Chile | H9: AquaSur 2026 | I9: Prospecto | J9: Alta | K9: Identificar Gerente HSE/Prevención en LinkedIn y proponer demo (faenas marítimas de alto riesgo) | L9: AquaSur 2026. Sin contacto publicado. | M9: Cliente potencial – contratista / operación de alto riesgo | N9: S-16 | O9: 1 | P9: Instituciones, medios y certificación › Certificación / bienestar animal | Q9: Somos una empresa especializada en ingeniería y construcción submarina, que entrega soluciones integrales en los ámbitos industrial, portuario y energético. Operamos bajo altos estándares de seguridad y calidad, con buzos certificados y respaldo técnico. Contamos con certificación Oil Spill Response (OSR), que acredita nuestra capacidad operativa ante emergencias ambientales en el medio marino. | S9: No
A10: 9 | D10: DYC INGENIERIA | E10: Chile | H10: AquaSur 2026 | I10: Prospecto | J10: Alta | K10: Identificar Gerente HSE/Prevención en LinkedIn y proponer demo (faenas marítimas de alto riesgo) | L10: AquaSur 2026. Sin contacto publicado. | M10: Cliente potencial – contratista / operación de alto riesgo | N10: G-24 | O10: 1 | P10: Transporte y logística › Transporte acuícola / wellboats | Q10: Trabajos de Ingenieria en Electronica y Automatizacion Industrial en Piscicultura, plantas de proceso de salmones y Wellboat. | S10: No
A11: 10 | D11: FABRIMAQ | E11: Chile | H11: AquaSur 2026 | I11: Prospecto | J11: Alta | K11: Identificar Gerente HSE/Prevención en LinkedIn y proponer demo (faenas marítimas de alto riesgo) | L11: AquaSur 2026. Sin contacto publicado. | M11: Cliente potencial – contratista / operación de alto riesgo | N11: C-02 | O11: 1 | P11: Transporte y logística › Transporte acuícola / wellboats | Q11: FABRIMAQ es una empresa de ingeniería fabricación y servicios de maestranza orientada a la industria acuícola y alimenticia. Desarrolla proyectos llave en mano para el manejo de peces, sistemas de bombeo, transporte y procesos productivos, aplicados a Pisciculturas, Wellboats y Plantas de Proceso, integrando ingeniería, modelamiento 3D, fabricación en acero inoxidable y soluciones en HDPE. | S11: No
A12: 11 | D12: FYT TRANSPORTES | E12: Chile | H12: AquaSur 2026 | I12: Prospecto | J12: Alta | K12: Identificar Gerente HSE/Prevención en LinkedIn y proponer demo (faenas marítimas de alto riesgo) | L12: AquaSur 2026. Sin contacto publicado. | M12: Cliente potencial – contratista / operación de alto riesgo | N12: ST-96 | O12: 1 | P12: Transporte y logística › Transporte especializado / grúas | Q12: Nos dedicamos al transporte especial, tenemos distintas grúas, y también tenemos movimiento de tierra, contamos con moto niveladora y demás, | S12: No
A13: 12 | D13: Kafra Robotica spa | E13: Chile | H13: AquaSur 2026 | I13: Prospecto | J13: Alta | K13: Identificar Gerente HSE/Prevención en LinkedIn y proponer demo (faenas marítimas de alto riesgo) | L13: AquaSur 2026. Sin contacto publicado. | M13: Cliente potencial – contratista / operación de alto riesgo | N13: ST-102 | O13: 1 | P13: Instituciones, medios y certificación › Certificación / bienestar animal | Q13: Somos una empresa dedicada a la robotica submarina, instalacion de sistema de oxigenación , certificacion de cebtro de cultivo los servicios que contamos son los siguientes: *Inspección y costura de red lobera y pecera. *inspeccion de lineas de fondeos y certificación *extracción de mortalidad y observación de alimentación. *instalacion y desmontaje de oxigenación. | S13: No
... A84: 83 | D84: Acuiestudios SpA | E84: Chile | H84: AquaSur 2026 | I84: Prospecto | J84: Alta | K84: Explorar alianza comercial / reventa a sus clientes salmoneros | L84: AquaSur 2026. Sin contacto publicado. | M84: Canal / aliado – consultoría SST | N84: ST-128 | O84: 1 | P84: Producción acuícola, pesquera y alimentos › Productores / procesadores acuícolas | Q84: Empresa especializada en asesorías en el ámbito sanitario, productivo, ambiental, comercio exterior y jurídico de la pesca y acuicultura, altamente comprometida con el desarrollo de esta actividad estratégica del país. Para esto contamos con un equipo de trabajo multidisciplinario de reconocida trayectoria a nivel nacional e internacional. | S84: No
A85: 84 | D85: CINDER CAPACITACION | E85: Chile | H85: AquaSur 2026 | I85: Prospecto | J85: Alta | K85: Explorar alianza comercial / reventa a sus clientes salmoneros | L85: AquaSur 2026. Sin contacto publicado. | M85: Canal / aliado – consultoría SST | N85: ST-126 | O85: 1 | P85: Servicios empresariales y consultoría › Consultoría / capacitación | S85: No
A86: 85 | D86: Enroka | E86: Chile | H86: AquaSur 2026 | I86: Prospecto | J86: Alta | K86: Explorar alianza comercial / reventa a sus clientes salmoneros | L86: AquaSur 2026. Sin contacto publicado. | M86: Canal / aliado – consultoría SST | N86: ST-124 | O86: 1 | P86: Servicios empresariales y consultoría › Reclutamiento / staffing | Q86: Ayudamos a empresas medianas y grandes a gestionar el envejecimiento laboral y la salida planificada de talentos +50 en cargos críticos, al ofrecer programas de Age Management que trabajan con la organización y con las personas, asegurando continuidad operacional, bienestar organizacional y transferencia estratégica de conocimiento. | S86: No
A87: 86 | D87: FERNANDEZ Y ALEUY CAPACITACION | E87: Chile | H87: AquaSur 2026 | I87: Prospecto | J87: Alta | K87: Explorar alianza comercial / reventa a sus clientes salmoneros | L87: AquaSur 2026. Sin contacto publicado. | M87: Canal / aliado – consultoría SST | N87: N-38 | O87: 1 | P87: Servicios empresariales y consultoría › Consultoría / capacitación | Q87: Grupo CONFIAL es una consultora estratégica y OTEC de alto nivel, especializada en capacitación, liderazgo y gestión de personas para la industria productiva. Contamos con equipos senior y más de 20 años de experiencia, entregando soluciones aplicadas, medibles y alineadas a resultados del negocio. | S87: No
A88: 87 | D88: INCAR | E88: Chile | H88: AquaSur 2026 | I88: Prospecto | J88: Alta | K88: Explorar alianza comercial / reventa a sus clientes salmoneros | L88: AquaSur 2026. Sin contacto publicado. | M88: Canal / aliado – consultoría SST | N88: ST-78 | O88: 1 | P88: Instituciones, medios y certificación › Certificación / bienestar animal | Q88: El Centro de Investigación Aplicada INCAR² desarrolla soluciones científicas y tecnológicas para los principales desafíos de la acuicultura chilena, creando vacunas, herramientas para reducir el uso de antimicrobianos, modelos ambientales y estrategias de resiliencia climática, con foco en soluciones sostenibles, competitividad, bienestar animal y transferencia efectiva al sector productivo. | S88: No
A89: 88 | D89: INTERTEK | E89: Chile | H89: AquaSur 2026 | I89: Prospecto | J89: Alta | K89: Explorar alianza comercial / reventa a sus clientes salmoneros | L89: AquaSur 2026. Sin contacto publicado. | M89: Canal / aliado – consultoría SST | N89: D-11 | O89: 1 | P89: Instituciones, medios y certificación › Certificación / bienestar animal | Q89: Intertek es un proveedor líder en Aseguramiento Total de la Calidad para las industrias al rededor del mundo. A través de nuestra red de más de 44,000 colaboradores, más de 1,000 laboratorios y oficinas en más de 100 países, brindamos soluciones innovadoras y hechas a la medida en Aseguramiento, Pruebas, Inspección y Certificación para las operaciones y cadenas de suministro de nuestros clientes. | S89: No
A90: 89 | D90: LEYTON INSURANCE | E90: Chile | H90: AquaSur 2026 | I90: Prospecto | J90: Alta | K90: Explorar alianza comercial / reventa a sus clientes salmoneros | L90: AquaSur 2026. Sin contacto publicado. | M90: Canal / aliado – consultoría SST | N90: P-36 | O90: 1 | P90: Finanzas, seguros y leasing › Seguros | Q90: LEYTON & ASOCIADOS Corredores de Seguros es especialista en Seguros para riesgos productivos e industriales de alta complejidad, tales como Plantas y Equipos, Seguro de Crédito, Responsabilidad Civil Corporativa, Naves Marítimas, Aéreas y otros Riesgos Facultativos, para lo que contamos con la colaboración Aseguradores en el «Mercado» nacional e internacional. | S90: No
A91: 90 | D91: OTIC CCC | E91: Chile | H91: AquaSur 2026 | I91: Prospecto | J91: Alta | K91: Explorar alianza comercial / reventa a sus clientes salmoneros | L91: AquaSur 2026. Sin contacto publicado. | M91: Canal / aliado – consultoría SST | N91: M-15 | O91: 1 | P91: Servicios empresariales y consultoría › Consultoría / capacitación | Q91: El OTIC CChC es el aliado líder de la industria salmonera en el sur de Chile. Acompañamos a las empresas del rubro en una gestión experta de la franquicia tributaria, conectándolas con capacitación pertinente, eficiente y de alto impacto para fortalecer la productividad, seguridad y sostenibilidad de sus equipos. | S91: No
A92: 91 | D92: PROFISUR | E92: Chile | H92: AquaSur 2026 | I92: Prospecto | J92: Alta | K92: Explorar alianza comercial / reventa a sus clientes salmoneros | L92: AquaSur 2026. Sin contacto publicado. | M92: Canal / aliado – consultoría SST | N92: B-10 | O92: 1 | P92: Servicios empresariales y consultoría › Reclutamiento / staffing | Q92: Profisur entrega soluciones integrales a la industria acuícola mediante la selección, gestión y dirección de personal calificado para plantas de proceso. Coordinamos su traslado, equipamiento y condiciones de trabajo, asegurando operaciones seguras, eficientes y alineadas a los objetivos productivos, con foco en la sustentabilidad y el cuidado de las personas. | S92: No
A93: 92 | D93: SAMS ENTERPRISE | E93: Reino Unido | H93: AquaSur 2026 | I93: Prospecto | J93: Alta | K93: Explorar alianza comercial / reventa a sus clientes salmoneros | L93: AquaSur 2026. Sin contacto publicado. | M93: Canal / aliado – consultoría SST | N93: E-24 | O93: 1 | P93: Producción acuícola, pesquera y alimentos › Productores / procesadores acuícolas | Q93: SAMS Enterprise es el brazo comercial de la Scottish Association for Marine Science, dedicado a transformar la investigación marina de vanguardia en soluciones reales que beneficien a las personas y al planeta. Nuestro trabajo en acuicultura, y especialmente en el cultivo de salmón, respalda prácticas sostenibles, rentables y resilientes, al mismo tiempo que positiva para las comunidades locales. | S93: No
A94: 93 | D94: SGS CHILE | E94: Chile | F94: pe.info@sgs.com | H94: AquaSur 2026 | I94: Prospecto | J94: Alta | K94: Explorar alianza comercial / reventa a sus clientes salmoneros | L94: AquaSur 2026. También en CRM Directorio SSO 2026 (ID 254); contacto heredado = filial Perú. | M94: Canal / aliado – consultoría SST | N94: J-12 | O94: 1 | P94: Instituciones, medios y certificación › Certificación / bienestar animal | Q94: SGS es líder mundial en inspección, ensayos y certificación. Apoyamos a la industria acuícola con servicios para inocuidad, calidad, sostenibilidad y cumplimiento normativo: análisis ambientales y de agua, control sanitario, certificaciones y soluciones para una producción responsable, sostenible y eficiente. | R94: 5171900 / 999979079 | S94: Directorio SSO (ID 254)
A95: 94 | D95: SINGULARES SPA | E95: Chile | H95: AquaSur 2026 | I95: Prospecto | J95: Alta | K95: Explorar alianza comercial / reventa a sus clientes salmoneros | L95: AquaSur 2026. Sin contacto publicado. | M95: Canal / aliado – consultoría SST | N95: J-19 | O95: 1 | P95: Servicios empresariales y consultoría › Consultoría / capacitación | Q95: Singulares SpA es una consultora estratégica certificada como Empresa B, con más de 15 años de experiencia acompañando a empresas a crecer con foco en resultados, personas y sostenibilidad. Diseñamos e implementamos soluciones en estrategia, gestión, liderazgo y talento, generando impacto real en la competitividad y el desarrollo de organizaciones de la industria acuícola y productiva. | S95: No
A96: 95 | D96: SMART TRAINING | E96: Chile | H96: AquaSur 2026 | I96: Prospecto | J96: Alta | K96: Explorar alianza comercial / reventa a sus clientes salmoneros | L96: AquaSur 2026. Sin contacto publicado. | M96: Canal / aliado – consultoría SST | N96: N-31 | O96: 1 | P96: Servicios empresariales y consultoría › Consultoría / capacitación | Q96: Smartraining es una OTEC especializada en academias corporativas con tecnología educativa avanzada y aprendizaje experiencial. Mediante franquicia tributaria SENCE, capacita a empresas del sector salmonero con programas 100% financiados, enfocados en seguridad, productividad, cumplimiento normativo y sostenibilidad, asegurando aprendizaje efectivo y aplicable en el puesto de trabajo. | S96: No
A97: 96 | D97: STIM CHILE | E97: Chile | H97: AquaSur 2026 | I97: Prospecto | J97: Alta | K97: Explorar alianza comercial / reventa a sus clientes salmoneros | L97: AquaSur 2026. Sin contacto publicado. | M97: Canal / aliado – consultoría SST | N97: E-32 | O97: 1 | P97: Servicios empresariales y consultoría › Consultoría / capacitación | Q97: STIM Chile es una filial de una empresa global especializada en salud y bienestar de peces para la acuicultura, con foco en la salmonicultura. Desde Puerto Montt, impulsa soluciones y tecnologías innovadoras que mejoran el rendimiento, bienestar y sostenibilidad de la producción acuícola, respaldadas por investigación y desarrollo científico. | S97: No
A98: 97 | D98: UNIVERSIDAD DE CHILE | E98: Chile | H98: AquaSur 2026 | I98: Prospecto | J98: Alta | K98: Explorar alianza comercial / reventa a sus clientes salmoneros | L98: AquaSur 2026. Sin contacto publicado. | M98: Canal / aliado – consultoría SST | N98: J-41 | O98: 1 | P98: Servicios empresariales y consultoría › Consultoría / capacitación | Q98: El Proyecto PHAGENET, corresponde a una iniciativa Anillo Tecnológico de ANID, código ACT240045. Este núcleo integra especialistas de distintas áreas y universidades del país, comprometidos con impulsar la investigación aplicada, la innovación biotecnológica y la transferencia de conocimiento al entorno productivo. | S98: No
A99: 98 | D99: UNIVERSIDAD DE CONCEPCIÓN | E99: Chile | H99: AquaSur 2026 | I99: Prospecto | J99: Alta | K99: Explorar alianza comercial / reventa a sus clientes salmoneros | L99: AquaSur 2026. Sin contacto publicado. | M99: Canal / aliado – consultoría SST | N99: N-12 | O99: 1 | P99: Energía, climatización e iluminación › Energía / combustibles / electrificación | Q99: El Centro para la Industria 4.0 (C4i) conecta investigación aplicada con desafíos de la industria nacional, apoyando a empresas mediante extensionismo, implementación tecnológica e I+D. En acuicultura desarrolla IA y visión computacional, IoT y monitoreo en tiempo real, diseño y manufactura avanzada, y AR/XR para operación y mantenimiento. Además, CAD/CAM y energía limpia para operaciones. | S99: No
A100: 99 | D100: WSP GLOBAL | E100: Chile | H100: AquaSur 2026 | I100: Prospecto | J100: Alta | K100: Explorar alianza comercial / reventa a sus clientes salmoneros | L100: AquaSur 2026. Sin contacto publicado. | M100: Canal / aliado – consultoría SST | N100: E-46 | O100: 1 | P100: Servicios empresariales y consultoría › Consultoría / capacitación | Q100: WSP es una de las principales empresas de servicios profesionales del mundo, que cuenta con un equipo de más de 77,000 destacados ingenieros, asesores y científicos. Su propósito es dar forma a las comunidades y avanzar a la humanidad mediante el enfoque Future Ready®, impulsado por el compromiso de generar un impacto positivo y apoyar a sus clientes a innovar y enfrentar desafíos reales. | S100: No
A101: 100 | D101: MANPOWER GROUP | E101: Chile | H101: AquaSur 2026 | I101: Prospecto | J101: Alta | K101: Explorar alianza comercial / reventa a sus clientes salmoneros | L101: AquaSur 2026. Sin stand asignado en el listado. Sin contacto publicado. | M101: Canal / aliado – consultoría SST | N101: Sin stand | O101: 0 | P101: Servicios empresariales y consultoría › Reclutamiento / staffing | Q101: ManpowerGroup es líder global en soluciones de talento humano, con más de 70 años de experiencia y presencia en más de 70 países. En Chile apoyamos a empresas en la atracción, gestión y desarrollo del talento, combinando enfoque consultivo B2B, conocimiento del mercado laboral y especialización en talento tecnológico para impulsar su crecimiento y adaptación. | S101: No
A102: 101 | D102: ANCORA | E102: Chile | H102: AquaSur 2026 | I102: Prospecto | J102: Media | K102: Explorar integración con equipos (visión + telemetría en pontones, wellboats, jaulas) | L102: AquaSur 2026. Varios stands (mayor inversión). Sin contacto publicado. | M102: Partner OEM – equipos acuícolas y marinos | N102: D-45, D-44 | O102: 2 | P102: Automatización, robótica y monitoreo › ROV / robótica | Infraestructura marina y equipamiento acuícola › Servicios / equipos marítimos | Q102: ANCORA CHILE, en una nueva etapa de crecimiento y consolidación en la industria marítima continuamos liderando con innovación y soluciones de alta calidad, brindando un servicio integral que responde a las exigencias del sector y a la evolución de las necesidades de nuestros clientes. En la actualidad representamos alrededor de 16 marcas exclusivas, proveedores integrales de equipamiento naval. | S102: No
A103: 102 | D103: PATAGONIA IMPORTACIONES | E103: Chile | H103: AquaSur 2026 | I103: Prospecto | J103: Media | K103: Explorar integración con equipos (visión + telemetría en pontones, wellboats, jaulas) | L103: AquaSur 2026. Varios stands (mayor inversión). Sin contacto publicado. | M103: Partner OEM – equipos acuícolas y marinos | N103: B-50, AD-06 | O103: 2 | P103: Infraestructura marina y equipamiento acuícola › Servicios / equipos marítimos | Q103: Venta de Motores Marinos, Gruas Marinas, Grupos Generadores, Cajas Marinas, Accesorios Marinos, Electronica Naval y Repuestos en General | S103: No
A104: 103 | D104: ABB S.A. | E104: Chile | F104: contact.center@pe.abb.com | H104: AquaSur 2026 | I104: Prospecto | J104: Media | K104: Explorar integración con equipos (visión + telemetría en pontones, wellboats, jaulas) | L104: AquaSur 2026. También expone en Exponor 2026 (ID 361). También en CRM Directorio SSO 2026 (ID 512); contacto heredado = filial Perú. | M104: Partner OEM – equipos acuícolas y marinos | N104: G-48 | O104: 1 | P104: Automatización, robótica y monitoreo › Automatización / control | Q104: En ABB hacemos un futuro más eficiente y sostenible en el uso de los recursos. Conectando su dominio de la ingeniería y de la digitalización, ABB contribuye a que las industrias funcionen a alto rendimiento, al tiempo que mejoran su eficiencia, productividad y sostenibilidad, para superar sus resultados. En ABB, lo llamamos “Engineered to Outrun”. | R104: 4155100 | S104: Exponor (ID 361); Directorio SSO (ID 512)
A105: 104 | D105: ADRIA WINCH | E105: Chile | H105: AquaSur 2026 | I105: Prospecto | J105: Media | K105: Explorar integración con equipos (visión + telemetría en pontones, wellboats, jaulas) | L105: AquaSur 2026. Sin contacto publicado. | M105: Partner OEM – equipos acuícolas y marinos | N105: P-20 | O105: 1 | P105: Infraestructura marina y equipamiento acuícola › Servicios / equipos marítimos | Q105: Adria Winch d.o.o. is a Croatian manufacturer of deck machinery and winches for maritime, offshore, naval and energy sectors. Founded in 1993 and based in Split, the company delivers robust, custom-engineered solutions worldwide, trusted for reliability in demanding operating environments. | S105: No
A106: 105 | D106: BADINOTTI | E106: Chile | H106: AquaSur 2026 | I106: Prospecto | J106: Media | K106: Explorar integración con equipos (visión + telemetría en pontones, wellboats, jaulas) | L106: AquaSur 2026. Sin contacto publicado. | M106: Partner OEM – equipos acuícolas y marinos | N106: A-28 | O106: 1 | P106: Infraestructura marina y equipamiento acuícola › Jaulas / flotación / estructuras | Q106: Soluciones fiables para sistemas de contención en el agua y servicios relacionados | S106: No
A107: 106 | D107: BOSSAQUA | E107: Nueva Zelanda | H107: AquaSur 2026 | I107: Prospecto | J107: Media | K107: Explorar integración con equipos (visión + telemetría en pontones, wellboats, jaulas) | L107: AquaSur 2026. Sin contacto publicado. | M107: Partner OEM – equipos acuícolas y marinos | N107: J-14 | O107: 1 | P107: Infraestructura marina y equipamiento acuícola › Jaulas / flotación / estructuras | Q107: We design and manufacture AutoBoss™, specialised net washing equipment for the global Aquaculture industry. We focus on designing and producing world-class net washing equipment, with a strong emphasis on research and design. Our V4 model has generated exponential growth and significant offshore market penetration and is the ONLY self-contained autonomous net-cleaning solution in the market. | S107: No
A108: 107 | D108: BZ NAVAL ENGINEERING | E108: Chile | H108: AquaSur 2026 | I108: Prospecto | J108: Media | K108: Explorar integración con equipos (visión + telemetría en pontones, wellboats, jaulas) | L108: AquaSur 2026. Sin contacto publicado. | M108: Partner OEM – equipos acuícolas y marinos | N108: G-44 | O108: 1 | P108: Infraestructura marina y equipamiento acuícola › Servicios / equipos marítimos | Q108: BZ Naval ofrece soluciones para el ámbito Marítimo, Portuario y Astilleros. proporcionando servicios de Ingeniería, Concesiones Marítimas y representaciones de reconocidas compañías internacionales. Estará junto a HamiltonJet, pionera en propulsión por chorro de agua (waterjet), que también presentará sus sistemas híbridos-eléctricos para clientes que buscan una propulsión eficiente y ecológica. | S108: No
A109: 108 | D109: CFLOW FISH | E109: Chile | H109: AquaSur 2026 | I109: Prospecto | J109: Media | K109: Explorar integración con equipos (visión + telemetría en pontones, wellboats, jaulas) | L109: AquaSur 2026. Sin contacto publicado. | M109: Partner OEM – equipos acuícolas y marinos | N109: G-30 | O109: 1 | P109: Infraestructura marina y equipamiento acuícola › Jaulas / flotación / estructuras | Q109: Compañía noruega con más de 20 años de trayectoria global. Nos especializamos en diseñar soluciones estratégicas e innovadoras que transforman y optimizan los procesos productivos de nuestros clientes. | S109: No
A110: 109 | D110: DERCOMAQ S.A. | E110: Chile | H110: AquaSur 2026 | I110: Prospecto | J110: Media | K110: Explorar integración con equipos (visión + telemetría en pontones, wellboats, jaulas) | L110: AquaSur 2026. Sin contacto publicado. | M110: Partner OEM – equipos acuícolas y marinos | N110: J-36 | O110: 1 | P110: Equipos e insumos industriales › Construcción / estructuras | Q110: Dercomaq es una empresa líder en la comercialización de maquinaria, camiones, repuestos y soluciones integrales para los sectores agrícola, construcción, minería y transporte. con una amplia red de sucursales en Chile, Representa marcas de prestigio internacional y ofrece servicios de postventa, arriendo de equipos y soporte técnico especializado. | S110: No
...

Sheet Oportunidades
A1: ID oportunidad | B1: ID contacto | C1: Empresa | D1: Necesidad | E1: Solución propuesta | F1: Etapa | G1: Valor estimado | H1: Probabilidad | I1: Próxima acción | J1: Fecha

Sheet Resumen
A1: Evento/Fuente | B1: País | C1: Cantidad
A2: AquaSur 2026 | B2: Chile | C2: =COUNTIFS(Contactos!$H:$H,$A2,Contactos!$E:$E,$B2) -> 422
A3: AquaSur 2026 | B3: Dinamarca | C3: =COUNTIFS(Contactos!$H:$H,$A3,Contactos!$E:$E,$B3) -> 19
A4: AquaSur 2026 | B4: China | C4: =COUNTIFS(Contactos!$H:$H,$A4,Contactos!$E:$E,$B4) -> 18
A5: AquaSur 2026 | B5: Noruega | C5: =COUNTIFS(Contactos!$H:$H,$A5,Contactos!$E:$E,$B5) -> 14
A6: AquaSur 2026 | B6: Estados Unidos | C6: =COUNTIFS(Contactos!$H:$H,$A6,Contactos!$E:$E,$B6) -> 11
A7: AquaSur 2026 | B7: España | C7: =COUNTIFS(Contactos!$H:$H,$A7,Contactos!$E:$E,$B7) -> 5
A8: AquaSur 2026 | B8: Canadá | C8: =COUNTIFS(Contactos!$H:$H,$A8,Contactos!$E:$E,$B8) -> 4
A9: AquaSur 2026 | B9: Brasil | C9: =COUNTIFS(Contactos!$H:$H,$A9,Contactos!$E:$E,$B9) -> 2
A10: AquaSur 2026 | B10: Corea del Sur | C10: =COUNTIFS(Contactos!$H:$H,$A10,Contactos!$E:$E,$B10) -> 2
A11: AquaSur 2026 | B11: India | C11: =COUNTIFS(Contactos!$H:$H,$A11,Contactos!$E:$E,$B11) -> 2
A12: AquaSur 2026 | B12: Italia | C12: =COUNTIFS(Contactos!$H:$H,$A12,Contactos!$E:$E,$B12) -> 2
A13: AquaSur 2026 | B13: Suecia | C13: =COUNTIFS(Contactos!$H:$H,$A13,Contactos!$E:$E,$B13) -> 2
... A26: AquaSur 2026 | B26: Suiza | C26: =COUNTIFS(Contactos!$H:$H,$A26,Contactos!$E:$E,$B26) -> 1
A27: Total | C27: =SUM(C2:C26) -> 517
A29: Segmento SafetyMind | B29: Alta | C29: Media | D29: Baja | E29: Total
A30: Cliente final – productor acuícola | B30: =COUNTIFS(Contactos!$M:$M,$A30,Contactos!$J:$J,B$29) -> 2 | C30: =COUNTIFS(Contactos!$M:$M,$A30,Contactos!$J:$J,C$29) -> 0 | D30: =COUNTIFS(Contactos!$M:$M,$A30,Contactos!$J:$J,D$29) -> 0 | E30: =SUM(B30:D30) -> 2
A31: Cliente potencial – contratista / operación de alto riesgo | B31: =COUNTIFS(Contactos!$M:$M,$A31,Contactos!$J:$J,B$29) -> 21 | C31: =COUNTIFS(Contactos!$M:$M,$A31,Contactos!$J:$J,C$29) -> 0 | D31: =COUNTIFS(Contactos!$M:$M,$A31,Contactos!$J:$J,D$29) -> 0 | E31: =SUM(B31:D31) -> 21
A32: Partner tecnológico / competidor | B32: =COUNTIFS(Contactos!$M:$M,$A32,Contactos!$J:$J,B$29) -> 59 | C32: =COUNTIFS(Contactos!$M:$M,$A32,Contactos!$J:$J,C$29) -> 0 | D32: =COUNTIFS(Contactos!$M:$M,$A32,Contactos!$J:$J,D$29) -> 0 | E32: =SUM(B32:D32) -> 59
A33: Canal / aliado – consultoría SST | B33: =COUNTIFS(Contactos!$M:$M,$A33,Contactos!$J:$J,B$29) -> 18 | C33: =COUNTIFS(Contactos!$M:$M,$A33,Contactos!$J:$J,C$29) -> 0 | D33: =COUNTIFS(Contactos!$M:$M,$A33,Contactos!$J:$J,D$29) -> 0 | E33: =SUM(B33:D33) -> 18
A34: Partner OEM – equipos acuícolas y marinos | B34: =COUNTIFS(Contactos!$M:$M,$A34,Contactos!$J:$J,B$29) -> 0 | C34: =COUNTIFS(Contactos!$M:$M,$A34,Contactos!$J:$J,C$29) -> 28 | D34: =COUNTIFS(Contactos!$M:$M,$A34,Contactos!$J:$J,D$29) -> 0 | E34: =SUM(B34:D34) -> 28
A35: Canal / distribuidor EPP | B35: =COUNTIFS(Contactos!$M:$M,$A35,Contactos!$J:$J,B$29) -> 0 | C35: =COUNTIFS(Contactos!$M:$M,$A35,Contactos!$J:$J,C$29) -> 15 | D35: =COUNTIFS(Contactos!$M:$M,$A35,Contactos!$J:$J,D$29) -> 0 | E35: =SUM(B35:D35) -> 15
A36: Aliado complementario – seguridad | B36: =COUNTIFS(Contactos!$M:$M,$A36,Contactos!$J:$J,B$29) -> 0 | C36: =COUNTIFS(Contactos!$M:$M,$A36,Contactos!$J:$J,C$29) -> 7 | D36: =COUNTIFS(Contactos!$M:$M,$A36,Contactos!$J:$J,D$29) -> 0 | E36: =SUM(B36:D36) -> 7
A37: Aliado complementario – salud | B37: =COUNTIFS(Contactos!$M:$M,$A37,Contactos!$J:$J,B$29) -> 0 | C37: =COUNTIFS(Contactos!$M:$M,$A37,Contactos!$J:$J,C$29) -> 1 | D37: =COUNTIFS(Contactos!$M:$M,$A37,Contactos!$J:$J,D$29) -> 0 | E37: =SUM(B37:D37) -> 1
A38: Institución / gremio / pabellón país | B38: =COUNTIFS(Contactos!$M:$M,$A38,Contactos!$J:$J,B$29) -> 0 | C38: =COUNTIFS(Contactos!$M:$M,$A38,Contactos!$J:$J,C$29) -> 30 | D38: =COUNTIFS(Contactos!$M:$M,$A38,Contactos!$J:$J,D$29) -> 0 | E38: =SUM(B38:D38) -> 30
A39: Proveedor industrial (equipos/insumos) | B39: =COUNTIFS(Contactos!$M:$M,$A39,Contactos!$J:$J,B$29) -> 0 | C39: =COUNTIFS(Contactos!$M:$M,$A39,Contactos!$J:$J,C$29) -> 0 | D39: =COUNTIFS(Contactos!$M:$M,$A39,Contactos!$J:$J,D$29) -> 336 | E39: =SUM(B39:D39) -> 336
A40: Total | B40: =SUM(B30:B39) -> 100 | C40: =SUM(C30:C39) -> 81 | D40: =SUM(D30:D39) -> 336 | E40: =SUM(E30:E39) -> 517
A42: Estado (pipeline) | B42: Cantidad
A43: Prospecto | B43: =COUNTIF(Contactos!$I:$I,A43) -> 517
A44: Contactado | B44: =COUNTIF(Contactos!$I:$I,A44) -> 0
A45: Reunión | B45: =COUNTIF(Contactos!$I:$I,A45) -> 0
A46: Propuesta | B46: =COUNTIF(Contactos!$I:$I,A46) -> 0
A47: Cliente | B47: =COUNTIF(Contactos!$I:$I,A47) -> 0
A48: No interesado | B48: =COUNTIF(Contactos!$I:$I,A48) -> 0
A50: Indicadores | B50: Cantidad
A51: Registros originales | B51: 528
A52: Empresas únicas | B52: =COUNTA(Contactos!$D$2:$D$3000) -> 517
A53: También en Exponor 2026 | B53: =COUNTIF(Contactos!$S$2:$S$3000,"*Exponor*") -> 55
A54: También en ExpoMina 2026 | B54: =COUNTIF(Contactos!$S$2:$S$3000,"*ExpoMina*") -> 8
A55: También en Directorio SSO | B55: =COUNTIF(Contactos!$S$2:$S$3000,"*Directorio*") -> 3
...

Sheet Eventos
A1: Evento | B1: País | C1: Valor para SafetyMind
A2: Directorio SSO 2026 – Cero Accidentes (22.ª ed.) | B2: Perú | C2: Mapa de ~670 proveedores SST en Perú (ver CRM_Directorio_SSO_2026).
A3: ExpoMina Perú 2026 | B3: Perú | C3: Feria minera: mineras, contratistas, OEM, tecnología y proveedores (ver CRM_ExpoMina_2026).
A4: Exponor 2026 (Antofagasta) | B4: Chile | C4: Feria minera del norte de Chile (ver CRM_Exponor_2026).
A5: AquaSur 2026 (Puerto Montt) | B5: Chile | C5: Feria acuícola: salmoneras, contratistas marítimos (buceo, wellboats, astilleros), tecnología acuícola (IA, ROV, IoT) y proveedores; nueva vertical para SafetyMind.
