Workbook

Sheet Contactos
A1: ID | B1: Nombre | C1: Cargo | D1: Empresa | E1: País | F1: Email | G1: LinkedIn | H1: Origen | I1: Estado | J1: Prioridad | K1: Próxima acción | L1: Notas | M1: Segmento SafetyMind | N1: Stand(s) | O1: Ubicación | P1: Agrupación | Q1: Razón social | R1: Descripción | S1: Web | T1: Cruce otros CRM
A2: 1 | D2: ALDEBARAN RESOURCES INC. | E2: Argentina | F2: fatima.olavarria@aldebaranresources.com | H2: Expo San Juan Minera 2026 | I2: Prospecto | J2: Alta | K2: Identificar Gerente de Seguridad/SSO de la operación o proyecto; proponer piloto (rajo, planta, flota) | L2: Expo San Juan Minera 2026. | M2: Cliente final – minera / energía (operación o proyecto) | N2: B204 | O2: Pabellón 1 | Q2: MINERA PEREGRINE ARGENTINA S.A.U. | R2: Proyecto de cobre en etapa de exploración avanzada, ubicado en Calingasta, San Juan, Argentina. Se trata de uno de los depósitos de cobre más grandes a nivel mundial. Actualmente, el proyecto avanza hacia la etapa de prefactibilidad, consolidando información clave para su desarrollo futuro. | T2: No
A3: 2 | D3: CALERAS SAN JUAN | E3: Argentina | H3: Expo San Juan Minera 2026 | I3: Prospecto | J3: Alta | K3: Identificar Gerente de Seguridad/SSO de la operación o proyecto; proponer piloto (rajo, planta, flota) | L3: Expo San Juan Minera 2026. Sin email publicado. | M3: Cliente final – minera / energía (operación o proyecto) | N3: E529 | E550 | E551 | O3: Pabellón 2 | Q3: CALERAS SAN JUAN SA | R3: Caleras San Juan S.A. es una empresa minera fundada en el año 1952. Con más de 70 años de experiencia en la fabricación de cales y productos derivados, somos la primer empresa calera de capitales 100% argentinos en obtener la certificación trinorma. | T3: No
A4: 3 | D4: CALIDRA | E4: Argentina | F4: info@calidra.com.ar | H4: Expo San Juan Minera 2026 | I4: Prospecto | J4: Alta | K4: Identificar Gerente de Seguridad/SSO de la operación o proyecto; proponer piloto (rajo, planta, flota) | L4: Expo San Juan Minera 2026. | M4: Cliente final – minera / energía (operación o proyecto) | N4: E547 | E548 | E549 | O4: Pabellón 2 | Q4: CEFAS S.A | R4: Calidra cuenta con más de 115 años de historia y experiencia en la industria de la cal, acompañando el desarrollo productivo de la región y siendo parte activa de las cadenas de valor de múltiples industrias. A lo largo de su trayectoria, ha consolidado un profundo conocimiento técnico, una cultura de trabajo sólida y un compromiso permanente con la calidad, la seguridad y la mejora continua. En este contexto, Calidra Cono Sur reúne las operaciones de Calidra en Argentina y Chile, integrando equipos, capacidades productivas y logísticas para brindar soluciones industriales de alto valor agregado a sectores estratégicos como minería, construcción, siderurgia, estabilización de suelos, agricultura, química, pinturas y recubrimientos. La compañía opera con yacimientos de alta pureza, reservas de largo plazo y tecnología de clase mundial, incluyendo hornos Maerz de alta eficiencia. La propuesta de valor de Calidra Cono Sur se basa en la seguridad de suministro, la pureza desde el origen, una alta capacidad productiva y logística, y un fuerte enfoque en la asistencia técnica, la capacitación y el trabajo conjunto con sus clientes. Sus procesos están certificados bajo normas ISO 9001, ISO 14001 e ISO 45001, garantizando estándares internacionales de calidad, ambiente y seguridad. Con una visión de desarrollo sostenible, Calidra asume el compromiso de reducir a cero las emisiones del grupo hacia 2050, impulsando iniciativas ambientales, sociales y de seguridad que generan un impacto positivo y duradero en las comunidades donde está presente. Porque en Calidra, la cal está siempre ahí. | S4: https://www.calidra.com.ar/ | T4: No
A5: 4 | D5: CASPOSO ARGENTINA LTD. - SUCURSAL ARGENTINA | E5: Argentina | F5: info@australgold.com | H5: Expo San Juan Minera 2026 | I5: Prospecto | J5: Alta | K5: Identificar Gerente de Seguridad/SSO de la operación o proyecto; proponer piloto (rajo, planta, flota) | L5: Expo San Juan Minera 2026. | M5: Cliente final – minera / energía (operación o proyecto) | N5: D443 | O5: Pabellón 2 | R5: Mina Casposo producción de oro y plata | S5: https://australgold.com/ | T5: No
A6: 5 | D6: ECO MINERA | E6: Argentina | H6: Expo San Juan Minera 2026 | I6: Prospecto | J6: Alta | K6: Identificar Gerente de Seguridad/SSO de la operación o proyecto; proponer piloto (rajo, planta, flota) | L6: Expo San Juan Minera 2026. Sin email publicado. | M6: Cliente final – minera / energía (operación o proyecto) | N6: A166 | A167 | O6: Pabellón 1 | Q6: ECO MINERA S.A | T6: No
A7: 6 | D7: EPSE | E7: Argentina | F7: info@epse.com.ar | H7: Expo San Juan Minera 2026 | I7: Prospecto | J7: Alta | K7: Identificar Gerente de Seguridad/SSO de la operación o proyecto; proponer piloto (rajo, planta, flota) | L7: Expo San Juan Minera 2026. | M7: Cliente final – minera / energía (operación o proyecto) | N7: Isla: 2E | O7: Exterior | Q7: ENERGIA PROVINCIAL SOCIEDAD DEL ESTADO | R7: EPSE no es solamente un generador, sino el brazo ejecutor del Gobierno de San Juan en materia energética. • EPSE cuenta con amplia experiencia en el rubro de parques solares fotovoltaicos conectados a la red, habiendo licitado, construido e inspeccionado distintas obras en el marco de las energía renovables, específicamente solares, en la provincia de San Juan y también fuera de ella. • Es de destacar también que EPSE opera y mantiene las distintas centrales hidroeléctricas, estaciones transformadoras de alta/media tensión y de parques de generación fotovoltaicas que son de su propiedad. • En términos de MDL, EPSE logró certificar la primera central hidroeléctrica de Sudamérica (Los Caracoles) en el año 2010, y vendió los bonos generados en el mercado obligatorio, además de participar en otros proyectos de descarbonización. MISION : • Gestionar, de forma eficaz y eficiente, los recursos energéticos de nuestra región, logrando la satisfacción de nuestros clientes, accionistas, socios y personal, generando valores económicos, sociales y ambientales mediante la integración público privada para la generación de energía, montaje de plantas y provisión de servicios al sector energético. • Desarrollar de forma continua todo nuestro personal • Innovar tecnológicamente • Identificar a largo plazo tanto las necesidades energéticas de la región como así también las oportunidades tecnológicas de generación, planificando el desarrollo y evolución de las fuentes energéticas para cubrir en tiempo y forma las necesidades. • Trabajar de manera segura y ambientalmente sostenible. VISION Ser reconocidos como la empresa referente, a nivel nacional, en generación eléctrica y desarrollo de proyectos pioneros e innovadores, sustentado en la eficiencia de sus acciones y en el profesionalismo de su personal en favor de sus clientes, la comunidad y el ambiente. | S7: https://www.epse.com.ar/ | T7: No
A8: 7 | D8: GLENCORE EL PACHÓN | E8: Argentina | F8: comunicaciones.elpachon@glencore.com.ar | H8: Expo San Juan Minera 2026 | I8: Prospecto | J8: Alta | K8: Identificar Gerente de Seguridad/SSO de la operación o proyecto; proponer piloto (rajo, planta, flota) | L8: Expo San Juan Minera 2026. | M8: Cliente final – minera / energía (operación o proyecto) | N8: B205 | B206 | B215 | O8: Pabellón 1 | Q8: GLENCORE PACHON S.A. | R8: Proyecto El Pachón El Pachón es un yacimiento de cobre y molibdeno emplazado en el departamento Calingasta, provincia de San Juan, Argentina. Se encuentra situado a 3.600 metros sobre el nivel del mar, a 5 kilómetros del límite internacional con Chile. 100% del yacimiento pertenece a la compañía Glencore. Actualmente se encuentra en etapa de exploración avanzada. La producción media prevista sería aproximadamente 360.000t anuales de cobre en concentrado para los 10 primeros años. Acerca de Glencore Glencore es una de las mayores empresas de recursos naturales diversificados del mundo y uno de los principales productores y comercializadores de más de 60 materias primas. A través de una red de activos, clientes y proveedores que se extiende por todo el mundo, producimos, procesamos, reciclamos, obtenemos, comercializamos y distribuimos los productos que hacen posible la vida cotidiana. Con más de 140.000 empleados y contratistas, y una sólida presencia en más de 30 países, incluidas regiones consolidadas y emergentes en materia de recursos naturales, nuestras actividades industriales y de comercialización cuentan con el respaldo de una red global de oficinas. Los clientes de Glencore son consumidores industriales, como los de los sectores automotriz, siderúrgico, de generación de energía, de fabricación de baterías y petrolero. También proporcionamos financiación, logística y otros servicios a productores y consumidores de materias primas. | S8: https://www.elpachon.com.ar/ | T8: No
A9: 8 | D9: GOLDEN MINING | E9: Argentina | H9: Expo San Juan Minera 2026 | I9: Prospecto | J9: Alta | K9: Identificar Gerente de Seguridad/SSO de la operación o proyecto; proponer piloto (rajo, planta, flota) | L9: Expo San Juan Minera 2026. Sin email publicado. | M9: Cliente final – minera / energía (operación o proyecto) | N9: D435 | D436 | O9: Pabellón 2 | Q9: GOLDEN MINING S.A. | R9: Golden Mining es una compañía minera enfocada en el desarrollo y producción de oro en Sudamérica. Su principal activo es la mina Hualilán, ubicado en San Juan, Argentina. La empresa se distingue por su estrategia de toll milling, que permite acelerar la generación de ingresos reduciendo inversión inicial y riesgos, junto con un enfoque en eficiencia operativa y desarrollo progresivo del proyecto. Golden Mining is a mining company focused on the development and production of gold in South America. Its flagship asset is the Hualilán Mine, located in San Juan, Argentina. The company stands out for its toll milling strategy, enabling early cash flow generation with lower upfront capital and reduced risk, combined with a focus on operational efficiency and phased project development. | T9: No
A10: 9 | D10: MCEWEN COPPER PROYECTO LOS AZULES | E10: Argentina | H10: Expo San Juan Minera 2026 | I10: Prospecto | J10: Alta | K10: Identificar Gerente de Seguridad/SSO de la operación o proyecto; proponer piloto (rajo, planta, flota) | L10: Expo San Juan Minera 2026. Sin email publicado. | M10: Cliente final – minera / energía (operación o proyecto) | N10: Isla: 16 | O10: Exterior | Q10: ANDES CORPORACION MINERA S.A. | T10: No
A11: 10 | D11: MOGOTES METALS INC. | E11: Argentina | F11: info@mogotesmetals.com | H11: Expo San Juan Minera 2026 | I11: Prospecto | J11: Alta | K11: Identificar Gerente de Seguridad/SSO de la operación o proyecto; proponer piloto (rajo, planta, flota) | L11: Expo San Juan Minera 2026. | M11: Cliente final – minera / energía (operación o proyecto) | N11: B214 | O11: Pabellón 1 | Q11: MOGOTES METALS INC | R11: Mogotes Metals es una empresa minera en fase de exploración y desarrollo dedicada a la adquisición y exploración de propiedades minerales en todo el mundo. Actualmente, el objetivo de la compañía es identificar un recurso mineral en el Proyecto Filo Sur. El objetivo general de la compañía es identificar, evaluar, adquirir y explorar propiedades minerales adicionales con el fin de descubrir más recursos minerales. | S11: https://www.mogotesmetals.com/ | T11: No
A12: 11 | D12: NEW PEAK | E12: Argentina | F12: agrahame@newpeak.com.au | H12: Expo San Juan Minera 2026 | I12: Prospecto | J12: Alta | K12: Identificar Gerente de Seguridad/SSO de la operación o proyecto; proponer piloto (rajo, planta, flota) | L12: Expo San Juan Minera 2026. | M12: Cliente final – minera / energía (operación o proyecto) | N12: D434 | O12: Pabellón 2 | R12: NEwPeak inició un nuevo programa de perforación en su proyecto aurífero Las Opeñas, 100 % de su propiedad, situado en el Departamento de Iglesia, provincia de San Juan, Argentina. La Compañía tambien esta a la espera de los resultados de los análisis de su primer programa de perforación en su proyecto Tansey, en busca de las prolongaciones de una histórica mina de oro subterránea en el distrito de Tansey, en Queensland, Australia. | S12: https://www.neupeak.com.au/ | T12: No
A13: 12 | D13: PAN AMERICAN ENERGY - AXION PUEBLA | E13: Argentina | H13: Expo San Juan Minera 2026 | I13: Prospecto | J13: Alta | K13: Identificar Gerente de Seguridad/SSO de la operación o proyecto; proponer piloto (rajo, planta, flota) | L13: Expo San Juan Minera 2026. Sin email publicado. | M13: Cliente final – minera / energía (operación o proyecto) | N13: F642 | F643 | O13: Pabellón 2 | Q13: PUEBLA EQUIPO | R13: AXION Energy Minería -Pan American Energy- trabaja de manera articulada con AXION Puebla en la provincia de San Juan para abastecer y acompañar el desarrollo del sector minero. En conjunto, brindan soluciones integrales de energía, asegurando el suministro de combustibles y lubricantes en zonas operativas clave, muchas veces de difícil acceso. Además, aportan logística especializada, asistencia técnica y soporte constante para garantizar la continuidad y eficiencia de las operaciones mineras. Este trabajo conjunto permite potenciar la actividad productiva en San Juan, acompañando a las empresas del sector con estándares de calidad, seguridad y compromiso, alineados con las necesidades específicas de la industria minera. | T13: No
A14: 13 | D14: SABLE RESOURCES LTD | E14: Canadá | H14: Expo San Juan Minera 2026 | I14: Prospecto | J14: Alta | K14: Identificar Gerente de Seguridad/SSO de la operación o proyecto; proponer piloto (rajo, planta, flota) | L14: Expo San Juan Minera 2026. Sin email publicado. | M14: Cliente final – minera / energía (operación o proyecto) | N14: B213 | O14: Pabellón 1 | R14: Sable Resources Ltd. is a Canada-based junior exploration company focused on the discovery and development of copper, gold, and related mineral projects across the Americas. In Argentina, the company has a strong presence in San Juan Province, where it has been actively exploring for more than 7 years. Its portfolio includes key projects such as Don Julio, El Fierro, Zorro, and Cerro Negro, among others, located within highly prospective Andean mineral belts. Sable applies a modern exploration approach based on solid geological models, integrated geophysical and geochemical data, and an active project generation strategy. The company aims to advance its portfolio through strategic partnerships while maintaining high technical, environmental, and community engagement standards. | T14: No
A15: 14 | D15: VELADERO | E15: Argentina | H15: Expo San Juan Minera 2026 | I15: Prospecto | J15: Alta | K15: Identificar Gerente de Seguridad/SSO de la operación o proyecto; proponer piloto (rajo, planta, flota) | L15: Expo San Juan Minera 2026. Sin email publicado. | M15: Cliente final – minera / energía (operación o proyecto) | N15: D441 | D442 | O15: Pabellón 2 | Q15: MINERA ARGENTINA GOLD | R15: Veladero es una mina de oro y plata situada en la provincia de San Juan - Argentina, a una altitud de entre 4.000 y 4.850 metros sobre el nivel del mar, somos una empresa conjunta de Barrick y Shandong Gold. Nuestra misión es ser una mina de oro de clase mundial, con un ambiente de trabajo libre de peligros y trabajadores plenos y comprometidos, que cree valor a largo plazo para nuestros socios y comunidades. | S15: https://www.veladero.com/ | T15: No
A16: 15 | D16: VICUÑA | E16: Argentina | H16: Expo San Juan Minera 2026 | I16: Prospecto | J16: Alta | K16: Identificar Gerente de Seguridad/SSO de la operación o proyecto; proponer piloto (rajo, planta, flota) | L16: Expo San Juan Minera 2026. Sin email publicado. | M16: Cliente final – minera / energía (operación o proyecto) | N16: B201 | B202 | B203 | B210 | B211 | O16: Pabellón 1 | Q16: VICUÑA CORP | T16: No
A17: 16 | D17: YPF | E17: Argentina | H17: Expo San Juan Minera 2026 | I17: Prospecto | J17: Alta | K17: Identificar Gerente de Seguridad/SSO de la operación o proyecto; proponer piloto (rajo, planta, flota) | L17: Expo San Juan Minera 2026. Sin email publicado. | M17: Cliente final – minera / energía (operación o proyecto) | N17: B244 | B245 | B246 | B252 | B253 | B254 | O17: Pabellón 1 | Q17: YPF S.A. | R17: Somos el mayor productor de Oil & Gas de la Argentina, con sólidos resultados y capacidad para llevar adelante los proyectos que convertirán al país en un exportador de energía a nivel mundial. Nuestro objetivo es convertirnos en una empresa no convencional de clase mundial y que Argentina pueda exportar USD 30.000 millones en petróleo y gas para el 2031. Hoy, estamos al frente de los proyectos industriales más ambiciosos del país. Lideramos el Vaca Muerta Oil Sur (VMOS), que potenciará la producción de crudo, y el Argentina LNG, un proyecto de escala global que permitirá exportar gas al mundo. Buscamos constantemente innovación y nuevas tecnologías. Con nuestros Real Time Intelligence Centers, tomamos decisiones más eficientes basadas en datos en tiempo real, aumentando la rentabilidad. Trabajamos por los combustibles del futuro y de calidad internacional. | S17: https://ypf.com/ | T17: No
A18: 17 | D18: ACONCAGUA SERVICIOS MINEROS SRL | E18: Argentina | F18: asanchez@aconcagua-trans.com.ar | H18: Expo San Juan Minera 2026 | I18: Prospecto | J18: Alta | K18: Identificar Jefe de Prevención/SSO; proponer piloto en frente de trabajo (perforación, transporte, campamento) | L18: Expo San Juan Minera 2026. | M18: Cliente final – contratista minero (operación, perforación, transporte, campamento) | N18: Isla: 32A | Isla: 32B | Isla: 38A | Isla: 38B | O18: Exterior | R18: Especialistas en Transporte Minero desde 2002, Impulsando el desarrollo de Recursos Humanos y Proveedores Locales. | S18: https://www.aconcagua-trans.com.ar/ | T18: No
A19: 18 | D19: ADL | E19: Argentina | F19: alejandroacosta@exploservice.com.ar | H19: Expo San Juan Minera 2026 | I19: Prospecto | J19: Alta | K19: Identificar Jefe de Prevención/SSO; proponer piloto en frente de trabajo (perforación, transporte, campamento) | L19: Expo San Juan Minera 2026. | M19: Cliente final – contratista minero (operación, perforación, transporte, campamento) | N19: A111 | A112 | A113 | A114 | A115 | A116 | A121 | A122 | A123 | A124 | A125 | A126 | Isla: 2A | Isla: 2B | Isla: 8A | Isla: 8B | Isla: 14A | Isla: 14B | O19: Pabellón 1 | P19: CASEMI | Q19: ADL S.R.L. | R19: ADL SRL es una empresa especializada en servicios de perforación y voladura orientados a la industria minera y a proyectos de ingeniería civil, abarcando tanto etapas de exploración como de producción. Asimismo, desarrolla excavaciones para obras de construcción, adaptándose a las necesidades específicas de cada proyecto. Con más de 25 años de trayectoria en el sector, ADL SRL se destaca por su amplia experiencia y por contar con un equipo de profesionales altamente capacitados, comprometidos con la excelencia operativa y la mejora continua de sus procesos. La empresa trabaja bajo estrictos estándares de calidad, seguridad y cuidado del medio ambiente, garantizando soluciones eficientes, confiables y sostenibles que contribuyen al cumplimiento de los objetivos de sus clientes. | T19: No
A20: 19 | D20: ANDEMIRA S.A. | E20: Argentina | F20: obertero@andemira.com.ar | H20: Expo San Juan Minera 2026 | I20: Prospecto | J20: Alta | K20: Identificar Jefe de Prevención/SSO; proponer piloto en frente de trabajo (perforación, transporte, campamento) | L20: Expo San Juan Minera 2026. | M20: Cliente final – contratista minero (operación, perforación, transporte, campamento) | N20: C328 | C347 | O20: Pabellón 1 | R20: ANDEMIRA es una empresa de servicios a la minería que nace con 20 años de historia. Nuestros pilares son: OPERACIONES DE CONFIANZA, COMPROMISO AMBIENTAL y TALENTO AL SERVISIO. Nos especializamos en operaciones mineras subterráneas y superficie, construcción de diques de colas (y sus alteos de cota), pad de lixiviación, apertura y mantenimiento de caminos, construcción de plataformas de perforación y obras civiles en yacimientos mineros. | S20: https://andemira.com.ar/ | T20: No
A21: 20 | D21: ANDESITA SAS | E21: Argentina | F21: eugeniaacosta@exploservice.com.ar | H21: Expo San Juan Minera 2026 | I21: Prospecto | J21: Alta | K21: Identificar Jefe de Prevención/SSO; proponer piloto en frente de trabajo (perforación, transporte, campamento) | L21: Expo San Juan Minera 2026. | M21: Cliente final – contratista minero (operación, perforación, transporte, campamento) | N21: A111 | A112 | A113 | A114 | A115 | A116 | A121 | A122 | A123 | A124 | A125 | A126 | Isla: 2A | Isla: 2B | Isla: 8A | Isla: 8B | Isla: 14A | Isla: 14B | O21: Pabellón 1 | P21: CASEMI | Q21: ANDESITA S. A. S. | R21: Andesita SAS es una empresa dedicada a la ejecución de obras civiles, con experiencia en proyectos vinculados al sector minero y energético. Cuenta con trayectoria en el desarrollo de infraestructura para parques solares, realizando trabajos de movimiento de suelo, preparación de terreno y colocación de estructuras. La empresa se destaca por su compromiso con la calidad, la seguridad operativa y el cumplimiento de plazos, adaptándose a las necesidades de cada proyecto. Andesita SAS contribuye al desarrollo de soluciones eficientes y al crecimiento de la infraestructura energética sostenible. | S21: https://www.rocktec.com.ar/ | T21: No
A22: 21 | D22: ARAMARK | E22: Argentina | F22: comercial@aramark.com.ar | H22: Expo San Juan Minera 2026 | I22: Prospecto | J22: Alta | K22: Identificar Jefe de Prevención/SSO; proponer piloto en frente de trabajo (perforación, transporte, campamento) | L22: Expo San Juan Minera 2026. | M22: Cliente final – contratista minero (operación, perforación, transporte, campamento) | N22: D433 | O22: Pabellón 2 | Q22: CENTRAL DE RESTAURANTES SRL | R22: Aramark es una Empresa de Servicios de Alimentación en Campamentos Mineros e Industrias, Servicios de Hotelería y Gestión Integral de Instalaciones. | S22: https://www.aramark.ar/ | T22: No
A23: 22 | D23: ARCE GEOFÍSICOS ARGENTINA | E23: Argentina | F23: garce@geofisicos.com.pe | H23: Expo San Juan Minera 2026 | I23: Prospecto | J23: Alta | K23: Identificar Jefe de Prevención/SSO; proponer piloto en frente de trabajo (perforación, transporte, campamento) | L23: Expo San Juan Minera 2026. También en: Directorio SSO (ID 533). | M23: Cliente final – contratista minero (operación, perforación, transporte, campamento) | N23: B243 | O23: Pabellón 1 | R23: ARCE GEOFÍSICOS ARGENTINA: ESTUDIOS Y CONSULTORÍA GEOFÍSICA Desde 1960, Arce Geofísicos ha liderado el sector de la geofísica en América Latina, ofreciendo soluciones innovadoras y de alta calidad. Contamos con una sólida experiencia en toda América Latina, trabajando en estrecha colaboración con empresas líderes del sector minero, petrolero, agrícola, de energías renovables y de construcción. Nuestra red de operaciones se extiende a países como Perú, México, Bolivia, Colombia, Chile, Argentina, Ecuador, Guyana, Nicaragua, Guatemala, Panamá, Honduras, El Salvador, y República Dominicana, donde hemos contribuido con tecnología de punta y un equipo altamente capacitado. Productos/servicios de la empresa: I. Estudios de Prospección Minera: Magnetometría (precesión de protones, overhauser omnidireccional, vapor de potasio y vapor de cesio), Radiometría, Microgravimetría, Resistividad Eléctrica y Polarización Inducida (1D, 2D, 2D a 3D), así como Resistividad Eléctrica y Polarización Inducida de Señal Completa y Configuración Distribuida (AG-DAS), Métodos Electromagnéticos de Dominio de Tiempo (TDEM) con diversos sensores (fluxgate, bobina de baja frecuencia), Magnetometría en UAV, Análisis de Muestras, Magnetotelúrico (MT) y Audio-magnetotelúrico (AMT). II. Aplicaciones para Geotecnia: Microgravimetría, Tomografía Sísmica de Onda P, Análisis Multicanal de Onda de Superficie con fuente activa (MASW) o con fuente pasiva (MAM), Resistividad Eléctrica (1D, 2D, 3D), y Métodos Electromagnéticos de Dominio de Tiempo (TDEM) con diversos sensores (fluxgate, bobina de baja frecuencia). III. Estudios de Prospección por Agua Subterránea: Para estas aplicaciones utilizamos los métodos de Resistividad Eléctrica (1D, 2D, 3D), y Métodos Electromagnéticos de Dominio de Tiempo (TDEM) con distintos tamaños de loops para alcanzar distintas profundidades. | S23: https://www.geofisicos.com/ | T23: Directorio SSO (ID 533)
A24: 23 | D24: ATA | E24: Argentina | F24: mariela.pringles@atalimentaria.com | H24: Expo San Juan Minera 2026 | I24: Prospecto | J24: Alta | K24: Identificar Jefe de Prevención/SSO; proponer piloto en frente de trabajo (perforación, transporte, campamento) | L24: Expo San Juan Minera 2026. | M24: Cliente final – contratista minero (operación, perforación, transporte, campamento) | N24: Isla: 57 | Isla: 77 | O24: Exterior | Q24: ALTA TECNOLOGÍA ALIMENTARIA | R24: Somos una empresa argentina radicada en San Juan, especializada en alimentación institucional, hotelería y servicios en sitios remotos. Nuestro equipo combina experiencia, innovación y compromiso humano para garantizar bienestar y eficiencia en cada operación de manera sostenible. | S24: https://atalimentaria.com/web/ | T24: No
A25: 24 | D25: B & W | E25: Argentina | H25: Expo San Juan Minera 2026 | I25: Prospecto | J25: Alta | K25: Identificar Jefe de Prevención/SSO; proponer piloto en frente de trabajo (perforación, transporte, campamento) | L25: Expo San Juan Minera 2026. Sin email publicado. | M25: Cliente final – contratista minero (operación, perforación, transporte, campamento) | N25: A117 | A118 | O25: Pabellón 1 | Q25: B & W HIDROGEOLOGIA Y MEDIOAMBIENTE S.R.L. | R25: BW es una empresa especializada en soluciones hidrogeológicas y ambientales para la industria minera, con foco en el desarrollo sostenible y la gestión eficiente de los recursos hídricos. Brindamos servicios integrales que abarcan desde la caracterización hidrogeológica, monitoreo y muestreo de aguas superficiales y subterráneas, hasta modelación numérica, diseño de sistemas de desaguado de mina y soporte técnico para operaciones en entornos complejos, incluyendo alta montaña. Nuestro enfoque combina conocimiento técnico sólido, experiencia en terreno y tecnologías avanzadas, lo que nos permite acompañar a nuestros clientes en todas las etapas del proyecto, desde la exploración hasta la operación y cierre. En BW trabajamos para asegurar decisiones basadas en datos confiables, minimizando riesgos y promoviendo un desarrollo responsable de los recursos. | T25: No
A26: 25 | D26: BECHER LOGISTICA | E26: Argentina | F26: analaura@becherlogistica.com.ar | H26: Expo San Juan Minera 2026 | I26: Prospecto | J26: Alta | K26: Identificar Jefe de Prevención/SSO; proponer piloto en frente de trabajo (perforación, transporte, campamento) | L26: Expo San Juan Minera 2026. | M26: Cliente final – contratista minero (operación, perforación, transporte, campamento) | N26: A159 | A160 | O26: Pabellón 1 | Q26: VIA SRL | R26: Becher Logística es una empresa sanjuanina especializada en soluciones logísticas integrales y mineras , con sólida trayectoria en transporte de cargas generales, distribución, cargas peligrosas, proyectos especiales y operaciones para la industria y el sector minero. Brindamos servicios adaptados a cada cliente, priorizando la seguridad vial, la eficiencia operativa, el cumplimiento normativo y altos estándares de servicio en cada etapa. Trabajamos bajo principios de mejora continua y normas de gestión de calidad, con experiencia en entornos de alta exigencia acompañando proyectos en minería, comercio e industria. Nuestro compromiso es impulsar el crecimiento de nuestros clientes y comunidades a través de un servicio confiable y humano, brindando seguridad y soluciones que respondan a necesidades reales. | S26: https://www.becherlogistica.com.ar/ | T26: No
A27: 26 | D27: C&M SA - CONSTRUCCION Y MINERIA SA | E27: Argentina | F27: contacto@cymweb.com.ar | H27: Expo San Juan Minera 2026 | I27: Prospecto | J27: Alta | K27: Identificar Jefe de Prevención/SSO; proponer piloto en frente de trabajo (perforación, transporte, campamento) | L27: Expo San Juan Minera 2026. | M27: Cliente final – contratista minero (operación, perforación, transporte, campamento) | N27: B218 | B219 | O27: Pabellón 1 | Q27: CONSTRUCCION Y MINERIA S.A. | R27: Desde 1998, Construcción & Minería SA se dedica a ofrecer servicios integrales de alta calidad para los sectores minero, petrolero y civil. Nuestro enfoque combina experiencia, tecnología de vanguardia y un compromiso constante con la satisfacción de nuestros clientes. Trabajamos como socios estratégicos para superar los desafíos técnicos y operativos de cada proyecto. Brindamos atención personalizada, asesoramiento y excelente calidad de insumos y servicios. Calidad garantizada: Implementamos los más altos estándares internacionales de calidad en cada uno de nuestros procesos Equipo experimentado: Contamos con un experimentado personal dedicados a garantizar los mejores resultados. Altos estándares en tecnología: Productos de primera línea de todas las aristas del mundo, Canadá, USA, Europa, Australia y Oriente. Orientación al cliente: Trabajamos como verdaderos socios estratégicos, avanzando juntos con perseverancia, humildad y disciplina. | S27: http://cymweb.com.ar/ | T27: No
A28: 27 | D28: CASTEM | E28: Perú | F28: elozada@castem.com.pe | H28: Expo San Juan Minera 2026 | I28: Prospecto | J28: Alta | K28: Identificar Jefe de Prevención/SSO; proponer piloto en frente de trabajo (perforación, transporte, campamento) | L28: Expo San Juan Minera 2026. También en: Directorio SSO (ID 20); ExpoMina (ID 68). | M28: Cliente final – contratista minero (operación, perforación, transporte, campamento) | N28: A161 | O28: Pabellón 1 | R28: Somos una empresa 100 % peruana con 25 años de experiencia en minería y construcción. Brindamos soluciones integrales e innovadoras para la estabilización, fortificación y sostenimiento de roca y suelo, desarrollando productos de alta calidad adaptados a cada cliente. Contamos con un amplio portafolio y un equipo de ingenieros que visita operaciones mineras para ofrecer soporte técnico directo, en coordinación con el área comercial. Ofrecemos cartuchos de resina y cemento, cargadores de ANFO, pernos de anclaje y de fricción “Split Set”, y bombas de inyección, entre otros. Brindamos acompañamiento permanente, soporte comercial y asistencia técnica especializada, garantizando soluciones eficientes y confiables en cada proyecto. | S28: https://castem.com.pe/ | T28: Directorio SSO (ID 20); ExpoMina (ID 68)
A29: 28 | D29: CATERWEST | E29: Argentina | F29: info@caterwest.com | H29: Expo San Juan Minera 2026 | I29: Prospecto | J29: Alta | K29: Identificar Jefe de Prevención/SSO; proponer piloto en frente de trabajo (perforación, transporte, campamento) | L29: Expo San Juan Minera 2026. | M29: Cliente final – contratista minero (operación, perforación, transporte, campamento) | N29: Isla: 13 | O29: Exterior | Q29: CATERWEST S.A | R29: Somos líderes en la provisión de soluciones integrales para la vida en sitios remotos, con una sólida especialización en los sectores minero, energético e industrial. A través de nuestra gestión en alimentación, hotelería, logística y mantenimiento, nos posicionamos como el aliado estratégico que garantiza la continuidad operativa de nuestros clientes. Con ADN sanjuanino y estándares internacionales, operamos bajo un firme compromiso de gestión ambiental y desarrollo genuino de las comunidades locales, transformando servicios en valor compartido. | S29: https://caterwest.com/ | T29: No
A30: 29 | D30: CINTER | E30: Argentina | F30: santiago.ochoa@cinter.com.ar | H30: Expo San Juan Minera 2026 | I30: Prospecto | J30: Alta | K30: Identificar Jefe de Prevención/SSO; proponer piloto en frente de trabajo (perforación, transporte, campamento) | L30: Expo San Juan Minera 2026. | M30: Cliente final – contratista minero (operación, perforación, transporte, campamento) | N30: B207 | B208 | B216 | B217 | O30: Pabellón 1 | Q30: CINTER S.R.L. | R30: CINTER es una empresa argentina de Ingeniería y Construcciones, con más de 50 años de experiencia en el mercado de Obras Industriales, lo que la han posicionado como líder en la fabricación de Estructuras Metálicas y ejecución de obras “Llave en Mano” para diversos sectores de la industria y con una destacada participación en el sector minero. Se ha consolidado como el mayor fabricante de estructuras metálicas del país, habiendo participado en la construcción de la mayoría de los grandes proyectos mineros del país. Es de destacar, que contamos con la planta de procesamiento de acero más grande y moderna del país con una capacidad de producción superior a 1.500Tn/mes, bajo los más altos estándares de calidad que demanda el sector y como consecuencia del ambicioso programa de inversión que viene ejecutando la empresa en los últimos 10 años. Ejemplo de esto último, lo constituye una línea robotizada de ensamblado de estructura, de origen austríaco, única en Sudamérica y que representa la tecnología más evolucionada que existe en el mercado de las estructuras de acero que incrementa, no solo la capacidad productiva de la empresa, sino también los niveles la calidad. | S30: https://www.cinter.com.ar/ | T30: No
A31: 30 | D31: COCYAR S.A. | E31: Argentina | F31: juancarloscaffaratti@cocyar.com | H31: Expo San Juan Minera 2026 | I31: Prospecto | J31: Alta | K31: Identificar Jefe de Prevención/SSO; proponer piloto en frente de trabajo (perforación, transporte, campamento) | L31: Expo San Juan Minera 2026. | M31: Cliente final – contratista minero (operación, perforación, transporte, campamento) | N31: F636 | F637 | F638 | F645 | F648 | F655 | F656 | F657 | F658 | F659 | F660 | F661 | F662 | F663 | F664 | F665 | F666 | F667 | O31: Pabellón 2 | P31: CFI - CONSEJO FEDERAL DE INVERSIONES | R31: COCYAR SA Somos una empresa constructora con más de 30 años de trayectoria en el gerenciamiento y ejecución de obras civiles, de arquitectura y electromecánicas, especializándose en proyectos bajo la modalidad "llave en mano", contando con certificaciones de calidad. Actualmente estamos realizando propuestas personalizadas y adaptadas a las necesidades específicas de nuestros clientes. Debido a su perfil y nuestra experiencia en distintas áreas de desarrollos, como infraestructura, obras civiles, arquitectura e industrial de todo tipo. Fabricamos nuestras propias estructuras metálicas, ejecutamos Obras eléctricas en BT, MT y AT, movimientos de suelos, bases y naves industriales, plantas de tratamientos, acueductos, infraestructura urbana, por lo que nos gustaría presentarles formalmente nuestros servicios y explorar posibles proyectos a futuro. Contamos con la capacidad de formar parte de un proyecto desde la ingeniería, la construcción y la puesta en marcha. En algunos casos, operamos y mantenemos nuestras obras. No dude en llamarnos, ofrecemos soluciones reales a sus necesidades. Cordiales saludos. Juan | S31: https://www.cocyar.com/ | T31: No
A32: 31 | D32: CONOSUR DRILLING S.A. | E32: Argentina | H32: Expo San Juan Minera 2026 | I32: Prospecto | J32: Alta | K32: Identificar Jefe de Prevención/SSO; proponer piloto en frente de trabajo (perforación, transporte, campamento) | L32: Expo San Juan Minera 2026. Sin email publicado. | M32: Cliente final – contratista minero (operación, perforación, transporte, campamento) | N32: C344 | O32: Pabellón 1 | Q32: CONOSUR DRILLING SA | R32: ConoSur Drilling S.A. es una empresa argentina especializada en servicios de perforación para la industria minera, con más de 25 años de experiencia acumulada en el sector. La compañía brinda soluciones integrales en perforación diamantina, rotary, aire reverso y estudios de suelo, incorporando tecnología de vanguardia y equipos adaptados a los desafíos operativos de cada proyecto. Con presencia en distintas regiones del país y un equipo conformado por profesionales altamente calificados, ConoSur Drilling se posiciona como un socio estratégico para campañas de exploración minera, desarrollo de recursos y perforaciones de producción. Su modelo de gestión está basado en la mejora continua, la eficiencia operativa y un fuerte compromiso con la seguridad, la salud, el medio ambiente y las comunidades donde opera, promoviendo un desarrollo sostenible de la industria minera argentina | T32: No
A33: 32 | D33: CRUZ DEL SUR | E33: Argentina | F33: marketing@cruzdelsur.com | H33: Expo San Juan Minera 2026 | I33: Prospecto | J33: Alta | K33: Identificar Jefe de Prevención/SSO; proponer piloto en frente de trabajo (perforación, transporte, campamento) | L33: Expo San Juan Minera 2026. | M33: Cliente final – contratista minero (operación, perforación, transporte, campamento) | N33: B255 | O33: Pabellón 1 | Q33: VICTOR MASSON CRUZ DEL SUR S A | R33: Cruz del Sur es una compañía argentina de transporte y logística integral con 70 años de trayectoria, una red federal de sucursales y cobertura en todo el país. Acompaña a empresas de distintos sectores con soluciones adaptadas a las necesidades de cada operación y cuenta con una amplia experiencia en industrias de alta exigencia, como la minería. Para este sector, desarrolla servicios de abastecimiento, transporte de cargas generales y peligrosas y operaciones especiales, combinando conocimiento regional, trazabilidad, capacidad operativa 24/7 y altos estándares de seguridad, con certificaciones específicas como el Código Internacional para el Manejo del Cianuro (ICMI). | S33: https://www.cruzdelsur.com/ | T33: No
A34: 33 | D34: CUYO MINERO | E34: Argentina | H34: Expo San Juan Minera 2026 | I34: Prospecto | J34: Alta | K34: Identificar Jefe de Prevención/SSO; proponer piloto en frente de trabajo (perforación, transporte, campamento) | L34: Expo San Juan Minera 2026. Sin email publicado. | M34: Cliente final – contratista minero (operación, perforación, transporte, campamento) | N34: C326 | O34: Pabellón 1 | T34: No
A35: 34 | D35: DELTA MINING | E35: Argentina | F35: info@deltamining.com.ar | H35: Expo San Juan Minera 2026 | I35: Prospecto | J35: Alta | K35: Identificar Jefe de Prevención/SSO; proponer piloto en frente de trabajo (perforación, transporte, campamento) | L35: Expo San Juan Minera 2026. | M35: Cliente final – contratista minero (operación, perforación, transporte, campamento) | N35: A131 | O35: Pabellón 1 | Q35: DELTA MINING S.A. | R35: QUE HACEMOS: Brindar servicios de alquiler de equipos viales para movimientos de suelo con operador, ofreciendo soluciones flexibles y adaptables, que satisfagan las necesidades de nuestros clientes. Contribuyendo a la apertura de caminos en zonas foráneas, a través de un desarrollo sustentable y bajo un estricto cuidado del medio ambiente, preservando la salud, la seguridad y el bienestar de nuestros empleados. NUESTROS SERVICIOS: SERVICIOS VIALES Ofrecemos servicios de apertura de caminos en alta cordillera, movimiento de suelo, nivelación y de limpieza de terrenos. Para ello, contamos con equipos exclusivos de altísima calidad y personal capacitado para brindar la mejor atención a nuestros clientes. Asimismo, realizamos trabajos de planchadas para perforación, excavaciones y trincheras. ALQUILER DE EQUIPOS VIALES Ofrecemos en alquiler equipos viales de alta calidad con y sin chofer. SERVICIO DE HIDROGRÚA Ofrecemos un servicio integral de carga, movimientos, transporte y descarga de materiales; facilitando la logística y reduciendo costos y tiempos para su empresa. ALQUILER DE CAMIÓN HIDROGRÚA Ofrecemos en alquiler camiones Hidrogrúa con y sin chofer. ALQUILER DE CAMIÓN CISTERNA Ofrecemos en alquiler camión cisterna con y sin chofer, con permisos para el transporte de mercancía peligrosa vigentes. ALQUILER DE CAMIONETAS Alquiler de camionetas 4x4 equipadas para cordillera, con y sin chofer. EXPERIENCIA: Nuestro equipo de profesionales participó en proyectos relevantes (como Filo del sol, Josemaria, Filo sur, el Fierro), adquiriendo experiencia desde la Prospección hasta la etapa de Explotación. Contamos con altos estándares de protección y compromiso hacia el cuidado del medio ambiente, trabajando en armonía con las comunidades. Desarrollamos un trabajo acorde a las mejores prácticas profesionales, guardando un alto valor a la confidencialidad con nuestros clientes. Creemos en la cooperación y el trabajo conjunto para desarrollar sinergias. QUE NOS DIFERENCIA: Promovemos los valores de confiabilidad, puntualidad, honestidad y el respeto hacia el cliente, siendo estos los que rigen nuestro accionar diario y los que nos motivan a evolucionar para brindar un servicio que supere las expectativas de nuestros clientes Nuestra trayectoria avala la calidad y responsabilidad de nuestro personal, así como también la solución a las necesidades particulares de cada empresa, adaptando el servicio de acuerdo a las necesidades del trabajo requerido | S35: https://deltamining.com.ar/ | T35: No
A36: 35 | D36: DRILLAR SAN JUAN | E36: Argentina | F36: info@drillar.ar | H36: Expo San Juan Minera 2026 | I36: Prospecto | J36: Alta | K36: Identificar Jefe de Prevención/SSO; proponer piloto en frente de trabajo (perforación, transporte, campamento) | L36: Expo San Juan Minera 2026. | M36: Cliente final – contratista minero (operación, perforación, transporte, campamento) | N36: A102 | A103 | O36: Pabellón 1 | Q36: DRILLAR SAN JUAN S.A.S | R36: DrillAr es una compañía argentina de perforación liderada por un equipo de profesionales con vasta experiencia en el rubro de la perforación minera y petróleo. Este personal se ha desempeñado en cargos ejecutivos y operativos en varias empresas multinacionales de perforación contribuyendo al éxito de cada una de ellas donde se desempeñó. La experiencia del equipo permite a la empresa, conocer una gran cantidad de proyectos de exploración y mineros a nivel nacional, además de conocer todas las técnicas de perforación y de servicios asociados. | S36: https://drillar.ar/ | T36: No
A37: 36 | D37: ECOVIAL | E37: Argentina | F37: ecovialsrl@gmail.com | H37: Expo San Juan Minera 2026 | I37: Prospecto | J37: Alta | K37: Identificar Jefe de Prevención/SSO; proponer piloto en frente de trabajo (perforación, transporte, campamento) | L37: Expo San Juan Minera 2026. | M37: Cliente final – contratista minero (operación, perforación, transporte, campamento) | N37: Isla: 36 | O37: Exterior | R37: ECO VIAL SRL es una empresa especializada en movimientos de suelo y servicios con maquinaria vial, orientada a brindar soluciones eficientes para proyectos de obra civil, minería y desarrollo de infraestructura. Contamos con experiencia en trabajos de terraplenes, nivelación de terrenos, excavaciones, apertura de caminos, limpieza de predios y desagües, adaptándonos a las necesidades específicas de cada cliente y proyecto. Disponemos de un moderno parque de maquinaria vial en alquiler, operada por personal capacitado, garantizando productividad, seguridad y cumplimiento de plazos. | T37: No
A38: 37 | D38: ENAEX | E38: Argentina | F38: roberta.politano@enaex.com | H38: Expo San Juan Minera 2026 | I38: Prospecto | J38: Alta | K38: Identificar Jefe de Prevención/SSO; proponer piloto en frente de trabajo (perforación, transporte, campamento) | L38: Expo San Juan Minera 2026. También en: Exponor (ID 38). | M38: Cliente final – contratista minero (operación, perforación, transporte, campamento) | N38: A132 | A133 | A144 | A145 | Isla: 7 | O38: Pabellón 1 | Q38: ENAEX ARGENTINA SRL | R38: Empresa líder en prestación de servicios integrales de fragmentación de rocas para la minería a cielo abierto (OP) y subterránea (UG), construcción y exploración sísmica. Se especializa en fabricación, comercialización y distribución de explosivos, emulsiones y sistema de iniciación remotos a distancia con tecnología de última generación | T38: Exponor (ID 38)
A39: 38 | D39: ESPECO | E39: Argentina | F39: david@especo.com.ar | H39: Expo San Juan Minera 2026 | I39: Prospecto | J39: Alta | K39: Identificar Jefe de Prevención/SSO; proponer piloto en frente de trabajo (perforación, transporte, campamento) | L39: Expo San Juan Minera 2026. | M39: Cliente final – contratista minero (operación, perforación, transporte, campamento) | N39: A111 | A112 | A113 | A114 | A115 | A116 | A121 | A122 | A123 | A124 | A125 | A126 | Isla: 2A | Isla: 2B | Isla: 8A | Isla: 8B | Isla: 14A | Isla: 14B | O39: Pabellón 1 | P39: CASEMI | Q39: ESPECO S.R.L. | R39: En ESPECO SRL brindamos soluciones integrales en alquiler de vehículos 4x4, orientadas a empresas que operan en entornos exigentes y de difícil acceso. Nos especializamos en acompañar industrias como la minería, energía, petróleo y obras de infraestructura, garantizando movilidad segura, eficiente y confiable en todo tipo de terrenos. Nuestra flota está compuesta por unidades modernas, equipadas y mantenidas bajo estrictos estándares de calidad y seguridad, adaptadas a las condiciones más desafiantes. Cada vehículo es sometido a controles preventivos periódicos, asegurando un rendimiento óptimo y minimizando riesgos operativos. En ESPECO entendemos que la seguridad es un valor clave. Por ello, incorporamos protocolos rigurosos en cada servicio, alineados con las normativas vigentes y las exigencias de nuestros clientes. Nuestro compromiso es brindar no solo vehículos, sino soluciones que acompañen la continuidad operativa de cada proyecto. Nos destacamos por la flexibilidad, la respuesta rápida y la atención personalizada, adaptándonos a las necesidades específicas de cada cliente. Acompañamos cada operación con un enfoque profesional, confiable y orientado a resultados. | S39: https://www.especo.com.ar/ | T39: No
A40: 39 | D40: FG LOGISTICA | E40: Argentina | H40: Expo San Juan Minera 2026 | I40: Prospecto | J40: Alta | K40: Identificar Jefe de Prevención/SSO; proponer piloto en frente de trabajo (perforación, transporte, campamento) | L40: Expo San Juan Minera 2026. Sin email publicado. También en: Exponor (ID 42). | M40: Cliente final – contratista minero (operación, perforación, transporte, campamento) | N40: F610 | O40: Pabellón 2 | R40: Logística FG es una unidad de negocios del Grupo FG, que ofrece soluciones logísticas integrales, incluyendo manejo de contenedores, manipulación de carga, almacenamiento de importación y exportación, y servicios de transporte de carga | T40: Exponor (ID 42)
...

Sheet Oportunidades
A1: ID oportunidad | B1: ID contacto | C1: Empresa | D1: Necesidad | E1: Solución propuesta | F1: Etapa | G1: Valor estimado | H1: Probabilidad | I1: Próxima acción | J1: Fecha

Sheet Resumen
A1: Evento/Fuente | B1: País | C1: Cantidad
A2: Expo San Juan Minera 2026 | B2: Argentina | C2: =COUNTIFS(Contactos!$H:$H,$A2,Contactos!$E:$E,$B2) -> 386
A3: Expo San Juan Minera 2026 | B3: Perú | C3: =COUNTIFS(Contactos!$H:$H,$A3,Contactos!$E:$E,$B3) -> 11
A4: Expo San Juan Minera 2026 | B4: Alemania | C4: =COUNTIFS(Contactos!$H:$H,$A4,Contactos!$E:$E,$B4) -> 9
A5: Expo San Juan Minera 2026 | B5: Canadá | C5: =COUNTIFS(Contactos!$H:$H,$A5,Contactos!$E:$E,$B5) -> 5
A6: Expo San Juan Minera 2026 | B6: Países Bajos | C6: =COUNTIFS(Contactos!$H:$H,$A6,Contactos!$E:$E,$B6) -> 5
A7: Expo San Juan Minera 2026 | B7: Chile | C7: =COUNTIFS(Contactos!$H:$H,$A7,Contactos!$E:$E,$B7) -> 5
A8: Expo San Juan Minera 2026 | B8: China | C8: =COUNTIFS(Contactos!$H:$H,$A8,Contactos!$E:$E,$B8) -> 3
A9: Expo San Juan Minera 2026 | B9: Finlandia | C9: =COUNTIFS(Contactos!$H:$H,$A9,Contactos!$E:$E,$B9) -> 1
A10: Expo San Juan Minera 2026 | B10: Estados Unidos | C10: =COUNTIFS(Contactos!$H:$H,$A10,Contactos!$E:$E,$B10) -> 1
A11: Total | C11: =SUM(C2:C10) -> 426
A13: Segmento SafetyMind | B13: Alta | C13: Media | D13: Baja | E13: Total
A14: Cliente final – minera / energía (operación o proyecto) | B14: =COUNTIFS(Contactos!$M:$M,$A14,Contactos!$J:$J,B$13) -> 16 | C14: =COUNTIFS(Contactos!$M:$M,$A14,Contactos!$J:$J,C$13) -> 0 | D14: =COUNTIFS(Contactos!$M:$M,$A14,Contactos!$J:$J,D$13) -> 0 | E14: =SUM(B14:D14) -> 16
A15: Cliente final – contratista minero (operación, perforación, transporte, campamento) | B15: =COUNTIFS(Contactos!$M:$M,$A15,Contactos!$J:$J,B$13) -> 56 | C15: =COUNTIFS(Contactos!$M:$M,$A15,Contactos!$J:$J,C$13) -> 0 | D15: =COUNTIFS(Contactos!$M:$M,$A15,Contactos!$J:$J,D$13) -> 0 | E15: =SUM(B15:D15) -> 56
A16: Partner tecnológico / competidor | B16: =COUNTIFS(Contactos!$M:$M,$A16,Contactos!$J:$J,B$13) -> 24 | C16: =COUNTIFS(Contactos!$M:$M,$A16,Contactos!$J:$J,C$13) -> 0 | D16: =COUNTIFS(Contactos!$M:$M,$A16,Contactos!$J:$J,D$13) -> 0 | E16: =SUM(B16:D16) -> 24
A17: Canal / aliado – consultoría, capacitación y certificación | B17: =COUNTIFS(Contactos!$M:$M,$A17,Contactos!$J:$J,B$13) -> 12 | C17: =COUNTIFS(Contactos!$M:$M,$A17,Contactos!$J:$J,C$13) -> 0 | D17: =COUNTIFS(Contactos!$M:$M,$A17,Contactos!$J:$J,D$13) -> 0 | E17: =SUM(B17:D17) -> 12
A18: Partner OEM – maquinaria y equipos mineros | B18: =COUNTIFS(Contactos!$M:$M,$A18,Contactos!$J:$J,B$13) -> 0 | C18: =COUNTIFS(Contactos!$M:$M,$A18,Contactos!$J:$J,C$13) -> 39 | D18: =COUNTIFS(Contactos!$M:$M,$A18,Contactos!$J:$J,D$13) -> 0 | E18: =SUM(B18:D18) -> 39
A19: Canal / distribuidor EPP | B19: =COUNTIFS(Contactos!$M:$M,$A19,Contactos!$J:$J,B$13) -> 0 | C19: =COUNTIFS(Contactos!$M:$M,$A19,Contactos!$J:$J,C$13) -> 7 | D19: =COUNTIFS(Contactos!$M:$M,$A19,Contactos!$J:$J,D$13) -> 0 | E19: =SUM(B19:D19) -> 7
A20: Aliado complementario – seguridad y emergencias | B20: =COUNTIFS(Contactos!$M:$M,$A20,Contactos!$J:$J,B$13) -> 0 | C20: =COUNTIFS(Contactos!$M:$M,$A20,Contactos!$J:$J,C$13) -> 8 | D20: =COUNTIFS(Contactos!$M:$M,$A20,Contactos!$J:$J,D$13) -> 0 | E20: =SUM(B20:D20) -> 8
A21: Aliado complementario – salud | B21: =COUNTIFS(Contactos!$M:$M,$A21,Contactos!$J:$J,B$13) -> 0 | C21: =COUNTIFS(Contactos!$M:$M,$A21,Contactos!$J:$J,C$13) -> 3 | D21: =COUNTIFS(Contactos!$M:$M,$A21,Contactos!$J:$J,D$13) -> 0 | E21: =SUM(B21:D21) -> 3
A22: Institución / cámara / medio / gobierno | B22: =COUNTIFS(Contactos!$M:$M,$A22,Contactos!$J:$J,B$13) -> 0 | C22: =COUNTIFS(Contactos!$M:$M,$A22,Contactos!$J:$J,C$13) -> 38 | D22: =COUNTIFS(Contactos!$M:$M,$A22,Contactos!$J:$J,D$13) -> 0 | E22: =SUM(B22:D22) -> 38
A23: Proveedor industrial / servicios | B23: =COUNTIFS(Contactos!$M:$M,$A23,Contactos!$J:$J,B$13) -> 0 | C23: =COUNTIFS(Contactos!$M:$M,$A23,Contactos!$J:$J,C$13) -> 0 | D23: =COUNTIFS(Contactos!$M:$M,$A23,Contactos!$J:$J,D$13) -> 202 | E23: =SUM(B23:D23) -> 202
A24: Fuera de foco (turismo y servicios locales) | B24: =COUNTIFS(Contactos!$M:$M,$A24,Contactos!$J:$J,B$13) -> 0 | C24: =COUNTIFS(Contactos!$M:$M,$A24,Contactos!$J:$J,C$13) -> 0 | D24: =COUNTIFS(Contactos!$M:$M,$A24,Contactos!$J:$J,D$13) -> 21 | E24: =SUM(B24:D24) -> 21
A25: Total | B25: =SUM(B14:B24) -> 108 | C25: =SUM(C14:C24) -> 95 | D25: =SUM(D14:D24) -> 223 | E25: =SUM(E14:E24) -> 426
A27: Estado (pipeline) | B27: Cantidad
A28: Prospecto | B28: =COUNTIF(Contactos!$I:$I,A28) -> 426
A29: Contactado | B29: =COUNTIF(Contactos!$I:$I,A29) -> 0
A30: Reunión | B30: =COUNTIF(Contactos!$I:$I,A30) -> 0
A31: Propuesta | B31: =COUNTIF(Contactos!$I:$I,A31) -> 0
A32: Cliente | B32: =COUNTIF(Contactos!$I:$I,A32) -> 0
A33: No interesado | B33: =COUNTIF(Contactos!$I:$I,A33) -> 0
A35: Indicadores | B35: Cantidad
A36: Registros originales | B36: 426
A37: Empresas / instituciones únicas | B37: =COUNTA(Contactos!$D$2:$D$3000) -> 426
A38: Con sede en Argentina | B38: =COUNTIF(Contactos!$E$2:$E$3000,"Argentina") -> 386
A39: Con email | B39: =COUNTIF(Contactos!$F$2:$F$3000,"?*") -> 289
A40: Con web | B40: =COUNTIF(Contactos!$S$2:$S$3000,"?*") -> 285
A41: En otros CRM | B41: =COUNTIF(Contactos!$T$2:$T$3000,"*(ID*") -> 52

Sheet Eventos
A1: Evento | B1: País | C1: Valor para SafetyMind
A2: Directorio SSO 2026 – Cero Accidentes (22.ª ed.) | B2: Perú | C2: Mapa de ~670 proveedores SST en Perú (ver CRM_Directorio_SSO_2026).
A3: ExpoMina Perú 2026 | B3: Perú | C3: Feria minera (ver CRM_ExpoMina_2026).
A4: Exponor 2026 (Antofagasta) | B4: Chile | C4: Feria minera del norte de Chile (ver CRM_Exponor_2026).
A5: AquaSur 2026 (Puerto Montt) | B5: Chile | C5: Feria acuícola (ver CRM_AquaSur_2026).
A6: FIDAE 2026 (Santiago) | B6: Chile | C6: Feria aeroespacial y de defensa (ver CRM_FIDAE_2026).
A7: Expo San Juan Minera 2026 | B7: Argentina | C7: Feria minera de San Juan (cobre y oro): operaciones y proyectos (Veladero, Vicuña, Los Azules, El Pachón, Casposo), contratistas de perforación, voladura, transporte y campamentos, y cámaras (Cámara Minera, CASEMI, AOMA). Puerta de entrada a Argentina.
