Workbook

Sheet Contactos
A1: ID | B1: Nombre | C1: Cargo | D1: Empresa | E1: País | F1: Email | G1: LinkedIn | H1: Origen | I1: Estado | J1: Prioridad | K1: Próxima acción | L1: Notas | M1: Segmento SafetyMind | N1: Stand(s) | O1: N° stands | P1: Pabellón país / zona | Q1: Web | R1: Teléfono(s) | S1: Cruce otros CRM
A2: 1 | D2: Albemarle | E2: Chile | H2: Exponor 2026 | I2: Prospecto | J2: Alta | K2: Mapear Gerente SSOMA/HSE y faenas; proponer piloto | L2: Exponor 2026. Sin contacto publicado. | M2: Minera (cliente final) | N2: Exterior B-65 | O2: 1 | S2: No
A3: 2 | D3: Antofagasta Minerals | E3: Chile | H3: Exponor 2026 | I3: Prospecto | J3: Alta | K3: Mapear Gerente SSOMA/HSE y faenas; proponer piloto | L3: Exponor 2026. Sin contacto publicado. | M3: Minera (cliente final) | N3: Exterior C-70 y 71 | O3: 1 | S3: No
A4: 3 | D4: BHP | E4: Chile | H4: Exponor 2026 | I4: Prospecto | J4: Alta | K4: Mapear Gerente SSOMA/HSE y faenas; proponer piloto | L4: Exponor 2026. Sin contacto publicado. | M4: Minera (cliente final) | N4: Exterior C-78-79-80-81 y 82 | O4: 1 | S4: No
A5: 4 | D5: Capstone Copper Mantos Blancos | E5: Chile | H5: Exponor 2026 | I5: Prospecto | J5: Alta | K5: Mapear Gerente SSOMA/HSE y faenas; proponer piloto | L5: Exponor 2026. Sin contacto publicado. | M5: Minera (cliente final) | N5: Exterior B-45 | O5: 1 | S5: No
A6: 5 | D6: Cerro Alto Minería | E6: Chile | H6: Exponor 2026 | I6: Prospecto | J6: Alta | K6: Mapear Gerente SSOMA/HSE y faenas; proponer piloto | L6: Exponor 2026. Sin contacto publicado. | M6: Minera (cliente final) | N6: Oro-1183 | O6: 1 | S6: No
A7: 6 | D7: Cía. Minera Cordillera Chile SCM | E7: Chile | H7: Exponor 2026 | I7: Prospecto | J7: Alta | K7: Mapear Gerente SSOMA/HSE y faenas; proponer piloto | L7: Exponor 2026. Sin contacto publicado. | M7: Minera (cliente final) | N7: Oro-1178 | O7: 1 | S7: No
A8: 7 | D8: Codelco | E8: Chile | H8: Exponor 2026 | I8: Prospecto | J8: Alta | K8: Mapear Gerente SSOMA/HSE y faenas; proponer piloto | L8: Exponor 2026. Sin contacto publicado. | M8: Minera (cliente final) | N8: Exterior B-52 | O8: 1 | S8: No
A9: 8 | D9: Compañía Minera CCL | E9: Chile | H9: Exponor 2026 | I9: Prospecto | J9: Alta | K9: Mapear Gerente SSOMA/HSE y faenas; proponer piloto | L9: Exponor 2026. Sin contacto publicado. | M9: Minera (cliente final) | N9: Litio-945 | O9: 1 | P9: EstaremosEnExponor | S9: No
A10: 9 | D10: Glencore | E10: Chile | H10: Exponor 2026 | I10: Prospecto | J10: Alta | K10: Mapear Gerente SSOMA/HSE y faenas; proponer piloto | L10: Exponor 2026. Sin contacto publicado. | M10: Minera (cliente final) | N10: Exterior B-37 | O10: 1 | S10: No
A11: 10 | D11: Minera El Abra | E11: Chile | H11: Exponor 2026 | I11: Prospecto | J11: Alta | K11: Mapear Gerente SSOMA/HSE y faenas; proponer piloto | L11: Exponor 2026. Sin contacto publicado. | M11: Minera (cliente final) | N11: Exterior B-51 | O11: 1 | S11: No
A12: 11 | D12: Novandina Litio | E12: Chile | H12: Exponor 2026 | I12: Prospecto | J12: Alta | K12: Mapear Gerente SSOMA/HSE y faenas; proponer piloto | L12: Exponor 2026. Sin contacto publicado. | M12: Minera (cliente final) | N12: Exterior B-36 | O12: 1 | S12: No
A13: 12 | D13: Sierra Gorda SCM | E13: Chile | H13: Exponor 2026 | I13: Prospecto | J13: Alta | K13: Mapear Gerente SSOMA/HSE y faenas; proponer piloto | L13: Exponor 2026. Sin contacto publicado. | M13: Minera (cliente final) | N13: Exterior B-39 | O13: 1 | S13: No
A14: 13 | D14: SQM | E14: Chile | H14: Exponor 2026 | I14: Prospecto | J14: Alta | K14: Mapear Gerente SSOMA/HSE y faenas; proponer piloto | L14: Exponor 2026. Sin contacto publicado. | M14: Minera (cliente final) | N14: Exterior B-36 | O14: 1 | S14: No
A15: 14 | D15: Teck Resourses Chile | E15: Chile | H15: Exponor 2026 | I15: Prospecto | J15: Alta | K15: Mapear Gerente SSOMA/HSE y faenas; proponer piloto | L15: Exponor 2026. Sin contacto publicado. | M15: Minera (cliente final) | N15: Exterior B-053A | O15: 1 | S15: No
A16: 15 | D16: All Drill Chile SpA | E16: Chile | H16: Exponor 2026 | I16: Prospecto | J16: Alta | K16: Identificar Gerente HSE/SSOMA en LinkedIn y proponer demo | L16: Exponor 2026. Sin contacto publicado. | M16: Cliente potencial – contratista / operación de alto riesgo | N16: Oro-1099 | O16: 1 | S16: No
A17: 16 | D17: Alo Rental | E17: Chile | H17: Exponor 2026 | I17: Prospecto | J17: Alta | K17: Identificar Gerente HSE/SSOMA en LinkedIn y proponer demo | L17: Exponor 2026. Sin contacto publicado. | M17: Cliente potencial – contratista / operación de alto riesgo | N17: Cobalto-1370 | O17: 1 | S17: No
A18: 17 | D18: Andamios At-Pac | E18: Chile | H18: Exponor 2026 | I18: Prospecto | J18: Alta | K18: Identificar Gerente HSE/SSOMA en LinkedIn y proponer demo | L18: Exponor 2026. Sin contacto publicado. | M18: Cliente potencial – contratista / operación de alto riesgo | N18: Exterior E-140 | O18: 1 | S18: No
A19: 18 | D19: BCM Servicios Mineros | E19: Chile | H19: Exponor 2026 | I19: Prospecto | J19: Alta | K19: Identificar Gerente HSE/SSOMA en LinkedIn y proponer demo | L19: Exponor 2026. Sin contacto publicado. | M19: Cliente potencial – contratista / operación de alto riesgo | N19: Yodo-706 | O19: 1 | S19: No
A20: 19 | D20: Boga Andamios y Servicios SpA | E20: Chile | H20: Exponor 2026 | I20: Prospecto | J20: Alta | K20: Identificar Gerente HSE/SSOMA en LinkedIn y proponer demo | L20: Exponor 2026. Sin contacto publicado. | M20: Cliente potencial – contratista / operación de alto riesgo | N20: Oro-1137 | O20: 1 | S20: No
A21: 20 | D21: Bus 4x4 Group | E21: Australia | H21: Exponor 2026 | I21: Prospecto | J21: Alta | K21: Identificar Gerente HSE/SSOMA en LinkedIn y proponer demo | L21: Exponor 2026. Sin contacto publicado. | M21: Cliente potencial – contratista / operación de alto riesgo | N21: Yodo-666 | O21: 1 | P21: Australia | S21: No
A22: 21 | D22: Buses Hualpén | E22: Chile | H22: Exponor 2026 | I22: Prospecto | J22: Alta | K22: Identificar Gerente HSE/SSOMA en LinkedIn y proponer demo | L22: Exponor 2026. Sin contacto publicado. | M22: Cliente potencial – contratista / operación de alto riesgo | N22: Molibdeno-1275 | O22: 1 | S22: No
A23: 22 | D23: C&V International | E23: Perú | F23: ventas@cvinternational.com.pe | H23: Exponor 2026 | I23: Prospecto | J23: Alta | K23: Identificar Gerente HSE/SSOMA en LinkedIn y proponer demo | L23: Exponor 2026. También en CRM Directorio SSO 2026 (ID 18). | M23: Cliente potencial – contratista / operación de alto riesgo | N23: Plata-564A | O23: 1 | P23: Perú | Q23: www.cvinternational.com.pe | R23: 5156714 | S23: Directorio SSO (ID 18)
A24: 23 | D24: Cas Servicios Industriales | E24: Chile | H24: Exponor 2026 | I24: Prospecto | J24: Alta | K24: Identificar Gerente HSE/SSOMA en LinkedIn y proponer demo | L24: Exponor 2026. Sin contacto publicado. | M24: Cliente potencial – contratista / operación de alto riesgo | N24: Litio-963 | O24: 1 | S24: No
A25: 24 | D25: Cemtec - Latam Mining Services | E25: Chile | H25: Exponor 2026 | I25: Prospecto | J25: Alta | K25: Identificar Gerente HSE/SSOMA en LinkedIn y proponer demo | L25: Exponor 2026. Sin contacto publicado. | M25: Cliente potencial – contratista / operación de alto riesgo | N25: Cobalto-1404 | O25: 1 | S25: No
A26: 25 | D26: Christensen | E26: Chile | H26: Exponor 2026 | I26: Prospecto | J26: Alta | K26: Identificar Gerente HSE/SSOMA en LinkedIn y proponer demo | L26: Exponor 2026. Sin contacto publicado. | M26: Cliente potencial – contratista / operación de alto riesgo | N26: Exterior D-109 | O26: 1 | S26: No
A27: 26 | D27: Complejo Portuario Mejillones | E27: Chile | H27: Exponor 2026 | I27: Prospecto | J27: Alta | K27: Identificar Gerente HSE/SSOMA en LinkedIn y proponer demo | L27: Exponor 2026. Sin contacto publicado. | M27: Cliente potencial – contratista / operación de alto riesgo | N27: Yodo-799 | O27: 1 | S27: No
A28: 27 | D28: Conciencia Logística | E28: Chile | H28: Exponor 2026 | I28: Prospecto | J28: Alta | K28: Identificar Gerente HSE/SSOMA en LinkedIn y proponer demo | L28: Exponor 2026. Sin contacto publicado. | M28: Cliente potencial – contratista / operación de alto riesgo | N28: Molibdeno-1238 | O28: 1 | S28: No
A29: 28 | D29: Confipetrol Chile SpA | E29: Chile | H29: Exponor 2026 | I29: Prospecto | J29: Alta | K29: Identificar Gerente HSE/SSOMA en LinkedIn y proponer demo | L29: Exponor 2026. Sin contacto publicado. | M29: Cliente potencial – contratista / operación de alto riesgo | N29: Hierro-1478 | O29: 1 | S29: No
A30: 29 | D30: Constructora Baical Ltda. - Baical Rental | E30: Chile | H30: Exponor 2026 | I30: Prospecto | J30: Alta | K30: Identificar Gerente HSE/SSOMA en LinkedIn y proponer demo | L30: Exponor 2026. Sin contacto publicado. | M30: Cliente potencial – contratista / operación de alto riesgo | N30: Hierro-1488 | O30: 1 | S30: No
A31: 30 | D31: Constructora El Sauce S.A | E31: Chile | H31: Exponor 2026 | I31: Prospecto | J31: Alta | K31: Identificar Gerente HSE/SSOMA en LinkedIn y proponer demo | L31: Exponor 2026. Sin contacto publicado. | M31: Cliente potencial – contratista / operación de alto riesgo | N31: Exterior C-90 | O31: 1 | S31: No
A32: 31 | D32: Constructora VIC | E32: Chile | H32: Exponor 2026 | I32: Prospecto | J32: Alta | K32: Identificar Gerente HSE/SSOMA en LinkedIn y proponer demo | L32: Exponor 2026. Sin contacto publicado. | M32: Cliente potencial – contratista / operación de alto riesgo | N32: Molibdeno-1220 | O32: 1 | S32: No
A33: 32 | D33: Demolition Plus | E33: Chile | H33: Exponor 2026 | I33: Prospecto | J33: Alta | K33: Identificar Gerente HSE/SSOMA en LinkedIn y proponer demo | L33: Exponor 2026. Sin contacto publicado. | M33: Cliente potencial – contratista / operación de alto riesgo | N33: Litio-1005A | O33: 1 | S33: No
A34: 33 | D34: DMI Projects Global Logistics Ltda | E34: Chile | H34: Exponor 2026 | I34: Prospecto | J34: Alta | K34: Identificar Gerente HSE/SSOMA en LinkedIn y proponer demo | L34: Exponor 2026. Sin contacto publicado. | M34: Cliente potencial – contratista / operación de alto riesgo | N34: Yodo-738 | O34: 1 | S34: No
A35: 34 | D35: DyC Servicios Generales | E35: Chile | H35: Exponor 2026 | I35: Prospecto | J35: Alta | K35: Identificar Gerente HSE/SSOMA en LinkedIn y proponer demo | L35: Exponor 2026. Sin contacto publicado. | M35: Cliente potencial – contratista / operación de alto riesgo | N35: Hierro-1497 | O35: 1 | S35: No
... A39: 38 | D39: Enaex | E39: Chile | H39: Exponor 2026 | I39: Prospecto | J39: Alta | K39: Identificar Gerente HSE/SSOMA en LinkedIn y proponer demo | L39: Exponor 2026. Sin contacto publicado. | M39: Cliente potencial – contratista / operación de alto riesgo | N39: Cobre-181-182-220 y 221 | O39: 1 | S39: No
A40: 39 | D40: Famesa Explosivos Chile | E40: Perú | F40: ventas@famesa.com.pe | H40: Exponor 2026 | I40: Prospecto | J40: Alta | K40: Identificar Gerente HSE/SSOMA en LinkedIn y proponer demo | L40: Exponor 2026. También en CRM Directorio SSO 2026 (ID 60). También expone en ExpoMina 2026 (ID 19). | M40: Cliente potencial – contratista / operación de alto riesgo | N40: Plata-571 y 573 | O40: 1 | P40: Perú | Q40: www.famesa.com.pe | R40: 6139800 | S40: Directorio SSO (ID 60); ExpoMina (ID 19)
A41: 40 | D41: FCAB | E41: Chile | H41: Exponor 2026 | I41: Prospecto | J41: Alta | K41: Identificar Gerente HSE/SSOMA en LinkedIn y proponer demo | L41: Exponor 2026. Sin contacto publicado. | M41: Cliente potencial – contratista / operación de alto riesgo | N41: Exterior B-54 | O41: 1 | S41: No
A42: 41 | D42: Ferronor S.A | E42: Chile | H42: Exponor 2026 | I42: Prospecto | J42: Alta | K42: Identificar Gerente HSE/SSOMA en LinkedIn y proponer demo | L42: Exponor 2026. Sin contacto publicado. | M42: Cliente potencial – contratista / operación de alto riesgo | N42: Hierro-1452 | O42: 1 | S42: No
A43: 42 | D43: FG Logistica SpA | E43: Chile | H43: Exponor 2026 | I43: Prospecto | J43: Alta | K43: Identificar Gerente HSE/SSOMA en LinkedIn y proponer demo | L43: Exponor 2026. Sin contacto publicado. | M43: Cliente potencial – contratista / operación de alto riesgo | N43: Cobalto-1393 | O43: 1 | S43: No
...

Sheet Oportunidades
A1: ID oportunidad | B1: ID contacto | C1: Empresa | D1: Necesidad | E1: Solución propuesta | F1: Etapa | G1: Valor estimado | H1: Probabilidad | I1: Próxima acción | J1: Fecha

Sheet Resumen
A1: Evento/Fuente | B1: País | C1: Cantidad
A2: Exponor 2026 | B2: Chile | C2: =COUNTIFS(Contactos!$H:$H,$A2,Contactos!$E:$E,$B2) -> 850
A3: Exponor 2026 | B3: China | C3: =COUNTIFS(Contactos!$H:$H,$A3,Contactos!$E:$E,$B3) -> 180
A4: Exponor 2026 | B4: Alemania | C4: =COUNTIFS(Contactos!$H:$H,$A4,Contactos!$E:$E,$B4) -> 66
A5: Exponor 2026 | B5: Estados Unidos | C5: =COUNTIFS(Contactos!$H:$H,$A5,Contactos!$E:$E,$B5) -> 50
A6: Exponor 2026 | B6: Canadá | C6: =COUNTIFS(Contactos!$H:$H,$A6,Contactos!$E:$E,$B6) -> 38
A7: Exponor 2026 | B7: Perú | C7: =COUNTIFS(Contactos!$H:$H,$A7,Contactos!$E:$E,$B7) -> 29
A8: Exponor 2026 | B8: Brasil | C8: =COUNTIFS(Contactos!$H:$H,$A8,Contactos!$E:$E,$B8) -> 20
A9: Exponor 2026 | B9: Australia | C9: =COUNTIFS(Contactos!$H:$H,$A9,Contactos!$E:$E,$B9) -> 18
A10: Exponor 2026 | B10: Francia | C10: =COUNTIFS(Contactos!$H:$H,$A10,Contactos!$E:$E,$B10) -> 17
A11: Exponor 2026 | B11: Italia | C11: =COUNTIFS(Contactos!$H:$H,$A11,Contactos!$E:$E,$B11) -> 17
A12: Exponor 2026 | B12: España | C12: =COUNTIFS(Contactos!$H:$H,$A12,Contactos!$E:$E,$B12) -> 13
A13: Exponor 2026 | B13: Argentina | C13: =COUNTIFS(Contactos!$H:$H,$A13,Contactos!$E:$E,$B13) -> 12
... A25: Exponor 2026 | B25: Hungría | C25: =COUNTIFS(Contactos!$H:$H,$A25,Contactos!$E:$E,$B25) -> 1
A26: Total | C26: =SUM(C2:C25) -> 1375
A28: Segmento SafetyMind | B28: Alta | C28: Media | D28: Baja | E28: Total
A29: Minera (cliente final) | B29: =COUNTIFS(Contactos!$M:$M,$A29,Contactos!$J:$J,B$28) -> 14 | C29: =COUNTIFS(Contactos!$M:$M,$A29,Contactos!$J:$J,C$28) -> 0 | D29: =COUNTIFS(Contactos!$M:$M,$A29,Contactos!$J:$J,D$28) -> 0 | E29: =SUM(B29:D29) -> 14
A30: Cliente potencial – contratista / operación de alto riesgo | B30: =COUNTIFS(Contactos!$M:$M,$A30,Contactos!$J:$J,B$28) -> 72 | C30: =COUNTIFS(Contactos!$M:$M,$A30,Contactos!$J:$J,C$28) -> 0 | D30: =COUNTIFS(Contactos!$M:$M,$A30,Contactos!$J:$J,D$28) -> 0 | E30: =SUM(B30:D30) -> 72
A31: Partner tecnológico / competidor | B31: =COUNTIFS(Contactos!$M:$M,$A31,Contactos!$J:$J,B$28) -> 90 | C31: =COUNTIFS(Contactos!$M:$M,$A31,Contactos!$J:$J,C$28) -> 0 | D31: =COUNTIFS(Contactos!$M:$M,$A31,Contactos!$J:$J,D$28) -> 0 | E31: =SUM(B31:D31) -> 90
A32: Canal / aliado – consultoría SST | B32: =COUNTIFS(Contactos!$M:$M,$A32,Contactos!$J:$J,B$28) -> 38 | C32: =COUNTIFS(Contactos!$M:$M,$A32,Contactos!$J:$J,C$28) -> 0 | D32: =COUNTIFS(Contactos!$M:$M,$A32,Contactos!$J:$J,D$28) -> 0 | E32: =SUM(B32:D32) -> 38
A33: Partner OEM – equipos mineros | B33: =COUNTIFS(Contactos!$M:$M,$A33,Contactos!$J:$J,B$28) -> 0 | C33: =COUNTIFS(Contactos!$M:$M,$A33,Contactos!$J:$J,C$28) -> 30 | D33: =COUNTIFS(Contactos!$M:$M,$A33,Contactos!$J:$J,D$28) -> 0 | E33: =SUM(B33:D33) -> 30
A34: Canal / distribuidor EPP | B34: =COUNTIFS(Contactos!$M:$M,$A34,Contactos!$J:$J,B$28) -> 0 | C34: =COUNTIFS(Contactos!$M:$M,$A34,Contactos!$J:$J,C$28) -> 17 | D34: =COUNTIFS(Contactos!$M:$M,$A34,Contactos!$J:$J,D$28) -> 0 | E34: =SUM(B34:D34) -> 17
A35: Aliado complementario – seguridad | B35: =COUNTIFS(Contactos!$M:$M,$A35,Contactos!$J:$J,B$28) -> 0 | C35: =COUNTIFS(Contactos!$M:$M,$A35,Contactos!$J:$J,C$28) -> 21 | D35: =COUNTIFS(Contactos!$M:$M,$A35,Contactos!$J:$J,D$28) -> 0 | E35: =SUM(B35:D35) -> 21
A36: Aliado complementario – salud | B36: =COUNTIFS(Contactos!$M:$M,$A36,Contactos!$J:$J,B$28) -> 0 | C36: =COUNTIFS(Contactos!$M:$M,$A36,Contactos!$J:$J,C$28) -> 7 | D36: =COUNTIFS(Contactos!$M:$M,$A36,Contactos!$J:$J,D$28) -> 0 | E36: =SUM(B36:D36) -> 7
A37: Institución / gremio / pabellón país | B37: =COUNTIFS(Contactos!$M:$M,$A37,Contactos!$J:$J,B$28) -> 0 | C37: =COUNTIFS(Contactos!$M:$M,$A37,Contactos!$J:$J,C$28) -> 59 | D37: =COUNTIFS(Contactos!$M:$M,$A37,Contactos!$J:$J,D$28) -> 0 | E37: =SUM(B37:D37) -> 59
A38: Proveedor industrial (equipos/insumos) | B38: =COUNTIFS(Contactos!$M:$M,$A38,Contactos!$J:$J,B$28) -> 0 | C38: =COUNTIFS(Contactos!$M:$M,$A38,Contactos!$J:$J,C$28) -> 0 | D38: =COUNTIFS(Contactos!$M:$M,$A38,Contactos!$J:$J,D$28) -> 1027 | E38: =SUM(B38:D38) -> 1027
A39: Total | B39: =SUM(B29:B38) -> 214 | C39: =SUM(C29:C38) -> 134 | D39: =SUM(D29:D38) -> 1027 | E39: =SUM(E29:E38) -> 1375
A41: Estado (pipeline) | B41: Cantidad
A42: Prospecto | B42: =COUNTIF(Contactos!$I:$I,A42) -> 1375
A43: Contactado | B43: =COUNTIF(Contactos!$I:$I,A43) -> 0
A44: Reunión | B44: =COUNTIF(Contactos!$I:$I,A44) -> 0
A45: Propuesta | B45: =COUNTIF(Contactos!$I:$I,A45) -> 0
A46: Cliente | B46: =COUNTIF(Contactos!$I:$I,A46) -> 0
A47: No interesado | B47: =COUNTIF(Contactos!$I:$I,A47) -> 0
A49: Indicadores | B49: Cantidad
A50: Registros originales (stands) | B50: 1382
A51: Empresas únicas | B51: =COUNTA(Contactos!$D$2:$D$3000) -> 1375
A52: También en ExpoMina 2026 | B52: =COUNTIF(Contactos!$S$2:$S$3000,"*ExpoMina*") -> 96
A53: También en Directorio SSO | B53: =COUNTIF(Contactos!$S$2:$S$3000,"*Directorio*") -> 21
A54: Startups (Lanza tu Innovación) | B54: =COUNTIF(Contactos!$P$2:$P$3000,"*Lanza tu Innovación*") -> 32
...

Sheet Eventos
A1: Evento | B1: País | C1: Valor para SafetyMind
A2: Directorio SSO 2026 – Cero Accidentes (22.ª ed.) | B2: Perú | C2: Mapa de ~670 proveedores SST en Perú (ver CRM_Directorio_SSO_2026).
A3: ExpoMina Perú 2026 | B3: Perú | C3: Feria minera: mineras, contratistas, OEM, tecnología y proveedores (ver CRM_ExpoMina_2026).
A4: Exponor 2026 (Antofagasta) | B4: Chile | C4: Principal feria minera del norte de Chile: mineras (Codelco, BHP, AMSA, SQM, Albemarle), contratistas, OEM, startups y pabellones país; base para reuniones en stand y prospección post-evento.
