Workbook

Sheet Contactos
A1: ID | B1: Nombre | C1: Cargo | D1: Empresa | E1: País | F1: Email | G1: LinkedIn | H1: Origen | I1: Estado | J1: Prioridad | K1: Próxima acción | L1: Notas | M1: Segmento SafetyMind | N1: Stand(s) | O1: N° stands | P1: Web | Q1: Teléfono(s) | R1: Dirección | S1: En Directorio SSO
A2: 1 | D2: ACTIVOS MINEROS S.A.C. | E2: Perú | H2: ExpoMina 2026 | I2: Prospecto | J2: Alta | K2: Mapear Gerente SSOMA/HSE y unidades mineras; proponer piloto | L2: ExpoMina 2026. Varios stands (mayor inversión). Sin contacto publicado. | M2: Minera (cliente final) | N2: E-285, E-287 | O2: 2 | P2: amsac.pe | S2: No
A3: 2 | D3: ANGLO AMERICAN QUELLAVECO S.A. | E3: Perú | H3: ExpoMina 2026 | I3: Prospecto | J3: Alta | K3: Mapear Gerente SSOMA/HSE y unidades mineras; proponer piloto | L3: ExpoMina 2026. Sin contacto publicado. | M3: Minera (cliente final) | N3: A-078 | O3: 1 | P3: https://peru.angloamerican.com/ | S3: No
A4: 3 | D4: SOCIEDAD MINERA CERRO VERDE S.A.A. | E4: Perú | H4: ExpoMina 2026 | I4: Prospecto | J4: Alta | K4: Mapear Gerente SSOMA/HSE y unidades mineras; proponer piloto | L4: ExpoMina 2026. Sin contacto publicado. | M4: Minera (cliente final) | N4: A-175 | O4: 1 | P4: www.cerroverde.pe | S4: No
A5: 4 | D5: EQUANS SERVICES PERÚ S.A. | E5: Perú | F5: contacto.espe@equans.com | H5: ExpoMina 2026 | I5: Prospecto | J5: Alta | K5: Identificar Gerente SSOMA/HSE en LinkedIn y proponer demo | L5: ExpoMina 2026. Varios stands (mayor inversión). También en CRM Directorio SSO 2026 (ID 52). | M5: Cliente potencial – contratista / operación de alto riesgo | N5: A-297, A-298, A-301, A-302 | O5: 4 | P5: www.equans.pe | R5: Av. Paseo de la República 3617 San Isidro - Lima | S5: Sí
A6: 5 | D6: NEUMA PERÚ CONTRATISTAS GENERALES S.A.C. | E6: Perú | F6: ventas@neumaperu.com.pe | H6: ExpoMina 2026 | I6: Prospecto | J6: Alta | K6: Identificar Gerente SSOMA/HSE en LinkedIn y proponer demo | L6: ExpoMina 2026. Varios stands (mayor inversión). También en CRM Directorio SSO 2026 (ID 105). | M6: Cliente potencial – contratista / operación de alto riesgo | N6: F-084, F-085, F-086 | O6: 3 | P6: www.neumaperu.com.pe | Q6: 6180300 / 971523609 | R6: Av. Nicolás Ayllón 2142 - Ate Vitarte Lima | S6: Sí
A7: 6 | D7: AOM SUMINISTROS INDUSTRIALES S.A.C | E7: Perú | F7: info@aom.pe | H7: ExpoMina 2026 | I7: Prospecto | J7: Alta | K7: Identificar Gerente SSOMA/HSE en LinkedIn y proponer demo | L7: ExpoMina 2026. Varios stands (mayor inversión). También en CRM Directorio SSO 2026 (ID 10). | M7: Cliente potencial – contratista / operación de alto riesgo | N7: A-161, A-410 | O7: 2 | P7: www.aom.com.pe | R7: Jr. Cruz del Sur 140 Of.1503, Santiago de Surco - Lima | S7: Sí
A8: 7 | D8: CONSORCIO MINERIA SUBTERRANEA S.A.C. COMISUB S.A.C. | E8: Perú | H8: ExpoMina 2026 | I8: Prospecto | J8: Alta | K8: Identificar Gerente SSOMA/HSE en LinkedIn y proponer demo | L8: ExpoMina 2026. Varios stands (mayor inversión). Sin contacto publicado. | M8: Cliente potencial – contratista / operación de alto riesgo | N8: A-075, A-076 | O8: 2 | P8: https://comisub.com/ | S8: No
A9: 8 | D9: MAQUINAS Y MONTAJES S.A | E9: Perú (por validar) | H9: ExpoMina 2026 | I9: Prospecto | J9: Alta | K9: Identificar Gerente SSOMA/HSE en LinkedIn y proponer demo | L9: ExpoMina 2026. Varios stands (mayor inversión). País inferido; validar. Sin contacto publicado. | M9: Cliente potencial – contratista / operación de alto riesgo | N9: A-079, A-080 | O9: 2 | P9: www.maquinasymontajes.com | S9: No
A10: 9 | D10: TUMI CONTRATISTAS MINEROS S.A.C | E10: Perú | F10: sales.ventas@tumirb.com | H10: ExpoMina 2026 | I10: Prospecto | J10: Alta | K10: Identificar Gerente SSOMA/HSE en LinkedIn y proponer demo | L10: ExpoMina 2026. Varios stands (mayor inversión). También en CRM Directorio SSO 2026 (ID 163). | M10: Cliente potencial – contratista / operación de alto riesgo | N10: E-205A, E-205B | O10: 2 | P10: https://tumirb.com | Q10: 982483947 | R10: Unidad Inmobiliaria Nº1 con frente Av. Paul Poblet s/n, Lurín - Lima | S10: Sí
A11: 10 | D11: AHORRO DE ENERGÍA Y MANTENIMIENTO INDUSTRIAL | E11: Perú | F11: ademinsa@ademinsa.com | H11: ExpoMina 2026 | I11: Prospecto | J11: Alta | K11: Identificar Gerente SSOMA/HSE en LinkedIn y proponer demo | L11: ExpoMina 2026. También en CRM Directorio SSO 2026 (ID 2). | M11: Cliente potencial – contratista / operación de alto riesgo | N11: E-359 | O11: 1 | P11: https://ademinsa.com/ | Q11: 2750082 | R11: Cl. Cerro Azul 479 Of. 101A Urb. San Ignacio de Loyola Santiago de Surco - Lima | S11: Sí
A12: 11 | D12: ARMOTEC CONTRATISTAS GENERALES S.A.C. - ARMOTEC S.A.C. | E12: Perú | H12: ExpoMina 2026 | I12: Prospecto | J12: Alta | K12: Identificar Gerente SSOMA/HSE en LinkedIn y proponer demo | L12: ExpoMina 2026. Sin contacto publicado. | M12: Cliente potencial – contratista / operación de alto riesgo | N12: B-211 | O12: 1 | P12: http://armotec.pe | S12: No
A13: 12 | D13: COMERCIAL DRILLING SERVICES S.A.C.- CODRISE S.A.C. | E13: Perú | H13: ExpoMina 2026 | I13: Prospecto | J13: Alta | K13: Identificar Gerente SSOMA/HSE en LinkedIn y proponer demo | L13: ExpoMina 2026. Sin contacto publicado. | M13: Cliente potencial – contratista / operación de alto riesgo | N13: B-094 | O13: 1 | P13: https://codrise.com/ | S13: No
A14: 13 | D14: CONSORCIO MINING CONSTRUCCION & SOLUTION S.A.C. - CONSORCIO MICONSOL S.A.C. | E14: Perú | H14: ExpoMina 2026 | I14: Prospecto | J14: Alta | K14: Identificar Gerente SSOMA/HSE en LinkedIn y proponer demo | L14: ExpoMina 2026. Sin contacto publicado. | M14: Cliente potencial – contratista / operación de alto riesgo | N14: E-001 | O14: 1 | P14: https://essotech.pe/ | S14: No
A15: 14 | D15: CONSTRUCCIONES ELECTROMECANICAS DELCROSA S.A. O DELCROSA S.A. | E15: Perú | H15: ExpoMina 2026 | I15: Prospecto | J15: Alta | K15: Identificar Gerente SSOMA/HSE en LinkedIn y proponer demo | L15: ExpoMina 2026. Sin contacto publicado. | M15: Cliente potencial – contratista / operación de alto riesgo | N15: E-173 | O15: 1 | P15: https://www.delcrosa.com.pe/es | S15: No
A16: 15 | D16: CONSTRUCTORA GALAXIA S.A.C. | E16: Perú | H16: ExpoMina 2026 | I16: Prospecto | J16: Alta | K16: Identificar Gerente SSOMA/HSE en LinkedIn y proponer demo | L16: ExpoMina 2026. Sin contacto publicado. | M16: Cliente potencial – contratista / operación de alto riesgo | N16: A-390 | O16: 1 | S16: No
A17: 16 | D17: CONSULTORES EN INGENIERIA GEOTECNICA ESTRUCTURAL Y CONSTRUCCION S.A.C. - COINGEC S.A.C. | E17: Perú | H17: ExpoMina 2026 | I17: Prospecto | J17: Alta | K17: Identificar Gerente SSOMA/HSE en LinkedIn y proponer demo | L17: ExpoMina 2026. Sin contacto publicado. | M17: Cliente potencial – contratista / operación de alto riesgo | N17: A-199 | O17: 1 | P17: https://coingec.com/ | S17: No
A18: 17 | D18: EMPRESA DE SERVICIOS CONSTRUCCION CONSULTORIA | E18: Por validar | H18: ExpoMina 2026 | I18: Prospecto | J18: Alta | K18: Identificar Gerente SSOMA/HSE en LinkedIn y proponer demo | L18: ExpoMina 2026. País inferido; validar. Sin contacto publicado. | M18: Cliente potencial – contratista / operación de alto riesgo | N18: E-334 | O18: 1 | S18: No
A19: 18 | D19: FABRICACIONES ANDINAS S.A.C. | E19: Perú | H19: ExpoMina 2026 | I19: Prospecto | J19: Alta | K19: Identificar Gerente SSOMA/HSE en LinkedIn y proponer demo | L19: ExpoMina 2026. Sin contacto publicado. | M19: Cliente potencial – contratista / operación de alto riesgo | N19: A-261 | O19: 1 | P19: en construccion | S19: No
A20: 19 | D20: FAMESA EXPLOSIVOS S.A.C. | E20: Perú | F20: ventas@famesa.com.pe | H20: ExpoMina 2026 | I20: Prospecto | J20: Alta | K20: Identificar Gerente SSOMA/HSE en LinkedIn y proponer demo | L20: ExpoMina 2026. También en CRM Directorio SSO 2026 (ID 60). | M20: Cliente potencial – contratista / operación de alto riesgo | N20: E-016 | O20: 1 | P20: www.famesaexplosivos.com | Q20: 6139800 | R20: Panamericana Norte km 28 Puente Piedra - Lima | S20: Sí
A21: 20 | D21: GINSUMIL CORPORATION S.A.C. | E21: Perú | F21: ventas@ginsumilcorp.com | H21: ExpoMina 2026 | I21: Prospecto | J21: Alta | K21: Identificar Gerente SSOMA/HSE en LinkedIn y proponer demo | L21: ExpoMina 2026. También en CRM Directorio SSO 2026 (ID 70). | M21: Cliente potencial – contratista / operación de alto riesgo | N21: B-263 | O21: 1 | P21: https://ginsumilcorp.com/ | Q21: 993022915 | R21: Av. Mariano Pastor Sevilla Mz.D Lt.40 Sector 5 San Juan de Miraflores - Lima | S21: Sí
A22: 21 | D22: GS METAL DRILLING S.A.C. | E22: Perú | H22: ExpoMina 2026 | I22: Prospecto | J22: Alta | K22: Identificar Gerente SSOMA/HSE en LinkedIn y proponer demo | L22: ExpoMina 2026. Sin contacto publicado. | M22: Cliente potencial – contratista / operación de alto riesgo | N22: B-091 | O22: 1 | P22: www.gsdrilling.pe | S22: No
A23: 22 | D23: INGENIERÍA Y CONSTRUCCIÓN SIGDO KOPPERS EQUIPOS Y SERVICIOS S.A.C. - ICSK EQUIPOS Y SERVICIOS S.A.C. | E23: Perú | H23: ExpoMina 2026 | I23: Prospecto | J23: Alta | K23: Identificar Gerente SSOMA/HSE en LinkedIn y proponer demo | L23: ExpoMina 2026. Sin contacto publicado. | M23: Cliente potencial – contratista / operación de alto riesgo | N23: B-267 | O23: 1 | P23: www.skdeysu.com | S23: No
A24: 23 | D24: JMF INGENIERIA & CONSTRUCCION SAC | E24: Perú | H24: ExpoMina 2026 | I24: Prospecto | J24: Alta | K24: Identificar Gerente SSOMA/HSE en LinkedIn y proponer demo | L24: ExpoMina 2026. Sin contacto publicado. | M24: Cliente potencial – contratista / operación de alto riesgo | N24: E-275 | O24: 1 | P24: https://www.jmf.com.pe/ | S24: No
A25: 24 | D25: MINERA DRILLING S.R.L. | E25: Perú | H25: ExpoMina 2026 | I25: Prospecto | J25: Alta | K25: Identificar Gerente SSOMA/HSE en LinkedIn y proponer demo | L25: ExpoMina 2026. Sin contacto publicado. | M25: Cliente potencial – contratista / operación de alto riesgo | N25: A-192 | O25: 1 | P25: www.mineradrilling.com | S25: No
A26: 25 | D26: MINTECH MINING TECHNOLOGY E.I.R.L. | E26: Perú | F26: info@mintech.com.pe | H26: ExpoMina 2026 | I26: Prospecto | J26: Alta | K26: Identificar Gerente SSOMA/HSE en LinkedIn y proponer demo | L26: ExpoMina 2026. También en CRM Directorio SSO 2026 (ID 99). | M26: Cliente potencial – contratista / operación de alto riesgo | N26: E-226 | O26: 1 | P26: www.mintech.com.pe | Q26: 2766979 / 6228124 | R26: Av. Los Pinos Mz.W Lt.2 Asociación Chillón Puente Piedra - Lima | S26: Sí
A27: 26 | D27: NEXTECH CONSTRUCCION MODULAR S.A.C. | E27: Perú | H27: ExpoMina 2026 | I27: Prospecto | J27: Alta | K27: Identificar Gerente SSOMA/HSE en LinkedIn y proponer demo | L27: ExpoMina 2026. Sin contacto publicado. | M27: Cliente potencial – contratista / operación de alto riesgo | N27: E-183 | O27: 1 | P27: https://nextechmodular.com/ | S27: No
A28: 27 | D28: OVERPRIME MANUFACTURING S.A.C. | E28: Perú | H28: ExpoMina 2026 | I28: Prospecto | J28: Alta | K28: Identificar Gerente SSOMA/HSE en LinkedIn y proponer demo | L28: ExpoMina 2026. También en CRM Directorio SSO 2026 (ID 111). | M28: Cliente potencial – contratista / operación de alto riesgo | N28: E-013 | O28: 1 | P28: https://overprimegroup.com/ | Q28: 5187100 / 994660177 | R28: Av. Alameda Sur 216 Urb. Villa Marina Chorrillos - Lima | S28: Sí
A29: 28 | D29: PENTATECH CONSTRUCCION S.A.C. | E29: Perú | H29: ExpoMina 2026 | I29: Prospecto | J29: Alta | K29: Identificar Gerente SSOMA/HSE en LinkedIn y proponer demo | L29: ExpoMina 2026. Sin contacto publicado. | M29: Cliente potencial – contratista / operación de alto riesgo | N29: B-242A | O29: 1 | P29: www.pentatechsac.com | S29: No
A30: 29 | D30: PEVOEX CONTRATISTAS S.A.C. | E30: Perú | F30: presupuestos@pevoex.com.pe | H30: ExpoMina 2026 | I30: Prospecto | J30: Alta | K30: Identificar Gerente SSOMA/HSE en LinkedIn y proponer demo | L30: ExpoMina 2026. También en CRM Directorio SSO 2026 (ID 113). | M30: Cliente potencial – contratista / operación de alto riesgo | N30: B-023 | O30: 1 | P30: pevoex.com | Q30: 6832277 / 989262241 | R30: Av. Circunvalación del Club Golf Los Incas 154 Of. 404 Santiago de Surco - Lima | S30: Sí
A31: 30 | D31: PROYECTOS EJECUCION Y MONTAJES INDST.SA | E31: Perú | H31: ExpoMina 2026 | I31: Prospecto | J31: Alta | K31: Identificar Gerente SSOMA/HSE en LinkedIn y proponer demo | L31: ExpoMina 2026. Sin contacto publicado. | M31: Cliente potencial – contratista / operación de alto riesgo | N31: E-368 | O31: 1 | P31: www.proemisa.pe | S31: No
A32: 31 | D32: RCP INGENIEROS CONSULTORES Y CONTRATISTAS DE SERVICIOS ESPECIALIZADOS E.I.R.L. | E32: Perú | H32: ExpoMina 2026 | I32: Prospecto | J32: Alta | K32: Identificar Gerente SSOMA/HSE en LinkedIn y proponer demo | L32: ExpoMina 2026. Sin contacto publicado. | M32: Cliente potencial – contratista / operación de alto riesgo | N32: E-148D | O32: 1 | P32: www.geodrone.com.pe | S32: No
A33: 32 | D33: REPRESENTACIONES PERUVIAN TRADING S.A. | E33: Perú | F33: ventas@rptsa.com.pe | H33: ExpoMina 2026 | I33: Prospecto | J33: Alta | K33: Identificar Gerente SSOMA/HSE en LinkedIn y proponer demo | L33: ExpoMina 2026. También en CRM Directorio SSO 2026 (ID 123). | M33: Cliente potencial – contratista / operación de alto riesgo | N33: A-350 | O33: 1 | P33: https://rptsa.com.pe/ | Q33: 4428559 | R33: Pje. Los Jilgueros 108 Urb. Limatambo Surquillo - Lima | S33: Sí
A34: 33 | D34: ROBOCON SERVICIOS S.A.C. | E34: Perú | H34: ExpoMina 2026 | I34: Prospecto | J34: Alta | K34: Identificar Gerente SSOMA/HSE en LinkedIn y proponer demo | L34: ExpoMina 2026. Sin contacto publicado. | M34: Cliente potencial – contratista / operación de alto riesgo | N34: A-010 | O34: 1 | P34: https://robocon.pe/ | S34: No
A35: 34 | D35: ROEDA S.A | E35: Perú | F35: roeda@roeda.com.pe | H35: ExpoMina 2026 | I35: Prospecto | J35: Alta | K35: Identificar Gerente SSOMA/HSE en LinkedIn y proponer demo | L35: ExpoMina 2026. También en CRM Directorio SSO 2026 (ID 127). | M35: Cliente potencial – contratista / operación de alto riesgo | N35: A-259 | O35: 1 | P35: www.roeda.com.pe | Q35: 3151400 / 997567133 | R35: Jr. Tarma 272- Cercado de Lima - Lima | S35: Sí
A36: 35 | D36: RYDER DRILLING TOOLS S.A.C.- RYDER DRILLING TOOLS S.A.C. | E36: Perú | H36: ExpoMina 2026 | I36: Prospecto | J36: Alta | K36: Identificar Gerente SSOMA/HSE en LinkedIn y proponer demo | L36: ExpoMina 2026. Sin contacto publicado. | M36: Cliente potencial – contratista / operación de alto riesgo | N36: A-402 | O36: 1 | P36: https://ryderdrilling.com/ | S36: No
A37: 36 | D37: SAFE & CARE S.A.C. | E37: Perú | F37: ventas@safeycare.com | H37: ExpoMina 2026 | I37: Prospecto | J37: Alta | K37: Identificar Gerente SSOMA/HSE en LinkedIn y proponer demo | L37: ExpoMina 2026. También en CRM Directorio SSO 2026 (ID 130). | M37: Cliente potencial – contratista / operación de alto riesgo | N37: A-107 | O37: 1 | P37: https://safeycare.com/ | Q37: (+51) 959267990 / (+51) 989147895 | R37: Cl. Los Talladores 275 - Ate - Lima | S37: Sí
A38: 37 | D38: SISTEMAS DE PERFORACION Y GEOTECNIA S.A.C | E38: Perú | H38: ExpoMina 2026 | I38: Prospecto | J38: Alta | K38: Identificar Gerente SSOMA/HSE en LinkedIn y proponer demo | L38: ExpoMina 2026. Sin contacto publicado. | M38: Cliente potencial – contratista / operación de alto riesgo | N38: B-169 | O38: 1 | P38: https://incotep.com/ | S38: No
A39: 38 | D39: SOLUCIONES QUIMICAS PARA LA MINERIA Y LA CONSTRUCCION S.A.C.- SOQUIMIC S.A.C. | E39: Perú | H39: ExpoMina 2026 | I39: Prospecto | J39: Alta | K39: Identificar Gerente SSOMA/HSE en LinkedIn y proponer demo | L39: ExpoMina 2026. Sin contacto publicado. | M39: Cliente potencial – contratista / operación de alto riesgo | N39: E-002 | O39: 1 | P39: www.chryso.com | S39: No
A40: 39 | D40: TRANSPORTES LINEA S.A. | E40: Perú | H40: ExpoMina 2026 | I40: Prospecto | J40: Alta | K40: Identificar Gerente SSOMA/HSE en LinkedIn y proponer demo | L40: ExpoMina 2026. Sin contacto publicado. | M40: Cliente potencial – contratista / operación de alto riesgo | N40: E-291 | O40: 1 | P40: www.linea.pe | S40: No
...

Sheet Oportunidades
A1: ID oportunidad | B1: ID contacto | C1: Empresa | D1: Necesidad | E1: Solución propuesta | F1: Etapa | G1: Valor estimado | H1: Probabilidad | I1: Próxima acción | J1: Fecha

Sheet Resumen
A1: Evento/Fuente | B1: País | C1: Cantidad
A2: ExpoMina 2026 | B2: Perú | C2: =COUNTIFS(Contactos!$H:$H,$A2,Contactos!$E:$E,$B2) -> 593
A3: ExpoMina 2026 | B3: China | C3: =COUNTIFS(Contactos!$H:$H,$A3,Contactos!$E:$E,$B3) -> 258
A4: ExpoMina 2026 | B4: Por validar | C4: =COUNTIFS(Contactos!$H:$H,$A4,Contactos!$E:$E,$B4) -> 55
A5: ExpoMina 2026 | B5: Perú (por validar) | C5: =COUNTIFS(Contactos!$H:$H,$A5,Contactos!$E:$E,$B5) -> 33
A6: ExpoMina 2026 | B6: Estados Unidos (por validar) | C6: =COUNTIFS(Contactos!$H:$H,$A6,Contactos!$E:$E,$B6) -> 11
A7: ExpoMina 2026 | B7: Chile | C7: =COUNTIFS(Contactos!$H:$H,$A7,Contactos!$E:$E,$B7) -> 8
A8: ExpoMina 2026 | B8: Chile (por validar) | C8: =COUNTIFS(Contactos!$H:$H,$A8,Contactos!$E:$E,$B8) -> 5
A9: ExpoMina 2026 | B9: México | C9: =COUNTIFS(Contactos!$H:$H,$A9,Contactos!$E:$E,$B9) -> 3
A10: ExpoMina 2026 | B10: Alemania | C10: =COUNTIFS(Contactos!$H:$H,$A10,Contactos!$E:$E,$B10) -> 2
A11: ExpoMina 2026 | B11: Argentina | C11: =COUNTIFS(Contactos!$H:$H,$A11,Contactos!$E:$E,$B11) -> 2
A12: ExpoMina 2026 | B12: India | C12: =COUNTIFS(Contactos!$H:$H,$A12,Contactos!$E:$E,$B12) -> 2
A13: ExpoMina 2026 | B13: Colombia | C13: =COUNTIFS(Contactos!$H:$H,$A13,Contactos!$E:$E,$B13) -> 2
... A17: ExpoMina 2026 | B17: Sudáfrica | C17: =COUNTIFS(Contactos!$H:$H,$A17,Contactos!$E:$E,$B17) -> 1
A18: Total | C18: =SUM(C2:C17) -> 979
A20: Segmento SafetyMind | B20: Alta | C20: Media | D20: Baja | E20: Total
A21: Minera (cliente final) | B21: =COUNTIFS(Contactos!$M:$M,$A21,Contactos!$J:$J,B$20) -> 3 | C21: =COUNTIFS(Contactos!$M:$M,$A21,Contactos!$J:$J,C$20) -> 0 | D21: =COUNTIFS(Contactos!$M:$M,$A21,Contactos!$J:$J,D$20) -> 0 | E21: =SUM(B21:D21) -> 3
A22: Cliente potencial – contratista / operación de alto riesgo | B22: =COUNTIFS(Contactos!$M:$M,$A22,Contactos!$J:$J,B$20) -> 37 | C22: =COUNTIFS(Contactos!$M:$M,$A22,Contactos!$J:$J,C$20) -> 0 | D22: =COUNTIFS(Contactos!$M:$M,$A22,Contactos!$J:$J,D$20) -> 0 | E22: =SUM(B22:D22) -> 37
A23: Partner tecnológico / competidor | B23: =COUNTIFS(Contactos!$M:$M,$A23,Contactos!$J:$J,B$20) -> 25 | C23: =COUNTIFS(Contactos!$M:$M,$A23,Contactos!$J:$J,C$20) -> 0 | D23: =COUNTIFS(Contactos!$M:$M,$A23,Contactos!$J:$J,D$20) -> 0 | E23: =SUM(B23:D23) -> 25
A24: Canal / aliado – consultoría SST | B24: =COUNTIFS(Contactos!$M:$M,$A24,Contactos!$J:$J,B$20) -> 15 | C24: =COUNTIFS(Contactos!$M:$M,$A24,Contactos!$J:$J,C$20) -> 0 | D24: =COUNTIFS(Contactos!$M:$M,$A24,Contactos!$J:$J,D$20) -> 0 | E24: =SUM(B24:D24) -> 15
A25: Partner OEM – equipos mineros | B25: =COUNTIFS(Contactos!$M:$M,$A25,Contactos!$J:$J,B$20) -> 0 | C25: =COUNTIFS(Contactos!$M:$M,$A25,Contactos!$J:$J,C$20) -> 12 | D25: =COUNTIFS(Contactos!$M:$M,$A25,Contactos!$J:$J,D$20) -> 0 | E25: =SUM(B25:D25) -> 12
A26: Canal / distribuidor EPP | B26: =COUNTIFS(Contactos!$M:$M,$A26,Contactos!$J:$J,B$20) -> 2 | C26: =COUNTIFS(Contactos!$M:$M,$A26,Contactos!$J:$J,C$20) -> 20 | D26: =COUNTIFS(Contactos!$M:$M,$A26,Contactos!$J:$J,D$20) -> 0 | E26: =SUM(B26:D26) -> 22
A27: Aliado complementario – seguridad | B27: =COUNTIFS(Contactos!$M:$M,$A27,Contactos!$J:$J,B$20) -> 1 | C27: =COUNTIFS(Contactos!$M:$M,$A27,Contactos!$J:$J,C$20) -> 11 | D27: =COUNTIFS(Contactos!$M:$M,$A27,Contactos!$J:$J,D$20) -> 0 | E27: =SUM(B27:D27) -> 12
A28: Aliado complementario – salud | B28: =COUNTIFS(Contactos!$M:$M,$A28,Contactos!$J:$J,B$20) -> 0 | C28: =COUNTIFS(Contactos!$M:$M,$A28,Contactos!$J:$J,C$20) -> 1 | D28: =COUNTIFS(Contactos!$M:$M,$A28,Contactos!$J:$J,D$20) -> 0 | E28: =SUM(B28:D28) -> 1
A29: Institución / gremio / pabellón país | B29: =COUNTIFS(Contactos!$M:$M,$A29,Contactos!$J:$J,B$20) -> 0 | C29: =COUNTIFS(Contactos!$M:$M,$A29,Contactos!$J:$J,C$20) -> 7 | D29: =COUNTIFS(Contactos!$M:$M,$A29,Contactos!$J:$J,D$20) -> 0 | E29: =SUM(B29:D29) -> 7
A30: Proveedor industrial (equipos/insumos) | B30: =COUNTIFS(Contactos!$M:$M,$A30,Contactos!$J:$J,B$20) -> 0 | C30: =COUNTIFS(Contactos!$M:$M,$A30,Contactos!$J:$J,C$20) -> 0 | D30: =COUNTIFS(Contactos!$M:$M,$A30,Contactos!$J:$J,D$20) -> 845 | E30: =SUM(B30:D30) -> 845
A31: Total | B31: =SUM(B21:B30) -> 83 | C31: =SUM(C21:C30) -> 51 | D31: =SUM(D21:D30) -> 845 | E31: =SUM(E21:E30) -> 979
A33: Estado (pipeline) | B33: Cantidad
A34: Prospecto | B34: =COUNTIF(Contactos!$I:$I,A34) -> 979
A35: Contactado | B35: =COUNTIF(Contactos!$I:$I,A35) -> 0
A36: Reunión | B36: =COUNTIF(Contactos!$I:$I,A36) -> 0
A37: Propuesta | B37: =COUNTIF(Contactos!$I:$I,A37) -> 0
A38: Cliente | B38: =COUNTIF(Contactos!$I:$I,A38) -> 0
A39: No interesado | B39: =COUNTIF(Contactos!$I:$I,A39) -> 0
A41: Indicadores | B41: Cantidad
A42: Registros originales (stands) | B42: 1209
A43: Empresas únicas | B43: =COUNTA(Contactos!$D$2:$D$3000) -> 979
A44: Con web | B44: =COUNTIF(Contactos!$P$2:$P$3000,"?*") -> 952
A45: También en Directorio SSO | B45: =COUNTIF(Contactos!$S:$S,"Sí") -> 74
A46: Con email (vía Directorio) | B46: =COUNTIF(Contactos!$F$2:$F$3000,"?*") -> 69
...

Sheet Eventos
A1: Evento | B1: País | C1: Valor para SafetyMind
A2: Directorio SSO 2026 – Cero Accidentes (22.ª ed.) | B2: Perú | C2: Mapa de ~670 proveedores SST en Perú (ver CRM_Directorio_SSO_2026).
A3: ExpoMina Perú 2026 | B3: Perú | C3: Feria minera: mineras, contratistas, OEM de equipos, tecnología y proveedores; base para agendar reuniones en stand y prospección post-evento.
