Workbook

Sheet Contactos
A1: ID | B1: Nombre | C1: Cargo | D1: Empresa | E1: País | F1: Email | G1: LinkedIn | H1: Origen | I1: Estado | J1: Prioridad | K1: Próxima acción | L1: Notas | M1: Segmento SafetyMind | N1: Stand(s) | O1: N° stands | P1: Rubro FIDAE | Q1: Web | R1: Teléfono(s) | S1: Cruce otros CRM
A2: 1 | D2: A PROFESIONAL AVIATION SERVICES CHILE ( APAS CHILE) | E2: Chile | H2: FIDAE 2026 | I2: Prospecto | J2: Alta | K2: Identificar Gerente de Seguridad Operacional/HSE; proponer piloto (hangar, rampa, mantenimiento, combustible) | L2: FIDAE 2026. Sin contacto publicado. | M2: Cliente final – operador aéreo / MRO / industria | N2: CHALET C5 Y C6 | O2: 1 | P2: Mantenimiento aeronáutico (MRO) | Q2: https://www.apaschile.cl/ | S2: No
A3: 2 | D3: ABM AERO | E3: Chile | H3: FIDAE 2026 | I3: Prospecto | J3: Alta | K3: Identificar Gerente de Seguridad Operacional/HSE; proponer piloto (hangar, rampa, mantenimiento, combustible) | L3: FIDAE 2026. Sin contacto publicado. | M3: Cliente final – operador aéreo / MRO / industria | N3: D23 | O3: 1 | P3: Aviación civil y comercial | Q3: https://ww.abmaero.cl/ | S3: No
A4: 3 | D4: AEREOS DEFENSE | E4: Chile | H4: FIDAE 2026 | I4: Prospecto | J4: Alta | K4: Identificar Gerente de Seguridad Operacional/HSE; proponer piloto (hangar, rampa, mantenimiento, combustible) | L4: FIDAE 2026. Sin contacto publicado. | M4: Cliente final – operador aéreo / MRO / industria | N4: C53 | O4: 1 | P4: Mantenimiento aeronáutico (MRO) | Q4: https://ww.aereos.com/ | S4: No
A5: 4 | D5: AEROCARDAL LIMITADA | E5: Chile | H5: FIDAE 2026 | I5: Prospecto | J5: Alta | K5: Identificar Gerente de Seguridad Operacional/HSE; proponer piloto (hangar, rampa, mantenimiento, combustible) | L5: FIDAE 2026. Sin contacto publicado. | M5: Cliente final – operador aéreo / MRO / industria | N5: CHALET A3 | O5: 1 | P5: Aviación civil y comercial | Q5: https://www.aerocardal.com/ | S5: No
A6: 5 | D6: AEROLIDER | E6: Chile | H6: FIDAE 2026 | I6: Prospecto | J6: Alta | K6: Identificar Gerente de Seguridad Operacional/HSE; proponer piloto (hangar, rampa, mantenimiento, combustible) | L6: FIDAE 2026. Sin contacto publicado. | M6: Cliente final – operador aéreo / MRO / industria | N6: E12 | O6: 1 | P6: Aviación civil y comercial | Q6: https://www.aerolider.com/ | S6: No
A7: 6 | D7: AEROMAC (AERONAUTICAL MAINTENANCE CENTER SPA.) | E7: Chile | H7: FIDAE 2026 | I7: Prospecto | J7: Alta | K7: Identificar Gerente de Seguridad Operacional/HSE; proponer piloto (hangar, rampa, mantenimiento, combustible) | L7: FIDAE 2026. Sin contacto publicado. | M7: Cliente final – operador aéreo / MRO / industria | N7: E139 | O7: 1 | P7: Defensa | Q7: https://www.aeromac-group.com/ | S7: No
A8: 7 | D8: AERONAUTICAL INVESTMENTS SPA | E8: Chile | H8: FIDAE 2026 | I8: Prospecto | J8: Alta | K8: Identificar Gerente de Seguridad Operacional/HSE; proponer piloto (hangar, rampa, mantenimiento, combustible) | L8: FIDAE 2026. Sin contacto publicado. | M8: Cliente final – operador aéreo / MRO / industria | N8: E30 | O8: 1 | P8: Defensa | Q8: https://www.aeronauticalinvestments.com/ | S8: No
A9: 8 | D9: Aeroservicios Toqui Ltda | E9: Chile | H9: FIDAE 2026 | I9: Prospecto | J9: Alta | K9: Identificar Gerente de Seguridad Operacional/HSE; proponer piloto (hangar, rampa, mantenimiento, combustible) | L9: FIDAE 2026. Sin contacto publicado. | M9: Cliente final – operador aéreo / MRO / industria | N9: E 02 | O9: 1 | P9: Aviación civil y comercial | Q9: https://www.aerotoqui.cl/ | S9: No
A10: 9 | D10: ASMAR - ASTILLEROS Y MAESTRANZAS DE LA ARMADA | E10: Chile | H10: FIDAE 2026 | I10: Prospecto | J10: Alta | K10: Identificar Gerente de Seguridad Operacional/HSE; proponer piloto (hangar, rampa, mantenimiento, combustible) | L10: FIDAE 2026. Sin contacto publicado. | M10: Cliente final – operador aéreo / MRO / industria | N10: D130 | O10: 1 | P10: Defensa | Q10: https://www.asmar.cl/ | S10: No
A11: 10 | D11: BODE AVIATION | E11: Chile | H11: FIDAE 2026 | I11: Prospecto | J11: Alta | K11: Identificar Gerente de Seguridad Operacional/HSE; proponer piloto (hangar, rampa, mantenimiento, combustible) | L11: FIDAE 2026. Sin contacto publicado. | M11: Cliente final – operador aéreo / MRO / industria | N11: E02 | O11: 1 | P11: Aviación civil y comercial | Q11: https://www.flybode.com/ | S11: No
A12: 11 | D12: CLUB AÉREO DE SANTIAGO | E12: Chile | H12: FIDAE 2026 | I12: Prospecto | J12: Alta | K12: Identificar Gerente de Seguridad Operacional/HSE; proponer piloto (hangar, rampa, mantenimiento, combustible) | L12: FIDAE 2026. Sin contacto publicado. | M12: Cliente final – operador aéreo / MRO / industria | N12: OUTDOOR /AIRCRAFT DISPLAY | O12: 1 | P12: Aviación civil y comercial | Q12: https://www.cas.cl/ | S12: No
A13: 12 | D13: DISTRIBUIDORA DE VEHICULOS ESPECIALES SPA. | E13: Chile | H13: FIDAE 2026 | I13: Prospecto | J13: Alta | K13: Identificar Gerente de Seguridad Operacional/HSE; proponer piloto (hangar, rampa, mantenimiento, combustible) | L13: FIDAE 2026. Sin contacto publicado. | M13: Cliente final – operador aéreo / MRO / industria | N13: OUTDOOR | O13: 1 | P13: Defensa | Q13: https://www.divespec.cl/ | S13: No
... A23: 22 | D23: SISDEF LTDA | E23: Chile | H23: FIDAE 2026 | I23: Prospecto | J23: Alta | K23: Identificar Gerente de Seguridad Operacional/HSE; proponer piloto (hangar, rampa, mantenimiento, combustible) | L23: FIDAE 2026. También en: AquaSur (ID 17). Sin contacto publicado. | M23: Cliente final – operador aéreo / MRO / industria | N23: D130 | O23: 1 | P23: Defensa | Q23: https://www.sisdef.cl/ | S23: AquaSur (ID 17)
A24: 23 | D24: TKOF SPA | E24: Chile | H24: FIDAE 2026 | I24: Prospecto | J24: Alta | K24: Identificar Gerente de Seguridad Operacional/HSE; proponer piloto (hangar, rampa, mantenimiento, combustible) | L24: FIDAE 2026. Sin contacto publicado. | M24: Cliente final – operador aéreo / MRO / industria | N24: E29 | O24: 1 | Q24: https://www.tkofaviation.com/ | S24: No
A25: 24 | D25: HELISUL TAXI AEREO LTDA | E25: Brasil | H25: FIDAE 2026 | I25: Prospecto | J25: Alta | K25: Identificar Gerente de Seguridad Operacional/HSE; proponer piloto (hangar, rampa, mantenimiento, combustible) | L25: FIDAE 2026. Sin contacto publicado. | M25: Cliente final – operador aéreo / MRO / industria | N25: C47 | O25: 1 | P25: Aviación civil y comercial | Q25: https://www.helisul.com/ | S25: No
A26: 25 | D26: LAMAIGNERE CARGO S.L. | E26: España | H26: FIDAE 2026 | I26: Prospecto | J26: Alta | K26: Identificar Gerente de Seguridad Operacional/HSE; proponer piloto (hangar, rampa, mantenimiento, combustible) | L26: FIDAE 2026. Sin contacto publicado. | M26: Cliente final – operador aéreo / MRO / industria | N26: B30 | O26: 1 | P26: Logística y apoyo en tierra | Q26: https://www.lamaignere.com/ | S26: No
A27: 26 | D27: WORLD FUEL SERVICES | E27: Estados Unidos | H27: FIDAE 2026 | I27: Prospecto | J27: Alta | K27: Identificar Gerente de Seguridad Operacional/HSE; proponer piloto (hangar, rampa, mantenimiento, combustible) | L27: FIDAE 2026. Sin ubicación asignada. Sin contacto publicado. | M27: Cliente final – operador aéreo / MRO / industria | O27: 0 | P27: Servicios y equipos aeroportuarios | Q27: https://www.world-kinect.com/world-fuel | S27: No
A28: 27 | D28: ACELERADORA ANIPRIME LIMITADA | E28: Chile | H28: FIDAE 2026 | I28: Prospecto | J28: Alta | K28: Mapear oferta: evaluar integración (cámaras térmicas, drones, satélite, comunicaciones) o competencia | L28: FIDAE 2026. Sin contacto publicado. | M28: Partner tecnológico / competidor | N28: D29 | O28: 1 | P28: UAV / drones | Q28: https://www.stellarchile.cl/ | S28: No
A29: 28 | D29: ALACRON.AI | E29: Chile | H29: FIDAE 2026 | I29: Prospecto | J29: Alta | K29: Mapear oferta: evaluar integración (cámaras térmicas, drones, satélite, comunicaciones) o competencia | L29: FIDAE 2026. Sin contacto publicado. | M29: Partner tecnológico / competidor | N29: E10 | O29: 1 | P29: Otros | Q29: https://www.alacron.ai/ | S29: No
A30: 29 | D30: AUTEL ROBOTICS | E30: Chile | H30: FIDAE 2026 | I30: Prospecto | J30: Alta | K30: Mapear oferta: evaluar integración (cámaras térmicas, drones, satélite, comunicaciones) o competencia | L30: FIDAE 2026. Sin contacto publicado. | M30: Partner tecnológico / competidor | N30: G06 | O30: 1 | P30: UAV / drones | Q30: https://www.uavsics.cl/ | S30: No
A31: 30 | D31: Codan Communications | E31: Chile | H31: FIDAE 2026 | I31: Prospecto | J31: Alta | K31: Mapear oferta: evaluar integración (cámaras térmicas, drones, satélite, comunicaciones) o competencia | L31: FIDAE 2026. Sin contacto publicado. | M31: Partner tecnológico / competidor | N31: D08 | O31: 1 | S31: No
A32: 31 | D32: COMERCIALIZADORA RUGGEDTECH LIMITADA | E32: Chile | H32: FIDAE 2026 | I32: Prospecto | J32: Alta | K32: Mapear oferta: evaluar integración (cámaras térmicas, drones, satélite, comunicaciones) o competencia | L32: FIDAE 2026. Sin contacto publicado. | M32: Partner tecnológico / competidor | N32: D15 | O32: 1 | P32: Otros | Q32: https://www.ruggedtechla/ | S32: No
A33: 32 | D33: DTS (DESARROLLO DE TECNOLOGIA Y SISTEMAS SPA) | E33: Chile | H33: FIDAE 2026 | I33: Prospecto | J33: Alta | K33: Mapear oferta: evaluar integración (cámaras térmicas, drones, satélite, comunicaciones) o competencia | L33: FIDAE 2026. Sin contacto publicado. | M33: Partner tecnológico / competidor | N33: CHALET A1-A2 | O33: 1 | P33: Defensa | Q33: https://www.dts.cl/ | S33: No
A34: 33 | D34: ESRI CHILE | E34: Chile | H34: FIDAE 2026 | I34: Prospecto | J34: Alta | K34: Mapear oferta: evaluar integración (cámaras térmicas, drones, satélite, comunicaciones) o competencia | L34: FIDAE 2026. Sin contacto publicado. | M34: Partner tecnológico / competidor | N34: D18 | O34: 1 | P34: Tecnologías espaciales | Q34: https://www.esri.cl/ | S34: No
A35: 34 | D35: GEOCOM | E35: Chile | H35: FIDAE 2026 | I35: Prospecto | J35: Alta | K35: Mapear oferta: evaluar integración (cámaras térmicas, drones, satélite, comunicaciones) o competencia | L35: FIDAE 2026. Sin contacto publicado. | M35: Partner tecnológico / competidor | N35: G05 | O35: 1 | P35: UAV / drones | Q35: https://www.geocom.cl/ | S35: No
A36: 35 | D36: IPS TELECOM SPA | E36: Chile | H36: FIDAE 2026 | I36: Prospecto | J36: Alta | K36: Mapear oferta: evaluar integración (cámaras térmicas, drones, satélite, comunicaciones) o competencia | L36: FIDAE 2026. Sin contacto publicado. | M36: Partner tecnológico / competidor | N36: D8 | O36: 1 | P36: Otros | Q36: https://www.ipstelecom.cl/ | S36: No
A37: 36 | D37: MOTOROLA SOLUTIONS CHILE | E37: Chile | H37: FIDAE 2026 | I37: Prospecto | J37: Alta | K37: Mapear oferta: evaluar integración (cámaras térmicas, drones, satélite, comunicaciones) o competencia | L37: FIDAE 2026. Sin contacto publicado. | M37: Partner tecnológico / competidor | N37: B02 | O37: 1 | P37: Defensa | Q37: https://www.motorolasolutions.com/ | S37: No
A38: 37 | D38: NVIS Communications | E38: Chile | H38: FIDAE 2026 | I38: Prospecto | J38: Alta | K38: Mapear oferta: evaluar integración (cámaras térmicas, drones, satélite, comunicaciones) o competencia | L38: FIDAE 2026. Sin contacto publicado. | M38: Partner tecnológico / competidor | N38: D08 | O38: 1 | S38: No
A39: 38 | D39: OPEN CHANNEL S.A. | E39: Chile | H39: FIDAE 2026 | I39: Prospecto | J39: Alta | K39: Mapear oferta: evaluar integración (cámaras térmicas, drones, satélite, comunicaciones) o competencia | L39: FIDAE 2026. Sin contacto publicado. | M39: Partner tecnológico / competidor | N39: E44 | O39: 1 | P39: Ciberseguridad | Q39: https://www.openchannels.cl/ | S39: No
A40: 39 | D40: RASTER 4 SPA | E40: Chile | H40: FIDAE 2026 | I40: Prospecto | J40: Alta | K40: Mapear oferta: evaluar integración (cámaras térmicas, drones, satélite, comunicaciones) o competencia | L40: FIDAE 2026. Sin contacto publicado. | M40: Partner tecnológico / competidor | N40: D12 | O40: 1 | P40: Tecnologías espaciales | Q40: https://www.raster4.com/ | S40: No
A41: 40 | D41: ROBOMOTIC SPA | E41: Chile | H41: FIDAE 2026 | I41: Prospecto | J41: Alta | K41: Mapear oferta: evaluar integración (cámaras térmicas, drones, satélite, comunicaciones) o competencia | L41: FIDAE 2026. Sin contacto publicado. | M41: Partner tecnológico / competidor | N41: E26 | O41: 1 | P41: Ciberseguridad | Q41: https://www.robomotic%20.cl/ | S41: No
A42: 41 | D42: SERVICIOS Y SOLUCIONES TECNOLOGICAS SA | E42: Chile | H42: FIDAE 2026 | I42: Prospecto | J42: Alta | K42: Mapear oferta: evaluar integración (cámaras térmicas, drones, satélite, comunicaciones) o competencia | L42: FIDAE 2026. Sin ubicación asignada. Sin contacto publicado. | M42: Partner tecnológico / competidor | O42: 0 | P42: Otros | Q42: https://www.s2t.cl/ | S42: No
A43: 42 | D43: SETRONIX CHILE S.A | E43: Chile | H43: FIDAE 2026 | I43: Prospecto | J43: Alta | K43: Mapear oferta: evaluar integración (cámaras térmicas, drones, satélite, comunicaciones) o competencia | L43: FIDAE 2026. Sin contacto publicado. | M43: Partner tecnológico / competidor | N43: G10 | O43: 1 | Q43: https://www.setronix.cl/ | S43: No
A44: 43 | D44: SI IMAGING SERVICES (SIIS) | E44: Chile | H44: FIDAE 2026 | I44: Prospecto | J44: Alta | K44: Mapear oferta: evaluar integración (cámaras térmicas, drones, satélite, comunicaciones) o competencia | L44: FIDAE 2026. Sin contacto publicado. | M44: Partner tecnológico / competidor | N44: D136 | O44: 1 | P44: Tecnologías espaciales | Q44: https://www.si-imaging.com/ | S44: No
A45: 44 | D45: SKYTEL TELECOMUNICACIONES LIMITADA | E45: Chile | H45: FIDAE 2026 | I45: Prospecto | J45: Alta | K45: Mapear oferta: evaluar integración (cámaras térmicas, drones, satélite, comunicaciones) o competencia | L45: FIDAE 2026. Sin contacto publicado. | M45: Partner tecnológico / competidor | N45: HALL E - 16 | O45: 1 | P45: Defensa | Q45: https://www.skytel.cl/ | S45: No
A46: 45 | D46: SMART PARTNERS | E46: Chile | H46: FIDAE 2026 | I46: Prospecto | J46: Alta | K46: Mapear oferta: evaluar integración (cámaras térmicas, drones, satélite, comunicaciones) o competencia | L46: FIDAE 2026. Sin contacto publicado. | M46: Partner tecnológico / competidor | N46: C49 | O46: 1 | P46: Defensa | Q46: https://www.smartpartners.cl/ | S46: No
A47: 46 | D47: SOCIEDAD CREA3D INGENIERÍA SPA | E47: Chile | H47: FIDAE 2026 | I47: Prospecto | J47: Alta | K47: Mapear oferta: evaluar integración (cámaras térmicas, drones, satélite, comunicaciones) o competencia | L47: FIDAE 2026. Sin contacto publicado. | M47: Partner tecnológico / competidor | N47: E28 | O47: 1 | P47: UAV / drones | Q47: https://www.c3d.cl/ | S47: No
A48: 47 | D48: TEK CHILE | E48: Chile | H48: FIDAE 2026 | I48: Prospecto | J48: Alta | K48: Mapear oferta: evaluar integración (cámaras térmicas, drones, satélite, comunicaciones) o competencia | L48: FIDAE 2026. Sin contacto publicado. | M48: Partner tecnológico / competidor | N48: D105 | O48: 1 | P48: Defensa | Q48: https://www.tek.tech/ | S48: No
A49: 48 | D49: AEVEX | E49: Estados Unidos | H49: FIDAE 2026 | I49: Prospecto | J49: Alta | K49: Mapear oferta: evaluar integración (cámaras térmicas, drones, satélite, comunicaciones) o competencia | L49: FIDAE 2026. Sin contacto publicado. | M49: Partner tecnológico / competidor | N49: C64 | O49: 1 | P49: Seguridad interior | Q49: https://www.aevex.com/ | S49: No
...

Sheet Oportunidades
A1: ID oportunidad | B1: ID contacto | C1: Empresa | D1: Necesidad | E1: Solución propuesta | F1: Etapa | G1: Valor estimado | H1: Probabilidad | I1: Próxima acción | J1: Fecha

Sheet Resumen
A1: Evento/Fuente | B1: País | C1: Cantidad
A2: FIDAE 2026 | B2: Chile | C2: =COUNTIFS(Contactos!$H:$H,$A2,Contactos!$E:$E,$B2) -> 127
A3: FIDAE 2026 | B3: Estados Unidos | C3: =COUNTIFS(Contactos!$H:$H,$A3,Contactos!$E:$E,$B3) -> 74
A4: FIDAE 2026 | B4: Corea del Sur | C4: =COUNTIFS(Contactos!$H:$H,$A4,Contactos!$E:$E,$B4) -> 30
A5: FIDAE 2026 | B5: República Checa | C5: =COUNTIFS(Contactos!$H:$H,$A5,Contactos!$E:$E,$B5) -> 25
A6: FIDAE 2026 | B6: Brasil | C6: =COUNTIFS(Contactos!$H:$H,$A6,Contactos!$E:$E,$B6) -> 24
A7: FIDAE 2026 | B7: España | C7: =COUNTIFS(Contactos!$H:$H,$A7,Contactos!$E:$E,$B7) -> 22
A8: FIDAE 2026 | B8: Francia | C8: =COUNTIFS(Contactos!$H:$H,$A8,Contactos!$E:$E,$B8) -> 14
A9: FIDAE 2026 | B9: Argentina | C9: =COUNTIFS(Contactos!$H:$H,$A9,Contactos!$E:$E,$B9) -> 12
A10: FIDAE 2026 | B10: Austria | C10: =COUNTIFS(Contactos!$H:$H,$A10,Contactos!$E:$E,$B10) -> 11
A11: FIDAE 2026 | B11: Alemania | C11: =COUNTIFS(Contactos!$H:$H,$A11,Contactos!$E:$E,$B11) -> 10
A12: FIDAE 2026 | B12: Polonia | C12: =COUNTIFS(Contactos!$H:$H,$A12,Contactos!$E:$E,$B12) -> 10
A13: FIDAE 2026 | B13: Turquía | C13: =COUNTIFS(Contactos!$H:$H,$A13,Contactos!$E:$E,$B13) -> 9
... A36: FIDAE 2026 | B36: Letonia | C36: =COUNTIFS(Contactos!$H:$H,$A36,Contactos!$E:$E,$B36) -> 1
A37: Total | C37: =SUM(C2:C36) -> 427
A39: Segmento SafetyMind | B39: Alta | C39: Media | D39: Baja | E39: Total
A40: Cliente final – operador aéreo / MRO / industria | B40: =COUNTIFS(Contactos!$M:$M,$A40,Contactos!$J:$J,B$39) -> 26 | C40: =COUNTIFS(Contactos!$M:$M,$A40,Contactos!$J:$J,C$39) -> 0 | D40: =COUNTIFS(Contactos!$M:$M,$A40,Contactos!$J:$J,D$39) -> 0 | E40: =SUM(B40:D40) -> 26
A41: Partner tecnológico / competidor | B41: =COUNTIFS(Contactos!$M:$M,$A41,Contactos!$J:$J,B$39) -> 47 | C41: =COUNTIFS(Contactos!$M:$M,$A41,Contactos!$J:$J,C$39) -> 0 | D41: =COUNTIFS(Contactos!$M:$M,$A41,Contactos!$J:$J,D$39) -> 0 | E41: =SUM(B41:D41) -> 47
A42: Canal / aliado – capacitación y consultoría | B42: =COUNTIFS(Contactos!$M:$M,$A42,Contactos!$J:$J,B$39) -> 10 | C42: =COUNTIFS(Contactos!$M:$M,$A42,Contactos!$J:$J,C$39) -> 0 | D42: =COUNTIFS(Contactos!$M:$M,$A42,Contactos!$J:$J,D$39) -> 0 | E42: =SUM(B42:D42) -> 10
A43: Partner OEM – aeronaves, motores y equipos | B43: =COUNTIFS(Contactos!$M:$M,$A43,Contactos!$J:$J,B$39) -> 0 | C43: =COUNTIFS(Contactos!$M:$M,$A43,Contactos!$J:$J,C$39) -> 27 | D43: =COUNTIFS(Contactos!$M:$M,$A43,Contactos!$J:$J,D$39) -> 0 | E43: =SUM(B43:D43) -> 27
A44: Canal / distribuidor EPP y equipamiento táctico | B44: =COUNTIFS(Contactos!$M:$M,$A44,Contactos!$J:$J,B$39) -> 0 | C44: =COUNTIFS(Contactos!$M:$M,$A44,Contactos!$J:$J,C$39) -> 20 | D44: =COUNTIFS(Contactos!$M:$M,$A44,Contactos!$J:$J,D$39) -> 0 | E44: =SUM(B44:D44) -> 20
A45: Aliado complementario – seguridad | B45: =COUNTIFS(Contactos!$M:$M,$A45,Contactos!$J:$J,B$39) -> 0 | C45: =COUNTIFS(Contactos!$M:$M,$A45,Contactos!$J:$J,C$39) -> 11 | D45: =COUNTIFS(Contactos!$M:$M,$A45,Contactos!$J:$J,D$39) -> 0 | E45: =SUM(B45:D45) -> 11
A46: Aliado complementario – salud | B46: =COUNTIFS(Contactos!$M:$M,$A46,Contactos!$J:$J,B$39) -> 0 | C46: =COUNTIFS(Contactos!$M:$M,$A46,Contactos!$J:$J,C$39) -> 3 | D46: =COUNTIFS(Contactos!$M:$M,$A46,Contactos!$J:$J,D$39) -> 0 | E46: =SUM(B46:D46) -> 3
A47: Institución pública – FF.AA., policías y autoridad | B47: =COUNTIFS(Contactos!$M:$M,$A47,Contactos!$J:$J,B$39) -> 0 | C47: =COUNTIFS(Contactos!$M:$M,$A47,Contactos!$J:$J,C$39) -> 17 | D47: =COUNTIFS(Contactos!$M:$M,$A47,Contactos!$J:$J,D$39) -> 0 | E47: =SUM(B47:D47) -> 17
A48: Institución / gremio / pabellón país | B48: =COUNTIFS(Contactos!$M:$M,$A48,Contactos!$J:$J,B$39) -> 0 | C48: =COUNTIFS(Contactos!$M:$M,$A48,Contactos!$J:$J,C$39) -> 34 | D48: =COUNTIFS(Contactos!$M:$M,$A48,Contactos!$J:$J,D$39) -> 0 | E48: =SUM(B48:D48) -> 34
A49: Proveedor defensa / industrial | B49: =COUNTIFS(Contactos!$M:$M,$A49,Contactos!$J:$J,B$39) -> 0 | C49: =COUNTIFS(Contactos!$M:$M,$A49,Contactos!$J:$J,C$39) -> 0 | D49: =COUNTIFS(Contactos!$M:$M,$A49,Contactos!$J:$J,D$39) -> 232 | E49: =SUM(B49:D49) -> 232
A50: Total | B50: =SUM(B40:B49) -> 83 | C50: =SUM(C40:C49) -> 112 | D50: =SUM(D40:D49) -> 232 | E50: =SUM(E40:E49) -> 427
A52: Estado (pipeline) | B52: Cantidad
A53: Prospecto | B53: =COUNTIF(Contactos!$I:$I,A53) -> 427
A54: Contactado | B54: =COUNTIF(Contactos!$I:$I,A54) -> 0
A55: Reunión | B55: =COUNTIF(Contactos!$I:$I,A55) -> 0
A56: Propuesta | B56: =COUNTIF(Contactos!$I:$I,A56) -> 0
A57: Cliente | B57: =COUNTIF(Contactos!$I:$I,A57) -> 0
A58: No interesado | B58: =COUNTIF(Contactos!$I:$I,A58) -> 0
A60: Indicadores | B60: Cantidad
A61: Registros originales | B61: 449
A62: Empresas / instituciones únicas | B62: =COUNTA(Contactos!$D$2:$D$3000) -> 427
A63: Con sede en Chile | B63: =COUNTIF(Contactos!$E$2:$E$3000,"Chile") -> 127
A64: Con web | B64: =COUNTIF(Contactos!$Q$2:$Q$3000,"?*") -> 402
A65: En otros CRM | B65: =COUNTIF(Contactos!$S$2:$S$3000,"*(ID*") -> 11

Sheet Eventos
A1: Evento | B1: País | C1: Valor para SafetyMind
A2: Directorio SSO 2026 – Cero Accidentes (22.ª ed.) | B2: Perú | C2: Mapa de ~670 proveedores SST en Perú (ver CRM_Directorio_SSO_2026).
A3: ExpoMina Perú 2026 | B3: Perú | C3: Feria minera (ver CRM_ExpoMina_2026).
A4: Exponor 2026 (Antofagasta) | B4: Chile | C4: Feria minera del norte de Chile (ver CRM_Exponor_2026).
A5: AquaSur 2026 (Puerto Montt) | B5: Chile | C5: Feria acuícola (ver CRM_AquaSur_2026).
A6: FIDAE 2026 (Santiago) | B6: Chile | C6: Feria aeroespacial y de defensa: operadores aéreos y MRO (hangar, rampa, combustible), FF.AA. y policías, tecnología de sensores/drones/satélites y fabricantes de aeronaves.
